Workbook

Sheet hse1
B2: OLE SAMEDHA APARTMENTS-Kitengela | N2: VAR | O2: TAX DUE
B3: P.O BOX 9473-00200 NAIROBI | N3: =O3-Q3 -> 10270 | O3: 10270
B4: WATER BILL | G4: BILL NO. | H4: 20242001 | N4: =O4-Q4 -> 10304 | O4: 10304
N5: =O5-Q5 -> 10988 | O5: 10988
B6: TENANT NAME | C6: MAUREEN | N6: =O6-Q6 -> 11070 | O6: 11070
B7: PHONE NO | C7: O731078405 | N7: =O7-Q7 -> 1197 | O7: 1197
B8: HOUSE NUMBER | C8: 1A | N8: =O8-Q8 -> 9250 | O8: 9250
N9: =O9-Q9 -> 8770 | O9: 8770
B10: ISSUE DATE | C10: 27/1/2026 | N10: =O10-Q10 -> 23190 | O10: 23190
N11: =O11-Q11 -> 10910 | O11: 10910
B12: LAST PAY DATE | C12: 46144 | N12: =O12-Q12 -> 10910 | O12: 10910
N13: =O13-Q13 -> 12190 | O13: 12190
N14: =O14-Q14 -> 11070 | O14: 11070
B15: PREVIOUS READING | C15: CURRENT READING | E15: CONSUMPTION (Units) | N15: =O15-Q15 -> 9090 | O15: 9090
B16: =meter!D3 -> 32 | C16: =meter!E3 -> 33 | D16: Units | E16: =C16-B16 -> 1 | N16: =O16-Q16 -> 9420 | O16: 9420
E17: AMOUNT KSHS | N17: =O17-Q17 -> 11154 | O17: 11154
C18: LAST ACCOUNT B/F | D18: Kshs. | N18: =O18-Q18 -> 10430 | O18: 10430
N19: =O19-Q19 -> 11831 | O19: 11831
C20: MONTH Water BILL | D20: Kshs. | E20: =meter!H3 -> 220 | N20: =O20-Q20 -> 10590 | O20: 10590
N21: =O21-Q21 -> 22423 | O21: 22423
C22: PUMP/POWER CHARGES | D22: Kshs. | E22: 110 | N22: =O22-Q22 -> 9250 | O22: 9250
N23: =O23-Q23 -> 10162 | O23: 10162
C24: MONTH HOUSE RENT | D24: Kshs. | E24: 10000 | N24: =O24-Q24 -> 10270 | O24: 10270
N25: =O25-Q25 -> 11070 | O25: 11070
C26: security | D26: Kshs. | E26: 500 | N26: =O26-Q26 -> 11550 | O26: 11550
C27: GARBAGE FEE | D27: Kshs. | E27: 150 | N27: =O27-Q27 -> 11393 | O27: 11393
C28: LATE PAY INTEREST | D28: Kshs. | N28: =O28-Q28 -> 10802 | O28: 10802
N29: =O29-Q29 -> 8930 | O29: 8930
C30: TOTAL PAYABLE | D30: Kshs. | E30: =E18+E20+E22+E24+E26+E27+E28 -> 10980 | N30: =O30-Q30 -> 9570 | O30: 9570
N31: =O31-Q31 -> 11390 | O31: 11390
C32: PAID | E32: =meter!R3 -> 0 | N32: =O32-Q32 -> 10750 | O32: 10750
N33: =O33-Q33 -> 11732 | O33: 11732
C34: AMOUNT DUE | E34: =E30-E32 -> 10980 | N34: =O34-Q34 -> 10934 | O34: 10934 | R34: 700
B35: NOTE | N35: =O35-Q35 -> 10270 | O35: 10270
A36: a) | B36: Rent is due on or before 5th of the month. By 7th day, any rent not paid will attract interest at 2% per day. | N36: =O36-Q36 -> 10598 | O36: 10598
A37: b) | B37: Any default in Rent payment by 10th of the following month the house shall be locked without notice and belongings removed for re-letting. | N37: =O37-Q37 -> 8770 | O37: 8770
N38: =O38-Q38 -> 8770 | O38: 8770
A39: c) | B39: Amounts not cleared by last pay date will render to water disconnection. | O39: =SUM(O3:O38) -> 391268 | Q39: =SUM(Q3:Q38) -> 0
A41: d) | B41: A reconnection fee of Kshs. 1,000 will be charged and paid before supply is reconnected.
A42: e) | B42: ANY MINOR REPAIRS OCCURING AFTER 3 MONTHS OF OCCUPANCY ARE TENANT'S RESPONSIBILITY AS PER TENANCY AGREEMENT.
...

Sheet hse2
B2: OLE SAMEDHA APARTMENTS-Kitengela | N2: VAR | O2: TAX DUE
B3: ='hse1'!B3 -> P.O BOX 9473-00200 NAIROBI | N3: =O3-Q3 -> 10270 | O3: 10270
B4: WATER BILL | F4: BILL NO. | G4: ='hse1'!H4+2-1 -> 20242002 | N4: =O4-Q4 -> 10304 | O4: 10304
N5: =O5-Q5 -> 10988 | O5: 10988
B6: TENANT NAME | D6: =meter!A4 -> GODFREY IRONGO | N6: =O6-Q6 -> 11070 | O6: 11070
N7: =O7-Q7 -> 1197 | O7: 1197
B8: HOUSE NUMBER | D8: 2A | N8: =O8-Q8 -> 9250 | O8: 9250
N9: =O9-Q9 -> 8770 | O9: 8770
B10: ISSUE DATE | D10: ='hse1'!C10 -> 27/1/2026 | N10: =O10-Q10 -> 23190 | O10: 23190
N11: =O11-Q11 -> 10910 | O11: 10910
B12: LAST PAY DATE | D12: ='hse1'!C12 -> 46144 | N12: =O12-Q12 -> 10910 | O12: 10910
N13: =O13-Q13 -> 12190 | O13: 12190
N14: =O14-Q14 -> 11070 | O14: 11070
B15: PREVIOUS READING | D15: CURRENT READING | F15: CONSUMPTION (Units) | N15: =O15-Q15 -> 9090 | O15: 9090
B16: =meter!D4 -> 229 | D16: =meter!E4 -> 232 | E16: Units | F16: =D16-B16 -> 3 | N16: =O16-Q16 -> 9420 | O16: 9420
F17: Amount (Kshs.) | N17: =O17-Q17 -> 11154 | O17: 11154
D18: LAST ACCOUNT B/F | E18: Kshs. | F18: =meter!O4 -> 0 | N18: =O18-Q18 -> 10430 | O18: 10430
N19: =O19-Q19 -> 11831 | O19: 11831
D20: MONTH BILL | E20: Kshs. | F20: =meter!H4 -> 660 | N20: =O20-Q20 -> 10590 | O20: 10590
N21: =O21-Q21 -> 22423 | O21: 22423
D22: PUMP/POWER CHARGES | E22: Kshs. | F22: ='hse1'!E22 -> 110 | N22: =O22-Q22 -> 9250 | O22: 9250
N23: =O23-Q23 -> 10162 | O23: 10162
D24: MONTH HOUSE RENT | E24: Kshs. | F24: 10000 | N24: =O24-Q24 -> 10270 | O24: 10270
N25: =O25-Q25 -> 11070 | O25: 11070
D26: ='hse1'!C26 -> security | E26: Kshs. | F26: 500 | N26: =O26-Q26 -> 11550 | O26: 11550
D27: GARBAGE FEE | F27: 150 | N27: =O27-Q27 -> 11393 | O27: 11393
D28: INTEREST ON ARREARS | E28: Kshs. | F28: =IF(F18*6%*3<0,0,F18*6%*3) -> 0 | N28: =O28-Q28 -> 10802 | O28: 10802
F29: 0 | N29: =O29-Q29 -> 8930 | O29: 8930
D30: TOTAL PAYABLE | E30: Kshs. | F30: =SUM(F17:F29) -> 11420 | N30: =O30-Q30 -> 9570 | O30: 9570
N31: =O31-Q31 -> 11390 | O31: 11390
D32: PAID | F32: =meter!R4 -> 0 | N32: =O32-Q32 -> 10750 | O32: 10750
N33: =O33-Q33 -> 11732 | O33: 11732
D34: AMOUNT DUE | F34: =F30-F32 -> 11420 | N34: =O34-Q34 -> 10934 | O34: 10934 | R34: 700
C35: NOTE | N35: =O35-Q35 -> 10270 | O35: 10270
B36: a) | C36: Rent is due on or before 5th of the month. By 7th day, any rent not paid will attract interest at 2% per day. | N36: =O36-Q36 -> 10598 | O36: 10598
B37: b) | C37: Any default in Rent payment by 10th of the following month the house shall be locked without notice and belongings removed for re-letting. | N37: =O37-Q37 -> 8770 | O37: 8770
N38: =O38-Q38 -> 8770 | O38: 8770
B39: c) | C39: Amounts not cleared by last pay date will render to water disconnection. | O39: =SUM(O3:O38) -> 391268 | Q39: =SUM(Q3:Q38) -> 0
B41: d) | C41: A reconnection fee of Kshs. 1,000 will be charged and paid before supply is reconnected.
B42: e) | C42: ANY MINOR REPAIRS OCCURING AFTER 3 MONTHS OF OCCUPANCY ARE TENANT'S RESPONSIBILITY AS PER TENANCY AGREEMENT.
...

Sheet hse3
B2: OLE SAMEDHA APARTMENTS-Kitengela | N2: VAR | O2: TAX DUE
B3: ='hse1'!B3 -> P.O BOX 9473-00200 NAIROBI | N3: =O3-Q3 -> 10270 | O3: 10270
B4: WATER BILL | G4: BILL NO. | H4: ='hse1'!H4+3-1 -> 20242003 | N4: =O4-Q4 -> 10304 | O4: 10304
N5: =O5-Q5 -> 10988 | O5: 10988
B6: TENANT NAME | C6: =meter!A5 -> STACY | N6: =O6-Q6 -> 11070 | O6: 11070
N7: =O7-Q7 -> 1197 | O7: 1197
B8: HOUSE NUMBER: | C8: 3A | N8: =O8-Q8 -> 9250 | O8: 9250
N9: =O9-Q9 -> 8770 | O9: 8770
B10: ISSUE DATE | C10: ='hse1'!C10 -> 27/1/2026 | N10: =O10-Q10 -> 23190 | O10: 23190
N11: =O11-Q11 -> 10910 | O11: 10910
B12: LAST PAY DATE | C12: ='hse1'!C12 -> 46144 | N12: =O12-Q12 -> 10910 | O12: 10910
N13: =O13-Q13 -> 12190 | O13: 12190
N14: =O14-Q14 -> 11070 | O14: 11070
B15: PREVIOUS READING | C15: CURRENT READING | E15: CONSUMPTION (Units) | N15: =O15-Q15 -> 9090 | O15: 9090
B16: =meter!D5 -> 845 | C16: =meter!E5 -> 847 | D16: Units | E16: =C16-B16 -> 2 | N16: =O16-Q16 -> 9420 | O16: 9420
E17: Amount (Kshs.) | N17: =O17-Q17 -> 11154 | O17: 11154
C18: LAST ACCOUNT B/F | D18: Kshs. | E18: =meter!O5 -> 2450 | N18: =O18-Q18 -> 10430 | O18: 10430
N19: =O19-Q19 -> 11831 | O19: 11831
C20: MONTH BILL | D20: Kshs. | E20: =meter!H5 -> 440 | N20: =O20-Q20 -> 10590 | O20: 10590
N21: =O21-Q21 -> 22423 | O21: 22423
C22: PUMP/POWER CHARGES | D22: Kshs. | E22: =meter!J5 -> 110 | N22: =O22-Q22 -> 9250 | O22: 9250
N23: =O23-Q23 -> 10162 | O23: 10162
C24: MONTH HOUSE RENT | D24: Kshs. | E24: =meter!N5 -> 10500 | N24: =O24-Q24 -> 10270 | O24: 10270
N25: =O25-Q25 -> 11070 | O25: 11070
C26: SECURITY | D26: Kshs. | E26: 500 | N26: =O26-Q26 -> 11550 | O26: 11550
C27: GARBAGE FEE | D27: Kshs. | E27: 150 | N27: =O27-Q27 -> 11393 | O27: 11393
C28: ADJUSTMENT | D28: Kshs. | E28: =IF(E18*6%*3<0,0,E18*6%*3) -> 441 | N28: =O28-Q28 -> 10802 | O28: 10802
N29: =O29-Q29 -> 8930 | O29: 8930
C30: TOTAL PAYABLE | D30: Kshs. | E30: =SUM(E17:E29) -> 14591 | N30: =O30-Q30 -> 9570 | O30: 9570
N31: =O31-Q31 -> 11390 | O31: 11390
C32: PAID | E32: =meter!R5 -> 0 | N32: =O32-Q32 -> 10750 | O32: 10750
N33: =O33-Q33 -> 11732 | O33: 11732
C34: AMOUNT DUE | E34: =E30-E32 -> 14591 | N34: =O34-Q34 -> 10934 | O34: 10934 | R34: 700
B35: NOTE | N35: =O35-Q35 -> 10270 | O35: 10270
A36: a) | B36: Rent is due on or before 5th of the month. By 7th day, any rent not paid will attract interest at 2% per day. | N36: =O36-Q36 -> 10598 | O36: 10598
A37: b) | B37: Any default in Rent payment by 10th of the following month the house shall be locked without notice and belongings removed for re-letting. | N37: =O37-Q37 -> 8770 | O37: 8770
N38: =O38-Q38 -> 8770 | O38: 8770
A39: c) | B39: Amounts not cleared by last pay date will render to water disconnection. | O39: =SUM(O3:O38) -> 391268 | Q39: =SUM(Q3:Q38) -> 0
A41: d) | B41: A reconnection fee of Kshs. 1,000 will be charged and paid before supply is reconnected.
A42: e) | B42: ANY MINOR REPAIRS OCCURING AFTER 3 MONTHS OF OCCUPANCY ARE TENANT'S RESPONSIBILITY AS PER TENANCY AGREEMENT.
...

Sheet hse4
B2: OLE SAMEDHA APARTMENTS-Kitengela | N2: VAR | O2: TAX DUE
B3: ='hse1'!B3 -> P.O BOX 9473-00200 NAIROBI | N3: =O3-Q3 -> 10270 | O3: 10270
B4: WATER BILL | G4: BILL NO. | H4: ='hse1'!H4+4-1 -> 20242004 | N4: =O4-Q4 -> 10304 | O4: 10304
N5: =O5-Q5 -> 10988 | O5: 10988
B6: TENANT NAME | C6: =meter!A6 -> MARY | N6: =O6-Q6 -> 11070 | O6: 11070
N7: =O7-Q7 -> 1197 | O7: 1197
B8: HOUSE NUMBER: | C8: 4A | N8: =O8-Q8 -> 9250 | O8: 9250
N9: =O9-Q9 -> 8770 | O9: 8770
B10: ISSUE DATE | C10: ='hse1'!C10 -> 27/1/2026 | N10: =O10-Q10 -> 23190 | O10: 23190
N11: =O11-Q11 -> 10910 | O11: 10910
B12: LAST PAY DATE | C12: ='hse1'!C12 -> 46144 | N12: =O12-Q12 -> 10910 | O12: 10910
N13: =O13-Q13 -> 12190 | O13: 12190
N14: =O14-Q14 -> 11070 | O14: 11070
B15: PREVIOUS READING | C15: CURRENT READING | E15: CONSUMPTION | N15: =O15-Q15 -> 9090 | O15: 9090
B16: =meter!D6 -> 721 | C16: =meter!E6 -> 724 | D16: Units | E16: =C16-B16 -> 3 | N16: =O16-Q16 -> 9420 | O16: 9420
E17: Amount (Kshs) | N17: =O17-Q17 -> 11154 | O17: 11154
C18: LAST ACCOUNT B/F | D18: Kshs. | E18: =meter!O6 -> 5250 | N18: =O18-Q18 -> 10430 | O18: 10430
N19: =O19-Q19 -> 11831 | O19: 11831
C20: MONTH BILL | D20: Kshs. | E20: =meter!H6 -> 660 | N20: =O20-Q20 -> 10590 | O20: 10590
N21: =O21-Q21 -> 22423 | O21: 22423
C22: PUMP/POWER CHARGES | D22: Kshs. | E22: =meter!J6 -> 110 | N22: =O22-Q22 -> 9250 | O22: 9250
N23: =O23-Q23 -> 10162 | O23: 10162
C24: MONTH HOUSE RENT | D24: Kshs. | E24: =meter!N6 -> 10000 | N24: =O24-Q24 -> 10270 | O24: 10270
N25: =O25-Q25 -> 11070 | O25: 11070
C26: SECURITY | D26: Kshs. | E26: 500 | N26: =O26-Q26 -> 11550 | O26: 11550
C27: GARBAGE FEE | D27: Kshs. | E27: 150 | N27: =O27-Q27 -> 11393 | O27: 11393
C28: INTEREST ON ARREARS | D28: Kshs. | E28: =IF(E18*6%*3<0,0,E18*6%*3) -> 945 | N28: =O28-Q28 -> 10802 | O28: 10802
N29: =O29-Q29 -> 8930 | O29: 8930
C30: TOTAL PAYABLE | D30: Kshs. | E30: =SUM(E17:E29) -> 17615 | N30: =O30-Q30 -> 9570 | O30: 9570
N31: =O31-Q31 -> 11390 | O31: 11390
C32: PAID | E32: =meter!R6 -> 0 | N32: =O32-Q32 -> 10750 | O32: 10750
N33: =O33-Q33 -> 11732 | O33: 11732
C34: AMOUNT DUE | E34: =E30-E32 -> 17615 | N34: =O34-Q34 -> 10934 | O34: 10934 | R34: 700
B35: NOTE | N35: =O35-Q35 -> 10270 | O35: 10270
A36: a) | B36: Rent is due on or before 5th of the month. By 7th day, any rent not paid will attract interest at 2% per day. | N36: =O36-Q36 -> 10598 | O36: 10598
A37: b) | B37: Any default in Rent payment by 10th of the following month the house shall be locked without notice and belongings removed for re-letting. | N37: =O37-Q37 -> 8770 | O37: 8770
N38: =O38-Q38 -> 8770 | O38: 8770
A39: c) | B39: Amounts not cleared by last pay date will render to water disconnection. | O39: =SUM(O3:O38) -> 391268 | Q39: =SUM(Q3:Q38) -> 0
A41: d) | B41: A reconnection fee of Kshs. 1,000 will be charged and paid before supply is reconnected.
A42: e) | B42: ANY MINOR REPAIRS OCCURING AFTER 3 MONTHS OF OCCUPANCY ARE TENANT'S RESPONSIBILITY AS PER TENANCY AGREEMENT.
...

Sheet hse5
B2: OLE SAMEDHA APARTMENTS-Kitengela | N2: VAR | O2: TAX DUE
B3: ='hse1'!B3 -> P.O BOX 9473-00200 NAIROBI | N3: =O3-Q3 -> 10270 | O3: 10270
B4: WATER BILL | G4: BILL NO. | H4: ='hse1'!H4+5-1 -> 20242005 | N4: =O4-Q4 -> 10304 | O4: 10304
N5: =O5-Q5 -> 10988 | O5: 10988
B6: TENANT NAME | C6: =meter!A7 -> GEOFFREY | N6: =O6-Q6 -> 11070 | O6: 11070
N7: =O7-Q7 -> 1197 | O7: 1197
B8: HOUSE NUMBER; | C8: 5A | N8: =O8-Q8 -> 9250 | O8: 9250
N9: =O9-Q9 -> 8770 | O9: 8770
B10: ISSUE DATE | C10: ='hse1'!C10 -> 27/1/2026 | N10: =O10-Q10 -> 23190 | O10: 23190
N11: =O11-Q11 -> 10910 | O11: 10910
B12: LAST PAY DATE | C12: ='hse1'!C12 -> 46144 | N12: =O12-Q12 -> 10910 | O12: 10910
N13: =O13-Q13 -> 12190 | O13: 12190
N14: =O14-Q14 -> 11070 | O14: 11070
B15: PREVIOUS READING | C15: CURRENT READING | E15: CONSUMPTION (Units) | N15: =O15-Q15 -> 9090 | O15: 9090
B16: =meter!D7 -> 125 | C16: =meter!E7 -> 126 | D16: Units | E16: =C16-B16 -> 1 | N16: =O16-Q16 -> 9420 | O16: 9420
E17: Amount(Kshs) | N17: =O17-Q17 -> 11154 | O17: 11154
C18: LAST ACCOUNT B/F | D18: Kshs. | E18: =meter!O7 -> 0 | N18: =O18-Q18 -> 10430 | O18: 10430
N19: =O19-Q19 -> 11831 | O19: 11831
C20: MONTH BILL | D20: Kshs. | E20: =meter!H7 -> 0 | N20: =O20-Q20 -> 10590 | O20: 10590
N21: =O21-Q21 -> 22423 | O21: 22423
C22: PUMP/POWER CHARGES | D22: Kshs. | E22: ='hse1'!E22 -> 110 | N22: =O22-Q22 -> 9250 | O22: 9250
N23: =O23-Q23 -> 10162 | O23: 10162
C24: MONTH HOUSE RENT | D24: Kshs. | N24: =O24-Q24 -> 10270 | O24: 10270
N25: =O25-Q25 -> 11070 | O25: 11070
C26: security | D26: ='hse1'!D26 -> Kshs. | E26: 500 | N26: =O26-Q26 -> 11550 | O26: 11550
C27: GARBAGE FEE | D27: Kshs. | E27: 150 | N27: =O27-Q27 -> 11393 | O27: 11393
C28: INTEREST ON ARREARS | D28: Kshs. | E28: =IF(E18*6%*3<0,0,E18*6%*3) -> 0 | N28: =O28-Q28 -> 10802 | O28: 10802
N29: =O29-Q29 -> 8930 | O29: 8930
C30: TOTAL PAYABLE | D30: Kshs. | E30: =SUM(E17:E29) -> 760 | N30: =O30-Q30 -> 9570 | O30: 9570
N31: =O31-Q31 -> 11390 | O31: 11390
C32: PAID | E32: =meter!R7 -> 0 | N32: =O32-Q32 -> 10750 | O32: 10750
N33: =O33-Q33 -> 11732 | O33: 11732
C34: AMOUNT DUE | E34: =E30-E32 -> 760 | N34: =O34-Q34 -> 10934 | O34: 10934 | R34: 700
B35: NOTE | N35: =O35-Q35 -> 10270 | O35: 10270
A36: a) | B36: Rent is due on or before 5th of the month. By 7th day, any rent not paid will attract interest at 2% per day. | N36: =O36-Q36 -> 10598 | O36: 10598
A37: b) | B37: Any default in Rent payment by 10th of the following month the house shall be locked without notice and belongings removed for re-letting. | N37: =O37-Q37 -> 8770 | O37: 8770
N38: =O38-Q38 -> 8770 | O38: 8770
A39: c) | B39: Amounts not cleared by last pay date will render to water disconnection. | O39: =SUM(O3:O38) -> 391268 | Q39: =SUM(Q3:Q38) -> 0
A41: d) | B41: A reconnection fee of Kshs. 1,000 will be charged and paid before supply is reconnected.
A42: e) | B42: ANY MINOR REPAIRS OCCURING AFTER 3 MONTHS OF OCCUPANCY ARE TENANT'S RESPONSIBILITY AS PER TENANCY AGREEMENT.
...

Sheet hse6B
B2: OLE SAMEDHA APARTMENTS-Kitengela | N2: VAR | O2: TAX DUE
B3: ='hse1'!B3 -> P.O BOX 9473-00200 NAIROBI | N3: =O3-Q3 -> 10270 | O3: 10270
B4: WATER BILL | F4: BILL NO. | G4: BILL NO. | H4: ='hse1'!H4+6-1 -> 20242006 | N4: =O4-Q4 -> 10304 | O4: 10304
N5: =O5-Q5 -> 10988 | O5: 10988
B6: TENANT NAME | C6: EVERLINE | N6: =O6-Q6 -> 11070 | O6: 11070
N7: =O7-Q7 -> 1197 | O7: 1197
B8: HOUSE NUMBER: | C8: 6B | N8: =O8-Q8 -> 9250 | O8: 9250
N9: =O9-Q9 -> 8770 | O9: 8770
B10: ISSUE DATE | C10: ='hse1'!C10 -> 27/1/2026 | N10: =O10-Q10 -> 23190 | O10: 23190
N11: =O11-Q11 -> 10910 | O11: 10910
B12: LAST PAY DATE | C12: ='hse1'!C12 -> 46144 | N12: =O12-Q12 -> 10910 | O12: 10910
N13: =O13-Q13 -> 12190 | O13: 12190
N14: =O14-Q14 -> 11070 | O14: 11070
B15: PREVIOUS READING | C15: CURRENT READING | E15: CONSUMPTION | N15: =O15-Q15 -> 9090 | O15: 9090
B16: =meter!D8 -> 450 | C16: =meter!E8 -> 450 | D16: Units | E16: =C16-B16 -> 0 | N16: =O16-Q16 -> 9420 | O16: 9420
E17: Amount(Kshs) | N17: =O17-Q17 -> 11154 | O17: 11154
C18: LAST ACCOUNT | D18: kshs. | E18: =meter!O8 -> 0 | N18: =O18-Q18 -> 10430 | O18: 10430
N19: =O19-Q19 -> 11831 | O19: 11831
C20: MONTH BILL | D20: KSHS. | E20: =meter!H8 -> 0 | N20: =O20-Q20 -> 10590 | O20: 10590
N21: =O21-Q21 -> 22423 | O21: 22423
C22: PUMP/POWER CHARGES | D22: KSHS. | E22: ='hse1'!E22 -> 110 | N22: =O22-Q22 -> 9250 | O22: 9250
N23: =O23-Q23 -> 10162 | O23: 10162
C24: MONTH HOUSE RENT | D24: KSHS. | E24: =meter!N8 -> 8500 | N24: =O24-Q24 -> 10270 | O24: 10270
N25: =O25-Q25 -> 11070 | O25: 11070
C26: ='hse1'!C26 -> security | D26: ='hse1'!D26 -> Kshs. | E26: =meter!M8 -> 0 | N26: =O26-Q26 -> 11550 | O26: 11550
C27: GARBAGE FEE | E27: 150 | N27: =O27-Q27 -> 11393 | O27: 11393
C28: ADJUSTMENT (Interest late payment) | D28: KSHS. | N28: =O28-Q28 -> 10802 | O28: 10802
N29: =O29-Q29 -> 8930 | O29: 8930
C30: TOTAL PAYABLE | D30: Kshs. | E30: =SUM(E17:E29) -> 8760 | N30: =O30-Q30 -> 9570 | O30: 9570
N31: =O31-Q31 -> 11390 | O31: 11390
C32: PAID | E32: 0 | N32: =O32-Q32 -> 10750 | O32: 10750
N33: =O33-Q33 -> 11732 | O33: 11732
C34: AMOUNT DUE | E34: =E30-E32 -> 8760 | N34: =O34-Q34 -> 10934 | O34: 10934 | R34: 700
B35: NOTE | C35: PAY & VACATE, REPAIRS CHARGES OF 8,400/- REMAINS TILL NEW TENANT LEAVES, THEN WE REPAIR | N35: =O35-Q35 -> 10270 | O35: 10270
A36: a) | B36: Rent is due on or before 5th of the month. By 7th day, any rent not paid will attract interest at 2% per day. | N36: =O36-Q36 -> 10598 | O36: 10598
A37: b) | B37: Any default in Rent payment by 10th of the following month the house shall be locked without notice and belongings removed for re-letting. | N37: =O37-Q37 -> 8770 | O37: 8770
N38: =O38-Q38 -> 8770 | O38: 8770
A39: c) | B39: Amounts not cleared by last pay date will render to water disconnection. | O39: =SUM(O3:O38) -> 391268 | Q39: =SUM(Q3:Q38) -> 0
A41: d) | B41: A reconnection fee of Kshs. 1,000 will be charged and paid before supply is reconnected.
A42: e) | B42: ANY MINOR REPAIRS OCCURING AFTER 3 MONTHS OF OCCUPANCY ARE TENANT'S RESPONSIBILITY AS PER TENANCY AGREEMENT.
...

Sheet hse7B
B2: OLE SAMEDHA APARTMENTS-Kitengela | N2: VAR | O2: TAX DUE
B3: ='hse1'!B3 -> P.O BOX 9473-00200 NAIROBI | N3: =O3-Q3 -> 10270 | O3: 10270
B4: WATER BILL | G4: BILL NO. | H4: ='hse1'!H4+7-1 -> 20242007 | N4: =O4-Q4 -> 10304 | O4: 10304
N5: =O5-Q5 -> 10988 | O5: 10988
B6: TENANT NAME | C6: AVRIL | N6: =O6-Q6 -> 11070 | O6: 11070
N7: =O7-Q7 -> 1197 | O7: 1197
B8: HOUSE NUMBER: | C8: 7B | N8: =O8-Q8 -> 9250 | O8: 9250
N9: =O9-Q9 -> 8770 | O9: 8770
B10: ISSUE DATE | C10: ='hse1'!C10 -> 27/1/2026 | N10: =O10-Q10 -> 23190 | O10: 23190
N11: =O11-Q11 -> 10910 | O11: 10910
B12: LAST PAY DATE | C12: ='hse1'!C12 -> 46144 | N12: =O12-Q12 -> 10910 | O12: 10910
N13: =O13-Q13 -> 12190 | O13: 12190
N14: =O14-Q14 -> 11070 | O14: 11070
B15: PREVIOUS READING | C15: CURRENT READING | E15: CONSUMPTION | N15: =O15-Q15 -> 9090 | O15: 9090
B16: =meter!D9 -> 630 | C16: =meter!E9 -> 630 | D16: Units | E16: =C16-B16 -> 0 | N16: =O16-Q16 -> 9420 | O16: 9420
E17: Amount (Kshs) | N17: =O17-Q17 -> 11154 | O17: 11154
C18: LAST ACCOUNT | D18: kshs. | E18: 0 | N18: =O18-Q18 -> 10430 | O18: 10430
N19: =O19-Q19 -> 11831 | O19: 11831
C20: MONTH BILL | D20: KSHS. | E20: =meter!H9 -> 0 | N20: =O20-Q20 -> 10590 | O20: 10590
N21: =O21-Q21 -> 22423 | O21: 22423
C22: PUMP/POWER CHARGES | D22: KSHS. | E22: ='hse1'!E22 -> 110 | N22: =O22-Q22 -> 9250 | O22: 9250
N23: =O23-Q23 -> 10162 | O23: 10162
C24: MONTH HOUSE RENT | D24: KSHS. | E24: 8500 | N24: =O24-Q24 -> 10270 | O24: 10270
N25: =O25-Q25 -> 11070 | O25: 11070
C26: ='hse1'!C26 -> security | D26: ='hse1'!D26 -> Kshs. | N26: =O26-Q26 -> 11550 | O26: 11550
C27: GARBAGE FEE | E27: 150 | N27: =O27-Q27 -> 11393 | O27: 11393
C28: ADJUSTMENT-interest on arrears | D28: KSHS. | E28: =IF(E18*6%*3<0,0,E18*6%*3) -> 0 | N28: =O28-Q28 -> 10802 | O28: 10802
N29: =O29-Q29 -> 8930 | O29: 8930
C30: TOTAL PAYABLE | D30: Kshs. | E30: =SUM(E17:E29) -> 8760 | N30: =O30-Q30 -> 9570 | O30: 9570
N31: =O31-Q31 -> 11390 | O31: 11390
C32: PAID | E32: 0 | N32: =O32-Q32 -> 10750 | O32: 10750
N33: =O33-Q33 -> 11732 | O33: 11732
C34: AMOUNT DUE | E34: =E30-E32 -> 8760 | N34: =O34-Q34 -> 10934 | O34: 10934 | R34: 700
B35: NOTE | N35: =O35-Q35 -> 10270 | O35: 10270
A36: a) | B36: Rent is due on or before 5th of the month. By 7th day, any rent not paid will attract interest at 2% per day. | N36: =O36-Q36 -> 10598 | O36: 10598
A37: b) | B37: Any default in Rent payment by 10th of the following month the house shall be locked without notice and belongings removed for re-letting. | N37: =O37-Q37 -> 8770 | O37: 8770
N38: =O38-Q38 -> 8770 | O38: 8770
A39: c) | B39: Amounts not cleared by last pay date will render to water disconnection. | O39: =SUM(O3:O38) -> 391268 | Q39: =SUM(Q3:Q38) -> 0
A41: d) | B41: A reconnection fee of Kshs. 1,000 will be charged and paid before supply is reconnected.
A42: e) | B42: ANY MINOR REPAIRS OCCURING AFTER 3 MONTHS OF OCCUPANCY ARE TENANT'S RESPONSIBILITY AS PER TENANCY AGREEMENT.
...

Sheet hse8
B2: OLE SAMEDHA APARTMENTS-Kitengela | N2: VAR | O2: TAX DUE
B3: ='hse1'!B3 -> P.O BOX 9473-00200 NAIROBI | N3: =O3-Q3 -> 10270 | O3: 10270
B4: WATER BILL | G4: BILL NO. | H4: ='hse1'!H4+8-1 -> 20242008 | N4: =O4-Q4 -> 10304 | O4: 10304
N5: =O5-Q5 -> 10988 | O5: 10988
B6: TENANT NAME | C6: =meter!A10 -> JAMES | N6: =O6-Q6 -> 11070 | O6: 11070
N7: =O7-Q7 -> 1197 | O7: 1197
B8: HOUSE NUMBER: | C8: 8A | N8: =O8-Q8 -> 9250 | O8: 9250
N9: =O9-Q9 -> 8770 | O9: 8770
B10: ISSUE DATE | C10: ='hse1'!C10 -> 27/1/2026 | N10: =O10-Q10 -> 23190 | O10: 23190
N11: =O11-Q11 -> 10910 | O11: 10910
B12: LAST PAY DATE | C12: ='hse1'!C12 -> 46144 | N12: =O12-Q12 -> 10910 | O12: 10910
N13: =O13-Q13 -> 12190 | O13: 12190
N14: =O14-Q14 -> 11070 | O14: 11070
B15: PREVIOUS READING | C15: CURRENT READING | E15: CONSUMPTION | N15: =O15-Q15 -> 9090 | O15: 9090
B16: =meter!D10 -> 48 | C16: =meter!E10 -> 53 | D16: Units | E16: =C16-B16 -> 5 | N16: =O16-Q16 -> 9420 | O16: 9420
E17: Amount (Kshs.) | N17: =O17-Q17 -> 11154 | O17: 11154
C18: LAST ACCOUNT | D18: kshs. | E18: =meter!O10 -> 0 | N18: =O18-Q18 -> 10430 | O18: 10430
N19: =O19-Q19 -> 11831 | O19: 11831
C20: MONTH BILL | D20: KSHS. | E20: =meter!H10 -> 1100 | N20: =O20-Q20 -> 10590 | O20: 10590
N21: =O21-Q21 -> 22423 | O21: 22423
C22: PUMP/POWER CHARGES | D22: KSHS. | E22: ='hse1'!E22 -> 110 | N22: =O22-Q22 -> 9250 | O22: 9250
N23: =O23-Q23 -> 10162 | O23: 10162
C24: MONTH HOUSE RENT | D24: KSHS. | E24: =meter!N10 -> 10500 | N24: =O24-Q24 -> 10270 | O24: 10270
N25: =O25-Q25 -> 11070 | O25: 11070
C26: ='hse1'!C26 -> security | D26: ='hse1'!D26 -> Kshs. | E26: 500 | N26: =O26-Q26 -> 11550 | O26: 11550
C27: GARBAGE FEE | D27: Kshs. | E27: 150 | N27: =O27-Q27 -> 11393 | O27: 11393
C28: ADJUSTMENT-interest on arrears | D28: KSHS. | E28: =IF(E18*6%*3<0,0,E18*6%*3) -> 0 | N28: =O28-Q28 -> 10802 | O28: 10802
N29: =O29-Q29 -> 8930 | O29: 8930
C30: TOTAL PAYABLE | D30: Kshs. | E30: =SUM(E17:E29) -> 12360 | N30: =O30-Q30 -> 9570 | O30: 9570
N31: =O31-Q31 -> 11390 | O31: 11390
C32: PAID | E32: =meter!R10 -> 0 | N32: =O32-Q32 -> 10750 | O32: 10750
N33: =O33-Q33 -> 11732 | O33: 11732
C34: AMOUNT DUE | E34: =E30-E32 -> 12360 | N34: =O34-Q34 -> 10934 | O34: 10934 | R34: 700
B35: NOTE | N35: =O35-Q35 -> 10270 | O35: 10270
A36: a) | B36: Rent is due on or before 5th of the month. By 7th day, any rent not paid will attract interest at 2% per day. | N36: =O36-Q36 -> 10598 | O36: 10598
A37: b) | B37: Any default in Rent payment by 10th of the following month the house shall be locked without notice and belongings removed for re-letting. | N37: =O37-Q37 -> 8770 | O37: 8770
N38: =O38-Q38 -> 8770 | O38: 8770
A39: c) | B39: Amounts not cleared by last pay date will render to water disconnection. | O39: =SUM(O3:O38) -> 391268 | Q39: =SUM(Q3:Q38) -> 0
A41: d) | B41: A reconnection fee of Kshs. 1,000 will be charged and paid before supply is reconnected.
A42: e) | B42: ANY MINOR REPAIRS OCCURING AFTER 3 MONTHS OF OCCUPANCY ARE TENANT'S RESPONSIBILITY AS PER TENANCY AGREEMENT.
...

Sheet hse9
B2: OLE SAMEDHA APARTMENTS-Kitengela | N2: VAR | O2: TAX DUE
B3: ='hse1'!B3 -> P.O BOX 9473-00200 NAIROBI | N3: =O3-Q3 -> 10270 | O3: 10270
B4: WATER BILL | G4: BILL NO. | H4: ='hse1'!H4+9-1 -> 20242009 | N4: =O4-Q4 -> 10304 | O4: 10304
N5: =O5-Q5 -> 10988 | O5: 10988
B6: TENANT NAME | C6: =meter!A11 -> CHERRYL | N6: =O6-Q6 -> 11070 | O6: 11070
N7: =O7-Q7 -> 1197 | O7: 1197
B8: HOUSE NUMBER: | C8: 9A | N8: =O8-Q8 -> 9250 | O8: 9250
N9: =O9-Q9 -> 8770 | O9: 8770
B10: ISSUE DATE | C10: ='hse1'!C10 -> 27/1/2026 | N10: =O10-Q10 -> 23190 | O10: 23190
N11: =O11-Q11 -> 10910 | O11: 10910
B12: LAST PAY DATE | C12: ='hse1'!C12 -> 46144 | N12: =O12-Q12 -> 10910 | O12: 10910
N13: =O13-Q13 -> 12190 | O13: 12190
N14: =O14-Q14 -> 11070 | O14: 11070
B15: PREVIOUS READING | C15: CURRENT READING | E15: CONSUMPTION | N15: =O15-Q15 -> 9090 | O15: 9090
B16: =meter!D11 -> 193 | C16: =meter!E11 -> 196 | D16: Units | E16: =C16-B16 -> 3 | N16: =O16-Q16 -> 9420 | O16: 9420
E17: Amount (Kshs.) | N17: =O17-Q17 -> 11154 | O17: 11154
C18: LAST ACCOUNT | D18: kshs. | E18: =meter!O11 -> 0 | N18: =O18-Q18 -> 10430 | O18: 10430
N19: =O19-Q19 -> 11831 | O19: 11831
C20: MONTH BILL | D20: KSHS. | E20: =meter!H11 -> 660 | N20: =O20-Q20 -> 10590 | O20: 10590
N21: =O21-Q21 -> 22423 | O21: 22423
C22: PUMP/POWER CHARGES | D22: KSHS. | E22: ='hse1'!E22 -> 110 | N22: =O22-Q22 -> 9250 | O22: 9250
N23: =O23-Q23 -> 10162 | O23: 10162
C24: MONTH HOUSE RENT | D24: KSHS. | E24: =meter!N11 -> 10500 | N24: =O24-Q24 -> 10270 | O24: 10270
N25: =O25-Q25 -> 11070 | O25: 11070
C26: ='hse1'!C26 -> security | D26: ='hse1'!D26 -> Kshs. | E26: 500 | N26: =O26-Q26 -> 11550 | O26: 11550
C27: GARBAGE FEE | D27: Kshs. | E27: 150 | N27: =O27-Q27 -> 11393 | O27: 11393
C28: Penalty & Interest late payment | D28: KSHS. | E28: =IF(E18*4%*1<0,0,E18*4%*1) -> 0 | N28: =O28-Q28 -> 10802 | O28: 10802
N29: =O29-Q29 -> 8930 | O29: 8930
C30: TOTAL PAYABLE | D30: Kshs. | E30: =SUM(E17:E29) -> 11920 | N30: =O30-Q30 -> 9570 | O30: 9570
N31: =O31-Q31 -> 11390 | O31: 11390
C32: PAID | E32: =meter!R11 -> 0 | N32: =O32-Q32 -> 10750 | O32: 10750
N33: =O33-Q33 -> 11732 | O33: 11732
C34: AMOUNT DUE | E34: =E30-E32 -> 11920 | N34: =O34-Q34 -> 10934 | O34: 10934 | R34: 700
B35: NOTE | N35: =O35-Q35 -> 10270 | O35: 10270
A36: a) | B36: Rent is due on or before 5th of the month. By 7th day, any rent not paid will attract interest at 2% per day. | N36: =O36-Q36 -> 10598 | O36: 10598
A37: b) | B37: Any default in Rent payment by 10th of the following month the house shall be locked without notice and belongings removed for re-letting. | N37: =O37-Q37 -> 8770 | O37: 8770
N38: =O38-Q38 -> 8770 | O38: 8770
A39: c) | B39: Amounts not cleared by last pay date will render to water disconnection. | O39: =SUM(O3:O38) -> 391268 | Q39: =SUM(Q3:Q38) -> 0
A41: d) | B41: A reconnection fee of Kshs. 1,000 will be charged and paid before supply is reconnected.
A42: e) | B42: ANY MINOR REPAIRS OCCURING AFTER 3 MONTHS OF OCCUPANCY ARE TENANT'S RESPONSIBILITY AS PER TENANCY AGREEMENT.
...

Sheet hse10
B2: OLE SAMEDHA APARTMENTS-Kitengela | N2: VAR | O2: TAX DUE
B3: ='hse1'!B3 -> P.O BOX 9473-00200 NAIROBI | N3: =O3-Q3 -> 10270 | O3: 10270
B4: WATER BILL | G4: BILL NO. | H4: ='hse1'!H4+10-1 -> 20242010 | N4: =O4-Q4 -> 10304 | O4: 10304
N5: =O5-Q5 -> 10988 | O5: 10988
B6: TENANT NAME | C6: =meter!A12 -> JACK | N6: =O6-Q6 -> 11070 | O6: 11070
N7: =O7-Q7 -> 1197 | O7: 1197
B8: HOUSE NUMBER: | C8: 10A | N8: =O8-Q8 -> 9250 | O8: 9250
N9: =O9-Q9 -> 8770 | O9: 8770
B10: ISSUE DATE | C10: ='hse1'!C10 -> 27/1/2026 | N10: =O10-Q10 -> 23190 | O10: 23190
N11: =O11-Q11 -> 10910 | O11: 10910
B12: LAST PAY DATE | C12: ='hse1'!C12 -> 46144 | N12: =O12-Q12 -> 10910 | O12: 10910
N13: =O13-Q13 -> 12190 | O13: 12190
N14: =O14-Q14 -> 11070 | O14: 11070
B15: PREVIOUS READING | C15: CURRENT READING | E15: CONSUMPTION | N15: =O15-Q15 -> 9090 | O15: 9090
B16: =meter!D12 -> 66 | C16: =meter!E12 -> 70 | D16: Units | E16: =C16-B16 -> 4 | N16: =O16-Q16 -> 9420 | O16: 9420
E17: Amount (Kshs) | N17: =O17-Q17 -> 11154 | O17: 11154
C18: LAST ACCOUNT | D18: kshs. | N18: =O18-Q18 -> 10430 | O18: 10430
N19: =O19-Q19 -> 11831 | O19: 11831
C20: MONTH BILL | D20: KSHS. | E20: =meter!H12 -> 880 | N20: =O20-Q20 -> 10590 | O20: 10590
N21: =O21-Q21 -> 22423 | O21: 22423
C22: PUMP/POWER CHARGES | D22: KSHS. | E22: ='hse1'!E22 -> 110 | N22: =O22-Q22 -> 9250 | O22: 9250
N23: =O23-Q23 -> 10162 | O23: 10162
C24: MONTH HOUSE RENT | D24: KSHS. | E24: =meter!N12 -> 10500 | N24: =O24-Q24 -> 10270 | O24: 10270
N25: =O25-Q25 -> 11070 | O25: 11070
C26: ='hse1'!C26 -> security | D26: KSHS. | E26: 500 | N26: =O26-Q26 -> 11550 | O26: 11550
C27: GARBAGE FEE | D27: KSHS. | E27: 150 | N27: =O27-Q27 -> 11393 | O27: 11393
C28: INTEREST ON LATE PAYMENT | D28: KSHS. | E28: =IF(E18*4%*1<0,0,E18*4%*1) -> 0 | N28: =O28-Q28 -> 10802 | O28: 10802
N29: =O29-Q29 -> 8930 | O29: 8930
C30: TOTAL PAYABLE | D30: Kshs. | E30: =SUM(E17:E29) -> 12140 | N30: =O30-Q30 -> 9570 | O30: 9570
N31: =O31-Q31 -> 11390 | O31: 11390
C32: PAID | E32: =meter!R12 -> 0 | N32: =O32-Q32 -> 10750 | O32: 10750
N33: =O33-Q33 -> 11732 | O33: 11732
C34: AMOUNT DUE | E34: =E30-E32 -> 12140 | N34: =O34-Q34 -> 10934 | O34: 10934 | R34: 700
B35: NOTE | N35: =O35-Q35 -> 10270 | O35: 10270
A36: a) | B36: Rent is due on or before 5th of the month. By 7th day, any rent not paid will attract interest at 2% per day. | N36: =O36-Q36 -> 10598 | O36: 10598
A37: b) | B37: Any default in Rent payment by 10th of the following month the house shall be locked without notice and belongings removed for re-letting. | N37: =O37-Q37 -> 8770 | O37: 8770
N38: =O38-Q38 -> 8770 | O38: 8770
A39: c) | B39: Amounts not cleared by last pay date will render to water disconnection. | O39: =SUM(O3:O38) -> 391268 | Q39: =SUM(Q3:Q38) -> 0
A41: d) | B41: A reconnection fee of Kshs. 1,000 will be charged and paid before supply is reconnected.
A42: e) | B42: ANY MINOR REPAIRS OCCURING AFTER 3 MONTHS OF OCCUPANCY ARE TENANT'S RESPONSIBILITY AS PER TENANCY AGREEMENT.
...

Sheet hse11
B2: OLE SAMEDHA APARTMENTS-Kitengela | N2: VAR | O2: TAX DUE
B3: ='hse1'!B3 -> P.O BOX 9473-00200 NAIROBI | N3: =O3-Q3 -> 10270 | O3: 10270
B4: WATER BILL | G4: BILL NO. | H4: ='hse1'!H4+11-1 -> 20242011 | N4: =O4-Q4 -> 10304 | O4: 10304
N5: =O5-Q5 -> 10988 | O5: 10988
B6: TENANT NAME | C6: =meter!A13 -> JAMES NGUGI | N6: =O6-Q6 -> 11070 | O6: 11070
N7: =O7-Q7 -> 1197 | O7: 1197
B8: HOUSE NUMBER: | C8: 11A | N8: =O8-Q8 -> 9250 | O8: 9250
N9: =O9-Q9 -> 8770 | O9: 8770
B10: ISSUE DATE | C10: ='hse1'!C10 -> 27/1/2026 | N10: =O10-Q10 -> 23190 | O10: 23190
N11: =O11-Q11 -> 10910 | O11: 10910
B12: LAST PAY DATE | C12: ='hse1'!C12 -> 46144 | N12: =O12-Q12 -> 10910 | O12: 10910
N13: =O13-Q13 -> 12190 | O13: 12190
N14: =O14-Q14 -> 11070 | O14: 11070
B15: PREVIOUS READING | C15: CURRENT READING | E15: CONSUMPTION | N15: =O15-Q15 -> 9090 | O15: 9090
B16: =meter!D13 -> 413 | C16: =meter!E13 -> 415 | D16: Units | E16: =C16-B16 -> 2 | N16: =O16-Q16 -> 9420 | O16: 9420
E17: Amount (Kshs.) | N17: =O17-Q17 -> 11154 | O17: 11154
C18: LAST ACCOUNT | D18: kshs. | E18: =meter!O13 -> 0 | N18: =O18-Q18 -> 10430 | O18: 10430
N19: =O19-Q19 -> 11831 | O19: 11831
C20: MONTH BILL | D20: KSHS. | E20: =meter!H13 -> 440 | N20: =O20-Q20 -> 10590 | O20: 10590
N21: =O21-Q21 -> 22423 | O21: 22423
C22: PUMP/POWER CHARGES | D22: KSHS. | E22: ='hse1'!E22 -> 110 | N22: =O22-Q22 -> 9250 | O22: 9250
N23: =O23-Q23 -> 10162 | O23: 10162
C24: MONTH HOUSE RENT | D24: KSHS. | E24: 9500 | N24: =O24-Q24 -> 10270 | O24: 10270
N25: =O25-Q25 -> 11070 | O25: 11070
C26: ='hse1'!C26 -> security | D26: KSHS. | E26: 500 | N26: =O26-Q26 -> 11550 | O26: 11550
C27: GARBAGE FEE | D27: KSHS. | E27: 150 | N27: =O27-Q27 -> 11393 | O27: 11393
C28: INTEREST ON LATE PAYMENT | D28: KSHS. | E28: =IF(E18*4%*1<0,0,E18*4%*1) -> 0 | N28: =O28-Q28 -> 10802 | O28: 10802
N29: =O29-Q29 -> 8930 | O29: 8930
C30: TOTAL PAYABLE | D30: Kshs. | E30: =SUM(E17:E29) -> 10700 | N30: =O30-Q30 -> 9570 | O30: 9570
N31: =O31-Q31 -> 11390 | O31: 11390
C32: PAID | E32: =meter!R13 -> 0 | N32: =O32-Q32 -> 10750 | O32: 10750
N33: =O33-Q33 -> 11732 | O33: 11732
C34: AMOUNT DUE | E34: =E30-E32 -> 10700 | N34: =O34-Q34 -> 10934 | O34: 10934 | R34: 700
B35: NOTE | N35: =O35-Q35 -> 10270 | O35: 10270
A36: a) | B36: Rent is due on or before 5th of the month. By 7th day, any rent not paid will attract interest at 2% per day. | N36: =O36-Q36 -> 10598 | O36: 10598
A37: b) | B37: Any default in Rent payment by 10th of the following month the house shall be locked without notice and belongings removed for re-letting. | N37: =O37-Q37 -> 8770 | O37: 8770
N38: =O38-Q38 -> 8770 | O38: 8770
A39: c) | B39: Amounts not cleared by last pay date will render to water disconnection. | O39: =SUM(O3:O38) -> 391268 | Q39: =SUM(Q3:Q38) -> 0
A41: d) | B41: A reconnection fee of Kshs. 1,000 will be charged and paid before supply is reconnected.
A42: e) | B42: ANY MINOR REPAIRS OCCURING AFTER 3 MONTHS OF OCCUPANCY ARE TENANT'S RESPONSIBILITY AS PER TENANCY AGREEMENT.
...

Sheet hse12
B2: OLE SAMEDHA APARTMENTS-Kitengela | N2: VAR | O2: TAX DUE
B3: ='hse1'!B3 -> P.O BOX 9473-00200 NAIROBI | N3: =O3-Q3 -> 10270 | O3: 10270
B4: WATER BILL | H4: BILL NO. | I4: ='hse1'!H4+12-1 -> 20242012 | J4: ='hse1'!H4+12-1 -> 20242012 | N4: =O4-Q4 -> 10304 | O4: 10304
N5: =O5-Q5 -> 10988 | O5: 10988
B6: TENANT NAME | D6: =meter!A14 -> LIMO | N6: =O6-Q6 -> 11070 | O6: 11070
N7: =O7-Q7 -> 1197 | O7: 1197
B8: HOUSE NUMBER: | D8: 12A | N8: =O8-Q8 -> 9250 | O8: 9250
N9: =O9-Q9 -> 8770 | O9: 8770
B10: ISSUE DATE | D10: ='hse1'!C10 -> 27/1/2026 | N10: =O10-Q10 -> 23190 | O10: 23190
N11: =O11-Q11 -> 10910 | O11: 10910
B12: LAST PAY DATE | D12: ='hse1'!C12 -> 46144 | N12: =O12-Q12 -> 10910 | O12: 10910
N13: =O13-Q13 -> 12190 | O13: 12190
N14: =O14-Q14 -> 11070 | O14: 11070
B15: PREVIOUS READING | D15: CURRENT READING | F15: CONSUMPTION | N15: =O15-Q15 -> 9090 | O15: 9090
B16: =meter!D14 -> 212 | D16: =meter!E14 -> 224 | E16: Units | F16: =D16-B16 -> 12 | N16: =O16-Q16 -> 9420 | O16: 9420
F17: Amount (Kshs.) | N17: =O17-Q17 -> 11154 | O17: 11154
D18: LAST ACCOUNT | E18: kshs. | F18: =meter!O14 -> 677 | N18: =O18-Q18 -> 10430 | O18: 10430
N19: =O19-Q19 -> 11831 | O19: 11831
D20: MONTH BILL | E20: KSHS. | F20: =meter!H14 -> 2640 | N20: =O20-Q20 -> 10590 | O20: 10590
N21: =O21-Q21 -> 22423 | O21: 22423
D22: PUMP/POWER CHARGES | E22: KSHS. | F22: ='hse1'!E22 -> 110 | N22: =O22-Q22 -> 9250 | O22: 9250
N23: =O23-Q23 -> 10162 | O23: 10162
D24: MONTH HOUSE RENT | E24: KSHS. | F24: =meter!N14 -> 10500 | N24: =O24-Q24 -> 10270 | O24: 10270
N25: =O25-Q25 -> 11070 | O25: 11070
D26: SECURITY | E26: KSHS. | F26: 500 | N26: =O26-Q26 -> 11550 | O26: 11550
D27: GARBAGE FEE | F27: 150 | N27: =O27-Q27 -> 11393 | O27: 11393
D28: INTEREST ON LATE PAYMENT | E28: KSHS. | F28: =IF(F18*4%*1<0,0,F18*4%*1) -> 27.08 | N28: =O28-Q28 -> 10802 | O28: 10802
N29: =O29-Q29 -> 8930 | O29: 8930
C30: TOTAL PAYABLE | D30: TOTAL PAYABLE | E30: Kshs. | F30: =SUM(F17:F29) -> 14604.08 | N30: =O30-Q30 -> 9570 | O30: 9570
N31: =O31-Q31 -> 11390 | O31: 11390
C32: PAID | D32: PAID | F32: =meter!R14 -> 0 | N32: =O32-Q32 -> 10750 | O32: 10750
N33: =O33-Q33 -> 11732 | O33: 11732
C34: BALANCE C/F | D34: AMOUNT DUE | F34: =F30-F32 -> 14604.08 | N34: =O34-Q34 -> 10934 | O34: 10934 | R34: 700
B35: NOTE | N35: =O35-Q35 -> 10270 | O35: 10270
A36: a) | B36: Rent is due on or before 5th of the month. By 7th day, any rent not paid will attract interest at 2% per day. | N36: =O36-Q36 -> 10598 | O36: 10598
A37: b) | B37: Any default in Rent payment by 10th of the following month the house shall be locked without notice and belongings removed for re-letting. | N37: =O37-Q37 -> 8770 | O37: 8770
N38: =O38-Q38 -> 8770 | O38: 8770
A39: c) | B39: Amounts not cleared by last pay date will render to water disconnection. | O39: =SUM(O3:O38) -> 391268 | Q39: =SUM(Q3:Q38) -> 0
A41: d) | B41: A reconnection fee of Kshs. 1,000 will be charged and paid before supply is reconnected.
A42: e) | B42: ANY MINOR REPAIRS OCCURING AFTER 3 MONTHS OF OCCUPANCY ARE TENANT'S RESPONSIBILITY AS PER TENANCY AGREEMENT.
...

Sheet hse13B
B2: OLE SAMEDHA APARTMENTS-Kitengela | N2: VAR | O2: TAX DUE
B3: ='hse1'!B3 -> P.O BOX 9473-00200 NAIROBI | N3: =O3-Q3 -> 10270 | O3: 10270
B4: WATER BILL | G4: BILL NO. | H4: ='hse1'!H4+13-1 -> 20242013 | N4: =O4-Q4 -> 10304 | O4: 10304
N5: =O5-Q5 -> 10988 | O5: 10988
B6: TENANT NAME | D6: =meter!A15 -> HARRIET | N6: =O6-Q6 -> 11070 | O6: 11070
N7: =O7-Q7 -> 1197 | O7: 1197
B8: HOUSE NUMBER: | D8: 13B | N8: =O8-Q8 -> 9250 | O8: 9250
N9: =O9-Q9 -> 8770 | O9: 8770
B10: ISSUE DATE | D10: ='hse1'!C10 -> 27/1/2026 | N10: =O10-Q10 -> 23190 | O10: 23190
N11: =O11-Q11 -> 10910 | O11: 10910
B12: LAST PAY DATE | D12: ='hse1'!C12 -> 46144 | N12: =O12-Q12 -> 10910 | O12: 10910
N13: =O13-Q13 -> 12190 | O13: 12190
N14: =O14-Q14 -> 11070 | O14: 11070
B15: PREVIOUS READING | D15: CURRENT READING | F15: CONSUMPTION | N15: =O15-Q15 -> 9090 | O15: 9090
B16: =meter!D15 -> 158 | D16: =meter!E15 -> 159 | E16: Units | F16: =D16-B16 -> 1 | N16: =O16-Q16 -> 9420 | O16: 9420
F17: Amount (Kshs.) | N17: =O17-Q17 -> 11154 | O17: 11154
D18: LAST ACCOUNT B/F | E18: kshs. | F18: =meter!O15 -> 0 | N18: =O18-Q18 -> 10430 | O18: 10430
N19: =O19-Q19 -> 11831 | O19: 11831
D20: MONTH BILL | E20: KSHS. | F20: =meter!H15 -> 220 | N20: =O20-Q20 -> 10590 | O20: 10590
N21: =O21-Q21 -> 22423 | O21: 22423
D22: PUMP/POWER CHARGES | E22: KSHS. | F22: ='hse1'!E22 -> 110 | N22: =O22-Q22 -> 9250 | O22: 9250
N23: =O23-Q23 -> 10162 | O23: 10162
D24: MONTH HOUSE RENT | E24: KSHS. | F24: =meter!N15 -> 8500 | N24: =O24-Q24 -> 10270 | O24: 10270
N25: =O25-Q25 -> 11070 | O25: 11070
D26: SECURITY | E26: KSHS. | F26: =meter!M15 -> 0 | N26: =O26-Q26 -> 11550 | O26: 11550
D27: GARBAGE FEE | E27: KSHS. | F27: 150 | N27: =O27-Q27 -> 11393 | O27: 11393
D28: INTEREST ON LATE PAYMENT | E28: KSHS. | F28: =IF(F18*4%*1<0,0,F18*4%*1) -> 0 | N28: =O28-Q28 -> 10802 | O28: 10802
N29: =O29-Q29 -> 8930 | O29: 8930
D30: TOTAL PAYABLE | E30: Kshs. | F30: =SUM(F17:F29) -> 8980 | N30: =O30-Q30 -> 9570 | O30: 9570
N31: =O31-Q31 -> 11390 | O31: 11390
D32: PAID | F32: =meter!R15 -> 0 | N32: =O32-Q32 -> 10750 | O32: 10750
N33: =O33-Q33 -> 11732 | O33: 11732
D34: AMOUNT DUE | F34: =F30-F32 -> 8980 | N34: =O34-Q34 -> 10934 | O34: 10934 | R34: 700
B35: NOTE | N35: =O35-Q35 -> 10270 | O35: 10270
A36: a) | B36: Rent is due on or before 5th of the month. By 7th day, any rent not paid will attract interest at 2% per day. | N36: =O36-Q36 -> 10598 | O36: 10598
A37: b) | B37: Any default in Rent payment by 10th of the following month the house shall be locked without notice and belongings removed for re-letting. | N37: =O37-Q37 -> 8770 | O37: 8770
N38: =O38-Q38 -> 8770 | O38: 8770
A39: c) | B39: Amounts not cleared by last pay date will render to water disconnection. | O39: =SUM(O3:O38) -> 391268 | Q39: =SUM(Q3:Q38) -> 0
A41: d) | B41: A reconnection fee of Kshs. 1,000 will be charged and paid before supply is reconnected.
A42: e) | B42: ANY MINOR REPAIRS OCCURING AFTER 3 MONTHS OF OCCUPANCY ARE TENANT'S RESPONSIBILITY AS PER TENANCY AGREEMENT.
...

Sheet hse14B
B2: OLE SAMEDHA APARTMENTS-Kitengela | N2: VAR | O2: TAX DUE
B3: ='hse1'!B3 -> P.O BOX 9473-00200 NAIROBI | N3: =O3-Q3 -> 10270 | O3: 10270
B4: WATER BILL | H4: BILL NO. | I4: ='hse1'!H4+14-1 -> 20242014 | J4: ='hse1'!H4+14-1 -> 20242014 | N4: =O4-Q4 -> 10304 | O4: 10304
N5: =O5-Q5 -> 10988 | O5: 10988
B6: TENANT NAME | D6: valentine | N6: =O6-Q6 -> 11070 | O6: 11070
N7: =O7-Q7 -> 1197 | O7: 1197
B8: HOUSE NUMBER: | D8: 14B | N8: =O8-Q8 -> 9250 | O8: 9250
N9: =O9-Q9 -> 8770 | O9: 8770
B10: ISSUE DATE | D10: ='hse1'!C10 -> 27/1/2026 | N10: =O10-Q10 -> 23190 | O10: 23190
N11: =O11-Q11 -> 10910 | O11: 10910
B12: LAST PAY DATE | D12: ='hse1'!C12 -> 46144 | N12: =O12-Q12 -> 10910 | O12: 10910
N13: =O13-Q13 -> 12190 | O13: 12190
N14: =O14-Q14 -> 11070 | O14: 11070
B15: PREVIOUS READING | D15: CURRENT READING | F15: CONSUMPTION | N15: =O15-Q15 -> 9090 | O15: 9090
B16: =meter!D16 -> 714 | D16: =meter!E16 -> 716 | E16: Units | F16: =D16-B16 -> 2 | H16: ESTIMATE | N16: =O16-Q16 -> 9420 | O16: 9420
F17: Amount (Kshs.) | N17: =O17-Q17 -> 11154 | O17: 11154
D18: LAST ACCOUNT B/F | E18: kshs. | F18: =meter!O16 -> 820 | N18: =O18-Q18 -> 10430 | O18: 10430
N19: =O19-Q19 -> 11831 | O19: 11831
D20: MONTH BILL | E20: KSHS. | F20: =meter!H16 -> 440 | N20: =O20-Q20 -> 10590 | O20: 10590
N21: =O21-Q21 -> 22423 | O21: 22423
D22: PUMP/POWER CHARGES | E22: KSHS. | F22: ='hse1'!E22 -> 110 | N22: =O22-Q22 -> 9250 | O22: 9250
N23: =O23-Q23 -> 10162 | O23: 10162
D24: MONTH HOUSE RENT | E24: KSHS. | F24: 8500 | N24: =O24-Q24 -> 10270 | O24: 10270
N25: =O25-Q25 -> 11070 | O25: 11070
D26: SECURITY | E26: ='hse1'!D26 -> Kshs. | F26: 500 | N26: =O26-Q26 -> 11550 | O26: 11550
D27: GARBAGE FEE | E27: Kshs. | F27: 150 | N27: =O27-Q27 -> 11393 | O27: 11393
D28: ADJUSTMENT (Interest late payment) | E28: KSHS. | F28: =IF(F18*4%*1<0,0,F18*4%*1) -> 32.8 | N28: =O28-Q28 -> 10802 | O28: 10802
N29: =O29-Q29 -> 8930 | O29: 8930
D30: TOTAL PAYABLE | E30: Kshs. | F30: =SUM(F17:F29) -> 10552.8 | N30: =O30-Q30 -> 9570 | O30: 9570
N31: =O31-Q31 -> 11390 | O31: 11390
D32: PAID | F32: =meter!R16 -> 0 | N32: =O32-Q32 -> 10750 | O32: 10750
N33: =O33-Q33 -> 11732 | O33: 11732
D34: AMOUNT DUE | F34: =F30-F32 -> 10552.8 | N34: =O34-Q34 -> 10934 | O34: 10934 | R34: 700
C35: NOTE | N35: =O35-Q35 -> 10270 | O35: 10270
A36: a) | B36: Rent is due on or before 5th of the month. By 7th day, any rent not paid will attract interest at 2% per day. | N36: =O36-Q36 -> 10598 | O36: 10598
A37: b) | B37: Any default in Rent payment by 10th of the following month the house shall be locked without notice and belongings removed for re-letting. | N37: =O37-Q37 -> 8770 | O37: 8770
N38: =O38-Q38 -> 8770 | O38: 8770
A39: c) | B39: Amounts not cleared by last pay date will render to water disconnection. | O39: =SUM(O3:O38) -> 391268 | Q39: =SUM(Q3:Q38) -> 0
A41: d) | B41: A reconnection fee of Kshs. 1,000 will be charged and paid before supply is reconnected.
A42: e) | B42: ANY MINOR REPAIRS OCCURING AFTER 3 MONTHS OF OCCUPANCY ARE TENANT'S RESPONSIBILITY AS PER TENANCY AGREEMENT.
...

Sheet hse 15
B2: OLE SAMEDHA APARTMENTS-Kitengela | N2: VAR | O2: TAX DUE
B3: ='hse1'!B3 -> P.O BOX 9473-00200 NAIROBI | N3: =O3-Q3 -> 10270 | O3: 10270
B4: WATER BILL | H4: BILL NO. | I4: ='hse1'!H4+15-1 -> 20242015 | J4: ='hse1'!H4+15-1 -> 20242015 | N4: =O4-Q4 -> 10304 | O4: 10304
N5: =O5-Q5 -> 10988 | O5: 10988
B6: TENANT NAME | D6: =meter!A17 -> ASHA | N6: =O6-Q6 -> 11070 | O6: 11070
N7: =O7-Q7 -> 1197 | O7: 1197
B8: HOUSE NUMBER: | D8: 15A | N8: =O8-Q8 -> 9250 | O8: 9250
N9: =O9-Q9 -> 8770 | O9: 8770
B10: ISSUE DATE | D10: ='hse1'!C10 -> 27/1/2026 | N10: =O10-Q10 -> 23190 | O10: 23190
N11: =O11-Q11 -> 10910 | O11: 10910
B12: LAST PAY DATE | D12: ='hse1'!C12 -> 46144 | N12: =O12-Q12 -> 10910 | O12: 10910
N13: =O13-Q13 -> 12190 | O13: 12190
N14: =O14-Q14 -> 11070 | O14: 11070
B15: PREVIOUS READING | D15: CURRENT READING | F15: CONSUMPTION | N15: =O15-Q15 -> 9090 | O15: 9090
B16: =meter!D17 -> 195 | D16: =meter!E17 -> 200 | E16: Units | F16: =D16-B16 -> 5 | N16: =O16-Q16 -> 9420 | O16: 9420
F17: Amount (Kshs) | N17: =O17-Q17 -> 11154 | O17: 11154
D18: LAST ACCOUNT B/F | E18: kshs. | F18: =meter!O17 -> 677 | N18: =O18-Q18 -> 10430 | O18: 10430
N19: =O19-Q19 -> 11831 | O19: 11831
D20: MONTH BILL | E20: KSHS. | F20: =meter!H17 -> 1100 | N20: =O20-Q20 -> 10590 | O20: 10590
N21: =O21-Q21 -> 22423 | O21: 22423
D22: PUMP/POWER CHARGES | E22: KSHS. | F22: ='hse1'!E22 -> 110 | N22: =O22-Q22 -> 9250 | O22: 9250
N23: =O23-Q23 -> 10162 | O23: 10162
D24: MONTH HOUSE RENT | E24: KSHS. | F24: =meter!N17 -> 10500 | N24: =O24-Q24 -> 10270 | O24: 10270
N25: =O25-Q25 -> 11070 | O25: 11070
D26: ='hse1'!C26 -> security | E26: ='hse1'!D26 -> Kshs. | N26: =O26-Q26 -> 11550 | O26: 11550
D27: GARBAGE FEE | E27: Kshs. | F27: 150 | N27: =O27-Q27 -> 11393 | O27: 11393
D28: ADJUSTMENT (Interest late payment) | E28: KSHS. | F28: =IF(F18*4%*1<0,0,F18*4%*1) -> 27.08 | N28: =O28-Q28 -> 10802 | O28: 10802
N29: =O29-Q29 -> 8930 | O29: 8930
C30: TOTAL PAYABLE | D30: AMOUNT PAYABLE | E30: Kshs. | F30: =SUM(F17:F29) -> 12564.08 | N30: =O30-Q30 -> 9570 | O30: 9570
N31: =O31-Q31 -> 11390 | O31: 11390
C32: PAID | E32: KSHS | F32: 5000 | N32: =O32-Q32 -> 10750 | O32: 10750
N33: =O33-Q33 -> 11732 | O33: 11732
C34: BALANCE C/F | D34: AMOUNT DUE | E34: KSHS. | F34: =F30-F32 -> 7564.08 | N34: =O34-Q34 -> 10934 | O34: 10934 | R34: 700
B35: NOTE | N35: =O35-Q35 -> 10270 | O35: 10270
A36: a) | B36: Rent is due on or before 5th of the month. By 7th day, any rent not paid will attract interest at 2% per day. | N36: =O36-Q36 -> 10598 | O36: 10598
A37: b) | B37: Any default in Rent payment by 10th of the following month the house shall be locked without notice and belongings removed for re-letting. | N37: =O37-Q37 -> 8770 | O37: 8770
N38: =O38-Q38 -> 8770 | O38: 8770
A39: c) | B39: Amounts not cleared by last pay date will render to water disconnection. | O39: =SUM(O3:O38) -> 391268 | Q39: =SUM(Q3:Q38) -> 0
A41: d) | B41: A reconnection fee of Kshs. 1,000 will be charged and paid before supply is reconnected.
A42: e) | B42: ANY MINOR REPAIRS OCCURING AFTER 3 MONTHS OF OCCUPANCY ARE TENANT'S RESPONSIBILITY AS PER TENANCY AGREEMENT.
...

Sheet hse16
B2: OLE SAMEDHA APARTMENTS-Kitengela | N2: VAR | O2: TAX DUE
B3: ='hse1'!B3 -> P.O BOX 9473-00200 NAIROBI | N3: =O3-Q3 -> 10270 | O3: 10270
B4: WATER BILL | H4: BILL NO. | I4: ='hse1'!H4+16-1 -> 20242016 | M4: ='hse1'!H4+16-1 -> 20242016 | N4: =O4-Q4 -> 10304 | O4: 10304
N5: =O5-Q5 -> 10988 | O5: 10988
B6: TENANT NAME | D6: =meter!A18 -> VACCANT | N6: =O6-Q6 -> 11070 | O6: 11070
N7: =O7-Q7 -> 1197 | O7: 1197
B8: HOUSE NUMBER: | D8: 16A | N8: =O8-Q8 -> 9250 | O8: 9250
N9: =O9-Q9 -> 8770 | O9: 8770
B10: ISSUE DATE | D10: ='hse1'!C10 -> 27/1/2026 | N10: =O10-Q10 -> 23190 | O10: 23190
N11: =O11-Q11 -> 10910 | O11: 10910
B12: LAST PAY DATE | D12: ='hse1'!C12 -> 46144 | N12: =O12-Q12 -> 10910 | O12: 10910
N13: =O13-Q13 -> 12190 | O13: 12190
N14: =O14-Q14 -> 11070 | O14: 11070
B15: PREVIOUS READING | D15: CURRENT READING | F15: CONSUMPTION | N15: =O15-Q15 -> 9090 | O15: 9090
B16: =meter!D18 -> 190 | D16: =meter!E18 -> 190 | E16: Units | F16: =D16-B16 -> 0 | N16: =O16-Q16 -> 9420 | O16: 9420
F17: Amount (Kshs.) | N17: =O17-Q17 -> 11154 | O17: 11154
D18: LAST ACCOUNT B/F | E18: kshs. | F18: =meter!O18 -> 677 | N18: =O18-Q18 -> 10430 | O18: 10430
N19: =O19-Q19 -> 11831 | O19: 11831
D20: MONTH BILL | E20: KSHS. | F20: =meter!H18 -> 0 | N20: =O20-Q20 -> 10590 | O20: 10590
N21: =O21-Q21 -> 22423 | O21: 22423
D22: PUMP/POWER CHARGES | E22: KSHS. | F22: ='hse1'!E22 -> 110 | N22: =O22-Q22 -> 9250 | O22: 9250
N23: =O23-Q23 -> 10162 | O23: 10162
D24: MONTH HOUSE RENT | E24: KSHS. | F24: =meter!N18 -> 10500 | N24: =O24-Q24 -> 10270 | O24: 10270
N25: =O25-Q25 -> 11070 | O25: 11070
D26: ='hse1'!C26 -> security | E26: ='hse1'!D26 -> Kshs. | F26: ='hse1'!E26 -> 500 | N26: =O26-Q26 -> 11550 | O26: 11550
D27: GARBAGE FEE | E27: Kshs. | F27: 150 | N27: =O27-Q27 -> 11393 | O27: 11393
D28: ADJUSTMENT-INTEREST LATE PAYMENT | E28: KSHS. | F28: =IF(F18*4%*1<0,0,F18*4%*1) -> 27.08 | N28: =O28-Q28 -> 10802 | O28: 10802
N29: =O29-Q29 -> 8930 | O29: 8930
D30: TOTAL PAYABLE | E30: Kshs. | F30: =SUM(F17:F29) -> 11964.08 | N30: =O30-Q30 -> 9570 | O30: 9570
N31: =O31-Q31 -> 11390 | O31: 11390
D32: PAID | F32: =meter!R18 -> 0 | N32: =O32-Q32 -> 10750 | O32: 10750
N33: =O33-Q33 -> 11732 | O33: 11732
D34: AMOUNT DUE | F34: =F30-F32 -> 11964.08 | N34: =O34-Q34 -> 10934 | O34: 10934 | R34: 700
C35: NOTE | N35: =O35-Q35 -> 10270 | O35: 10270
A36: a) | B36: Rent is due on or before 5th of the month. By 7th day, any rent not paid will attract interest at 2% per day. | N36: =O36-Q36 -> 10598 | O36: 10598
A37: b) | B37: Any default in Rent payment by 10th of the following month the house shall be locked without notice and belongings removed for re-letting. | N37: =O37-Q37 -> 8770 | O37: 8770
N38: =O38-Q38 -> 8770 | O38: 8770
A39: c) | B39: Amounts not cleared by last pay date will render to water disconnection. | O39: =SUM(O3:O38) -> 391268 | Q39: =SUM(Q3:Q38) -> 0
A41: d) | B41: A reconnection fee of Kshs. 1,000 will be charged and paid before supply is reconnected.
A42: e) | B42: ANY MINOR REPAIRS OCCURING AFTER 3 MONTHS OF OCCUPANCY ARE TENANT'S RESPONSIBILITY AS PER TENANCY AGREEMENT.
...

Sheet hse17
B2: OLE SAMEDHA APARTMENTS-Kitengela | N2: VAR | O2: TAX DUE
B3: ='hse1'!B3 -> P.O BOX 9473-00200 NAIROBI | N3: =O3-Q3 -> 10270 | O3: 10270
B4: WATER BILL | H4: BILL NO. | I4: ='hse1'!H4+17-1 -> 20242017 | J4: ='hse1'!H4+17-1 -> 20242017 | N4: =O4-Q4 -> 10304 | O4: 10304
N5: =O5-Q5 -> 10988 | O5: 10988
B6: TENANT NAME | D6: =meter!A19 -> JOASH | N6: =O6-Q6 -> 11070 | O6: 11070
N7: =O7-Q7 -> 1197 | O7: 1197
B8: HOUSE NUMBER: | D8: 17A | N8: =O8-Q8 -> 9250 | O8: 9250
D9: 0775203183 | N9: =O9-Q9 -> 8770 | O9: 8770
B10: ISSUE DATE | D10: ='hse1'!C10 -> 27/1/2026 | N10: =O10-Q10 -> 23190 | O10: 23190
N11: =O11-Q11 -> 10910 | O11: 10910
B12: LAST PAY DATE | D12: ='hse1'!C12 -> 46144 | N12: =O12-Q12 -> 10910 | O12: 10910
N13: =O13-Q13 -> 12190 | O13: 12190
N14: =O14-Q14 -> 11070 | O14: 11070
B15: PREVIOUS READING | D15: CURRENT READING | F15: CONSUMPTION | N15: =O15-Q15 -> 9090 | O15: 9090
B16: =meter!D19 -> 484 | D16: =meter!E19 -> 487 | E16: Units | F16: =D16-B16 -> 3 | N16: =O16-Q16 -> 9420 | O16: 9420
F17: Amount (Kshs.) | N17: =O17-Q17 -> 11154 | O17: 11154
D18: LAST ACCOUNT B/F | E18: kshs. | F18: =meter!O19 -> 1000 | N18: =O18-Q18 -> 10430 | O18: 10430
N19: =O19-Q19 -> 11831 | O19: 11831
D20: MONTH BILL | E20: KSHS. | F20: =meter!H19 -> 660 | N20: =O20-Q20 -> 10590 | O20: 10590
N21: =O21-Q21 -> 22423 | O21: 22423
D22: PUMP/POWER CHARGES | E22: KSHS. | F22: ='hse1'!E22 -> 110 | N22: =O22-Q22 -> 9250 | O22: 9250
N23: =O23-Q23 -> 10162 | O23: 10162
D24: MONTH HOUSE RENT | E24: KSHS. | F24: 11000 | N24: =O24-Q24 -> 10270 | O24: 10270
N25: =O25-Q25 -> 11070 | O25: 11070
D26: ='hse1'!C26 -> security | E26: ='hse1'!D26 -> Kshs. | N26: =O26-Q26 -> 11550 | O26: 11550
D27: GARBAGE FEE | E27: Kshs. | F27: 150 | N27: =O27-Q27 -> 11393 | O27: 11393
D28: INTEREST LATE PAYMENT | E28: KSHS. | F28: =IF(F18*8%*1<0,0,F18*8%*1) -> 80 | N28: =O28-Q28 -> 10802 | O28: 10802
N29: =O29-Q29 -> 8930 | O29: 8930
D30: TOTAL PAYABLE | E30: Kshs. | F30: =SUM(F17:F29) -> 13000 | N30: =O30-Q30 -> 9570 | O30: 9570
N31: =O31-Q31 -> 11390 | O31: 11390
D32: PAID | F32: =meter!R19 -> 0 | N32: =O32-Q32 -> 10750 | O32: 10750
N33: =O33-Q33 -> 11732 | O33: 11732
D34: AMOUNT DUE | F34: =F30-F32 -> 13000 | N34: =O34-Q34 -> 10934 | O34: 10934 | R34: 700
C35: NOTE | N35: =O35-Q35 -> 10270 | O35: 10270
A36: a) | B36: Rent is due on or before 5th of the month. By 7th day, any rent not paid will attract interest at 2% per day. | N36: =O36-Q36 -> 10598 | O36: 10598
A37: b) | B37: Any default in Rent payment by 10th of the following month the house shall be locked without notice and belongings removed for re-letting. | N37: =O37-Q37 -> 8770 | O37: 8770
N38: =O38-Q38 -> 8770 | O38: 8770
A39: c) | B39: Amounts not cleared by last pay date will render to water disconnection. | O39: =SUM(O3:O38) -> 391268 | Q39: =SUM(Q3:Q38) -> 0
A41: d) | B41: A reconnection fee of Kshs. 1,000 will be charged and paid before supply is reconnected.
A42: e) | B42: ANY MINOR REPAIRS OCCURING AFTER 3 MONTHS OF OCCUPANCY ARE TENANT'S RESPONSIBILITY AS PER TENANCY AGREEMENT.
...

Sheet hse18
B2: OLE SAMEDHA APARTMENTS-Kitengela | N2: VAR | O2: TAX DUE
B3: ='hse1'!B3 -> P.O BOX 9473-00200 NAIROBI | N3: =O3-Q3 -> 10270 | O3: 10270
B4: WATER BILL | H4: BILL NO. | I4: ='hse1'!H4+18-1 -> 20242018 | K4: ='hse1'!H4+18-1 -> 20242018 | N4: =O4-Q4 -> 10304 | O4: 10304
N5: =O5-Q5 -> 10988 | O5: 10988
B6: TENANT NAME | D6: =meter!A20 -> MOSES NJUGUNA | N6: =O6-Q6 -> 11070 | O6: 11070
N7: =O7-Q7 -> 1197 | O7: 1197
B8: HOUSE NUMBER | D8: 18A | N8: =O8-Q8 -> 9250 | O8: 9250
N9: =O9-Q9 -> 8770 | O9: 8770
B10: ISSUE DATE | D10: ='hse1'!C10 -> 27/1/2026 | N10: =O10-Q10 -> 23190 | O10: 23190
N11: =O11-Q11 -> 10910 | O11: 10910
B12: LAST PAY DATE | D12: ='hse1'!C12 -> 46144 | N12: =O12-Q12 -> 10910 | O12: 10910
N13: =O13-Q13 -> 12190 | O13: 12190
N14: =O14-Q14 -> 11070 | O14: 11070
B15: PREVIOUS READING | D15: CURRENT READING | F15: CONSUMPTION | N15: =O15-Q15 -> 9090 | O15: 9090
B16: =meter!D20 -> 210 | D16: =meter!E20 -> 213 | E16: Units | F16: =D16-B16 -> 3 | N16: =O16-Q16 -> 9420 | O16: 9420
F17: Amount (Kshs.) | N17: =O17-Q17 -> 11154 | O17: 11154
D18: LAST ACCOUNT B/F | E18: Kshs. | F18: =meter!O20 -> 1750 | N18: =O18-Q18 -> 10430 | O18: 10430
N19: =O19-Q19 -> 11831 | O19: 11831
D20: MONTH BILL | E20: KSHS. | F20: =meter!H20 -> 660 | N20: =O20-Q20 -> 10590 | O20: 10590
N21: =O21-Q21 -> 22423 | O21: 22423
D22: PUMP/POWER CHARGES | E22: KSHS. | F22: ='hse1'!E22 -> 110 | N22: =O22-Q22 -> 9250 | O22: 9250
N23: =O23-Q23 -> 10162 | O23: 10162
D24: MONTH HOUSE RENT | E24: KSHS. | F24: 10000 | N24: =O24-Q24 -> 10270 | O24: 10270
N25: =O25-Q25 -> 11070 | O25: 11070
D26: ='hse1'!C26 -> security | E26: ='hse1'!D26 -> Kshs. | F26: 500 | N26: =O26-Q26 -> 11550 | O26: 11550
D27: GARBAGE FEE | E27: Kshs. | F27: 150 | N27: =O27-Q27 -> 11393 | O27: 11393
D28: ADJUSTMENT (Interest late payment) | E28: KSHS. | F28: =IF(F18*4%*1<0,0,F18*4%*1) -> 70 | N28: =O28-Q28 -> 10802 | O28: 10802
N29: =O29-Q29 -> 8930 | O29: 8930
D30: TOTAL PAYABLE | E30: Kshs. | F30: =SUM(F17:F29) -> 13240 | N30: =O30-Q30 -> 9570 | O30: 9570
N31: =O31-Q31 -> 11390 | O31: 11390
D32: PAID | F32: =meter!R20 -> 0 | N32: =O32-Q32 -> 10750 | O32: 10750
N33: =O33-Q33 -> 11732 | O33: 11732
D34: AMOUNT DUE | F34: =F30-F32 -> 13240 | N34: =O34-Q34 -> 10934 | O34: 10934 | R34: 700
C35: NOTE | N35: =O35-Q35 -> 10270 | O35: 10270
A36: a) | B36: Rent is due on or before 5th of the month. By 7th day, any rent not paid will attract interest at 2% per day. | N36: =O36-Q36 -> 10598 | O36: 10598
A37: b) | B37: Any default in Rent payment by 10th of the following month the house shall be locked without notice and belongings removed for re-letting. | N37: =O37-Q37 -> 8770 | O37: 8770
N38: =O38-Q38 -> 8770 | O38: 8770
A39: c) | B39: Amounts not cleared by last pay date will render to water disconnection. | O39: =SUM(O3:O38) -> 391268 | Q39: =SUM(Q3:Q38) -> 0
A41: d) | B41: A reconnection fee of Kshs. 1,000 will be charged and paid before supply is reconnected.
A42: e) | B42: ANY MINOR REPAIRS OCCURING AFTER 3 MONTHS OF OCCUPANCY ARE TENANT'S RESPONSIBILITY AS PER TENANCY AGREEMENT.
...

Sheet hse19
B2: OLE SAMEDHA APARTMENTS-Kitengela | N2: VAR | O2: TAX DUE
B3: ='hse1'!B3 -> P.O BOX 9473-00200 NAIROBI | N3: =O3-Q3 -> 10270 | O3: 10270
B4: WATER BILL | G4: BILL NO. | H4: ='hse1'!H4+19-1 -> 20242019 | I4: ='hse1'!H4+19-1 -> 20242019 | N4: =O4-Q4 -> 10304 | O4: 10304
G5: ='hse1'!H4+19-1 -> 20242019 | N5: =O5-Q5 -> 10988 | O5: 10988
B6: TENANT NAME | D6: =meter!A21 -> DAGLOUS | N6: =O6-Q6 -> 11070 | O6: 11070
N7: =O7-Q7 -> 1197 | O7: 1197
B8: HOUSE NUMBER: | D8: 19A | N8: =O8-Q8 -> 9250 | O8: 9250
N9: =O9-Q9 -> 8770 | O9: 8770
B10: ISSUE DATE | D10: ='hse1'!C10 -> 27/1/2026 | N10: =O10-Q10 -> 23190 | O10: 23190
N11: =O11-Q11 -> 10910 | O11: 10910
B12: LAST PAY DATE | D12: ='hse1'!C12 -> 46144 | N12: =O12-Q12 -> 10910 | O12: 10910
N13: =O13-Q13 -> 12190 | O13: 12190
N14: =O14-Q14 -> 11070 | O14: 11070
B15: PREVIOUS READING | D15: CURRENT READING | F15: CONSUMPTION | N15: =O15-Q15 -> 9090 | O15: 9090
B16: =meter!D21 -> 55 | D16: =meter!E21 -> 59 | E16: Units | F16: =D16-B16+I16 -> 4 | N16: =O16-Q16 -> 9420 | O16: 9420
F17: Amount (Kshs.) | N17: =O17-Q17 -> 11154 | O17: 11154
D18: LAST ACCOUNT B/F | E18: Kshs. | N18: =O18-Q18 -> 10430 | O18: 10430
N19: =O19-Q19 -> 11831 | O19: 11831
D20: MONTH BILL | E20: KSHS. | F20: =meter!H21 -> 880 | N20: =O20-Q20 -> 10590 | O20: 10590
N21: =O21-Q21 -> 22423 | O21: 22423
D22: PUMP/POWER CHARGES | E22: KSHS. | F22: ='hse1'!E22 -> 110 | N22: =O22-Q22 -> 9250 | O22: 9250
N23: =O23-Q23 -> 10162 | O23: 10162
D24: MONTH HOUSE RENT | E24: KSHS. | F24: =meter!N21 -> 10500 | N24: =O24-Q24 -> 10270 | O24: 10270
N25: =O25-Q25 -> 11070 | O25: 11070
D26: ='hse1'!C26 -> security | E26: ='hse1'!D26 -> Kshs. | N26: =O26-Q26 -> 11550 | O26: 11550
D27: GARBAGE FEE | E27: Kshs. | F27: 150 | N27: =O27-Q27 -> 11393 | O27: 11393
D28: ADJUSTMENT-Interest on arrears | E28: KSHS. | F28: =IF(F18*8%*1<0,0,F18*8%*1) -> 0 | N28: =O28-Q28 -> 10802 | O28: 10802
N29: =O29-Q29 -> 8930 | O29: 8930
D30: TOTAL PAYABLE | E30: Kshs. | F30: =SUM(F17:F29) -> 11640 | N30: =O30-Q30 -> 9570 | O30: 9570
N31: =O31-Q31 -> 11390 | O31: 11390
D32: PAID | F32: =meter!R21 -> 0 | N32: =O32-Q32 -> 10750 | O32: 10750
N33: =O33-Q33 -> 11732 | O33: 11732
D34: AMOUNT DUE | F34: =F30-F32 -> 11640 | N34: =O34-Q34 -> 10934 | O34: 10934 | R34: 700
C35: NOTE | N35: =O35-Q35 -> 10270 | O35: 10270
A36: a) | B36: Rent is due on or before 5th of the month. By 7th day, any rent not paid will attract interest at 2% per day. | N36: =O36-Q36 -> 10598 | O36: 10598
A37: b) | B37: Any default in Rent payment by 10th of the following month the house shall be locked without notice and belongings removed for re-letting. | N37: =O37-Q37 -> 8770 | O37: 8770
N38: =O38-Q38 -> 8770 | O38: 8770
A39: c) | B39: Amounts not cleared by last pay date will render to water disconnection. | O39: =SUM(O3:O38) -> 391268 | Q39: =SUM(Q3:Q38) -> 0
A41: d) | B41: A reconnection fee of Kshs. 1,000 will be charged and paid before supply is reconnected.
A42: e) | B42: ANY MINOR REPAIRS OCCURING AFTER 3 MONTHS OF OCCUPANCY ARE TENANT'S RESPONSIBILITY AS PER TENANCY AGREEMENT.
...

Sheet hse20B
B2: OLE SAMEDHA APARTMENTS-Kitengela | N2: VAR | O2: TAX DUE
B3: ='hse1'!B3 -> P.O BOX 9473-00200 NAIROBI | N3: =O3-Q3 -> 10270 | O3: 10270
B4: WATER BILL | H4: BILL NO. | I4: ='hse1'!H4+20-1 -> 20242020 | J4: ='hse1'!H4+20-1 -> 20242020 | N4: =O4-Q4 -> 10304 | O4: 10304
N5: =O5-Q5 -> 10988 | O5: 10988
B6: TENANT NAME | D6: =meter!A22 -> OWEN | N6: =O6-Q6 -> 11070 | O6: 11070
N7: =O7-Q7 -> 1197 | O7: 1197
B8: HOUSE NUMBER: | D8: 20B | N8: =O8-Q8 -> 9250 | O8: 9250
N9: =O9-Q9 -> 8770 | O9: 8770
B10: ISSUE DATE | D10: ='hse1'!C10 -> 27/1/2026 | N10: =O10-Q10 -> 23190 | O10: 23190
N11: =O11-Q11 -> 10910 | O11: 10910
B12: LAST PAY DATE | D12: ='hse1'!C12 -> 46144 | N12: =O12-Q12 -> 10910 | O12: 10910
N13: =O13-Q13 -> 12190 | O13: 12190
N14: =O14-Q14 -> 11070 | O14: 11070
B15: PREVIOUS READING | D15: CURRENT READING | F15: CONSUMPTION | N15: =O15-Q15 -> 9090 | O15: 9090
B16: =meter!D22 -> 265 | D16: =meter!E22 -> 267 | E16: Units | F16: =D16-B16 -> 2 | N16: =O16-Q16 -> 9420 | O16: 9420
N17: =O17-Q17 -> 11154 | O17: 11154
D18: LAST ACCOUNT B/F | E18: Kshs. | N18: =O18-Q18 -> 10430 | O18: 10430
N19: =O19-Q19 -> 11831 | O19: 11831
D20: MONTH BILL | E20: KSHS. | F20: =meter!H22 -> 440 | N20: =O20-Q20 -> 10590 | O20: 10590
N21: =O21-Q21 -> 22423 | O21: 22423
D22: PUMP/POWER CHARGES | E22: KSHS. | F22: 110 | N22: =O22-Q22 -> 9250 | O22: 9250
N23: =O23-Q23 -> 10162 | O23: 10162
D24: MONTH HOUSE RENT | E24: KSHS. | F24: 8500 | N24: =O24-Q24 -> 10270 | O24: 10270
N25: =O25-Q25 -> 11070 | O25: 11070
D26: security | E26: ='hse1'!D26 -> Kshs. | F26: 0 | N26: =O26-Q26 -> 11550 | O26: 11550
D27: GARBAGE FEE | E27: Kshs. | F27: 150 | N27: =O27-Q27 -> 11393 | O27: 11393
D28: ADJUSTMENT-interest on arrears | E28: KSHS. | N28: =O28-Q28 -> 10802 | O28: 10802
N29: =O29-Q29 -> 8930 | O29: 8930
D30: TOTAL PAYABLE | E30: Kshs. | F30: =SUM(F17:F29) -> 9200 | N30: =O30-Q30 -> 9570 | O30: 9570
N31: =O31-Q31 -> 11390 | O31: 11390
D32: PAID | F32: 0 | N32: =O32-Q32 -> 10750 | O32: 10750
N33: =O33-Q33 -> 11732 | O33: 11732
D34: AMOUNT DUE | F34: =F30-F32 -> 9200 | N34: =O34-Q34 -> 10934 | O34: 10934 | R34: 700
C35: NOTE | N35: =O35-Q35 -> 10270 | O35: 10270
