Workbook

Sheet FROM BOREHOLE
B2: SAMEDHA BOREHOLE | N2: VAR | O2: TAX DUE
B3: P.O BOX 9473-00200 NAIROBI | N3: =O3-Q3 -> 10270 | O3: 10270
B4: WATER BILL | G4: BILL NO. | H4: 20242001 | N4: =O4-Q4 -> 10304 | O4: 10304
N5: =O5-Q5 -> 10988 | O5: 10988
B6: NAME | C6: =meter!A3 -> From Borehole | N6: =O6-Q6 -> 11070 | O6: 11070
N7: =O7-Q7 -> 1197 | O7: 1197
N8: =O8-Q8 -> 9250 | O8: 9250
N9: =O9-Q9 -> 8770 | O9: 8770
B10: ISSUE DATE | C10: 29TH JAN 2025 | N10: =O10-Q10 -> 23190 | O10: 23190
N11: =O11-Q11 -> 10910 | O11: 10910
B12: LAST PAY DATE | C12: 5TH FEB 2026 | N12: =O12-Q12 -> 10910 | O12: 10910
N13: =O13-Q13 -> 12190 | O13: 12190
N14: =O14-Q14 -> 11070 | O14: 11070
B15: PREVIOUS READING | C15: CURRENT READING | E15: CONSUMPTION (Units) | N15: =O15-Q15 -> 9090 | O15: 9090
B16: =meter!D3 -> 227 | C16: =meter!E3 -> 1280 | D16: Units | E16: =C16-B16 -> 1053 | N16: =O16-Q16 -> 9420 | O16: 9420
E17: AMOUNT KSHS | N17: =O17-Q17 -> 11154 | O17: 11154
C18: LAST ACCOUNT B/F | D18: Kshs. | E18: =meter!J3 -> 0 | N18: =O18-Q18 -> 10430 | O18: 10430
N19: =O19-Q19 -> 11831 | O19: 11831
C20: MONTH Water BILL | D20: Kshs. | E20: =meter!H3 -> 105300 | N20: =O20-Q20 -> 10590 | O20: 10590
N21: =O21-Q21 -> 22423 | O21: 22423
N22: =O22-Q22 -> 9250 | O22: 9250
N23: =O23-Q23 -> 10162 | O23: 10162
N24: =O24-Q24 -> 10270 | O24: 10270
N25: =O25-Q25 -> 11070 | O25: 11070
N26: =O26-Q26 -> 11550 | O26: 11550
N27: =O27-Q27 -> 11393 | O27: 11393
N28: =O28-Q28 -> 10802 | O28: 10802
N29: =O29-Q29 -> 8930 | O29: 8930
C30: TOTAL PAYABLE | D30: Kshs. | E30: =E18+E20+E22+E24+E26+E27+E28 -> 105300 | N30: =O30-Q30 -> 9570 | O30: 9570
N31: =O31-Q31 -> 11390 | O31: 11390
C32: PAID | E32: 0 | N32: =O32-Q32 -> 10750 | O32: 10750
N33: =O33-Q33 -> 11732 | O33: 11732
C34: AMOUNT DUE | E34: =E30-E32 -> 105300 | N34: =O34-Q34 -> 10934 | O34: 10934 | R34: 700
B35: NOTE | N35: =O35-Q35 -> 10270 | O35: 10270
N36: =O36-Q36 -> 10598 | O36: 10598
A37: b) | N37: =O37-Q37 -> 8770 | O37: 8770
N38: =O38-Q38 -> 8770 | O38: 8770
A39: c) | O39: =SUM(O3:O38) -> 391268 | Q39: =SUM(Q3:Q38) -> 0
A41: d)
A42: e)
...

Sheet OUT BOREHOLE
B2: SAMEDHA BOREHOLE | N2: VAR | O2: TAX DUE
B3: ='FROM BOREHOLE'!B3 -> P.O BOX 9473-00200 NAIROBI | N3: =O3-Q3 -> 10270 | O3: 10270
B4: WATER BILL | F4: BILL NO. | G4: ='FROM BOREHOLE'!H4+2-1 -> 20242002 | N4: =O4-Q4 -> 10304 | O4: 10304
N5: =O5-Q5 -> 10988 | O5: 10988
B6: NAME | D6: =meter!A4 -> Out Borehole | N6: =O6-Q6 -> 11070 | O6: 11070
N7: =O7-Q7 -> 1197 | O7: 1197
N8: =O8-Q8 -> 9250 | O8: 9250
N9: =O9-Q9 -> 8770 | O9: 8770
B10: ISSUE DATE | D10: ='FROM BOREHOLE'!C10 -> 29TH JAN 2025 | N10: =O10-Q10 -> 23190 | O10: 23190
N11: =O11-Q11 -> 10910 | O11: 10910
B12: LAST PAY DATE | D12: ='FROM BOREHOLE'!C12 -> 5TH FEB 2026 | N12: =O12-Q12 -> 10910 | O12: 10910
N13: =O13-Q13 -> 12190 | O13: 12190
N14: =O14-Q14 -> 11070 | O14: 11070
B15: PREVIOUS READING | D15: CURRENT READING | F15: CONSUMPTION (Units) | N15: =O15-Q15 -> 9090 | O15: 9090
B16: =meter!D4 -> 15801 | D16: =meter!E4 -> 16894 | E16: Units | F16: =D16-B16 -> 1093 | N16: =O16-Q16 -> 9420 | O16: 9420
F17: Amount (Kshs.) | N17: =O17-Q17 -> 11154 | O17: 11154
D18: LAST COUNT | F18: =meter!J4 -> 0 | N18: =O18-Q18 -> 10430 | O18: 10430
N19: =O19-Q19 -> 11831 | O19: 11831
D20: MONTH BILL | E20: Kshs. | F20: =meter!H4 -> 109300 | N20: =O20-Q20 -> 10590 | O20: 10590
N21: =O21-Q21 -> 22423 | O21: 22423
N22: =O22-Q22 -> 9250 | O22: 9250
N23: =O23-Q23 -> 10162 | O23: 10162
N24: =O24-Q24 -> 10270 | O24: 10270
N25: =O25-Q25 -> 11070 | O25: 11070
N26: =O26-Q26 -> 11550 | O26: 11550
N27: =O27-Q27 -> 11393 | O27: 11393
N28: =O28-Q28 -> 10802 | O28: 10802
N29: =O29-Q29 -> 8930 | O29: 8930
D30: TOTAL PAYABLE | E30: Kshs. | F30: =SUM(F17:F29) -> 109300 | N30: =O30-Q30 -> 9570 | O30: 9570
N31: =O31-Q31 -> 11390 | O31: 11390
D32: PAID | F32: 0 | N32: =O32-Q32 -> 10750 | O32: 10750
N33: =O33-Q33 -> 11732 | O33: 11732
D34: AMOUNT DUE | F34: =F30-F32 -> 109300 | N34: =O34-Q34 -> 10934 | O34: 10934 | R34: 700
C35: NOTE | N35: =O35-Q35 -> 10270 | O35: 10270
B36: a) | N36: =O36-Q36 -> 10598 | O36: 10598
B37: b) | N37: =O37-Q37 -> 8770 | O37: 8770
N38: =O38-Q38 -> 8770 | O38: 8770
B39: c) | O39: =SUM(O3:O38) -> 391268 | Q39: =SUM(Q3:Q38) -> 0
B41: d)
B42: e)
...

Sheet NEW OUT B
B2: SAMEDHA BOREHOLE | N2: VAR | O2: TAX DUE
B3: ='FROM BOREHOLE'!B3 -> P.O BOX 9473-00200 NAIROBI | N3: =O3-Q3 -> 10270 | O3: 10270
B4: WATER BILL | G4: BILL NO. | H4: ='FROM BOREHOLE'!H4+3-1 -> 20242003 | N4: =O4-Q4 -> 10304 | O4: 10304
N5: =O5-Q5 -> 10988 | O5: 10988
B6: NAME | C6: =meter!A5 -> New Out Borehole | N6: =O6-Q6 -> 11070 | O6: 11070
N7: =O7-Q7 -> 1197 | O7: 1197
N8: =O8-Q8 -> 9250 | O8: 9250
N9: =O9-Q9 -> 8770 | O9: 8770
B10: ISSUE DATE | C10: ='FROM BOREHOLE'!C10 -> 29TH JAN 2025 | N10: =O10-Q10 -> 23190 | O10: 23190
N11: =O11-Q11 -> 10910 | O11: 10910
B12: LAST PAY DATE | C12: ='FROM BOREHOLE'!C12 -> 5TH FEB 2026 | N12: =O12-Q12 -> 10910 | O12: 10910
N13: =O13-Q13 -> 12190 | O13: 12190
N14: =O14-Q14 -> 11070 | O14: 11070
B15: PREVIOUS READING | C15: CURRENT READING | E15: CONSUMPTION (Units) | N15: =O15-Q15 -> 9090 | O15: 9090
B16: =meter!D5 -> 11651 | C16: =meter!E5 -> 12600 | D16: Units | E16: =C16-B16 -> 949 | N16: =O16-Q16 -> 9420 | O16: 9420
E17: Amount (Kshs.) | N17: =O17-Q17 -> 11154 | O17: 11154
C18: LAST ACCOUNT B/F | D18: Kshs. | E18: =meter!J5 -> 0 | N18: =O18-Q18 -> 10430 | O18: 10430
N19: =O19-Q19 -> 11831 | O19: 11831
C20: MONTH BILL | D20: Kshs. | E20: =meter!H5 -> 94900 | N20: =O20-Q20 -> 10590 | O20: 10590
N21: =O21-Q21 -> 22423 | O21: 22423
N22: =O22-Q22 -> 9250 | O22: 9250
N23: =O23-Q23 -> 10162 | O23: 10162
N24: =O24-Q24 -> 10270 | O24: 10270
N25: =O25-Q25 -> 11070 | O25: 11070
N26: =O26-Q26 -> 11550 | O26: 11550
N27: =O27-Q27 -> 11393 | O27: 11393
N28: =O28-Q28 -> 10802 | O28: 10802
N29: =O29-Q29 -> 8930 | O29: 8930
C30: TOTAL PAYABLE | D30: Kshs. | E30: =SUM(E17:E29) -> 94900 | N30: =O30-Q30 -> 9570 | O30: 9570
N31: =O31-Q31 -> 11390 | O31: 11390
C32: PAID | E32: =meter!L5 -> 0 | N32: =O32-Q32 -> 10750 | O32: 10750
N33: =O33-Q33 -> 11732 | O33: 11732
C34: AMOUNT DUE | E34: =E30-E32 -> 94900 | N34: =O34-Q34 -> 10934 | O34: 10934 | R34: 700
B35: NOTE | N35: =O35-Q35 -> 10270 | O35: 10270
A36: a) | N36: =O36-Q36 -> 10598 | O36: 10598
A37: b) | N37: =O37-Q37 -> 8770 | O37: 8770
N38: =O38-Q38 -> 8770 | O38: 8770
A39: c) | O39: =SUM(O3:O38) -> 391268 | Q39: =SUM(Q3:Q38) -> 0
A41: d)
A42: e)
...

Sheet LORRY
B2: SAMEDHA BOREHOLE | N2: VAR | O2: TAX DUE
B3: ='FROM BOREHOLE'!B3 -> P.O BOX 9473-00200 NAIROBI | N3: =O3-Q3 -> 10270 | O3: 10270
B4: WATER BILL | G4: BILL NO. | H4: ='FROM BOREHOLE'!H4+4-1 -> 20242004 | N4: =O4-Q4 -> 10304 | O4: 10304
N5: =O5-Q5 -> 10988 | O5: 10988
B6: NAME | C6: =meter!A6 -> Lorry Water | N6: =O6-Q6 -> 11070 | O6: 11070
N7: =O7-Q7 -> 1197 | O7: 1197
N8: =O8-Q8 -> 9250 | O8: 9250
N9: =O9-Q9 -> 8770 | O9: 8770
B10: ISSUE DATE | C10: ='FROM BOREHOLE'!C10 -> 29TH JAN 2025 | N10: =O10-Q10 -> 23190 | O10: 23190
N11: =O11-Q11 -> 10910 | O11: 10910
B12: LAST PAY DATE | C12: ='FROM BOREHOLE'!C12 -> 5TH FEB 2026 | N12: =O12-Q12 -> 10910 | O12: 10910
N13: =O13-Q13 -> 12190 | O13: 12190
N14: =O14-Q14 -> 11070 | O14: 11070
B15: PREVIOUS READING | C15: CURRENT READING | E15: CONSUMPTION | N15: =O15-Q15 -> 9090 | O15: 9090
B16: =meter!D6 -> 9968 | C16: =meter!E6 -> 9968 | D16: Units | E16: =C16-B16 -> 0 | N16: =O16-Q16 -> 9420 | O16: 9420
E17: Amount (Kshs) | N17: =O17-Q17 -> 11154 | O17: 11154
C18: LAST ACCOUNT B/F | D18: Kshs. | E18: =meter!J6 -> 0 | N18: =O18-Q18 -> 10430 | O18: 10430
N19: =O19-Q19 -> 11831 | O19: 11831
C20: MONTH BILL | D20: Kshs. | E20: =meter!H6 -> 0 | N20: =O20-Q20 -> 10590 | O20: 10590
N21: =O21-Q21 -> 22423 | O21: 22423
N22: =O22-Q22 -> 9250 | O22: 9250
N23: =O23-Q23 -> 10162 | O23: 10162
N24: =O24-Q24 -> 10270 | O24: 10270
N25: =O25-Q25 -> 11070 | O25: 11070
N26: =O26-Q26 -> 11550 | O26: 11550
N27: =O27-Q27 -> 11393 | O27: 11393
N28: =O28-Q28 -> 10802 | O28: 10802
N29: =O29-Q29 -> 8930 | O29: 8930
C30: TOTAL PAYABLE | D30: Kshs. | E30: =SUM(E17:E29) -> 0 | N30: =O30-Q30 -> 9570 | O30: 9570
N31: =O31-Q31 -> 11390 | O31: 11390
C32: PAID | E32: =meter!L6 -> 0 | N32: =O32-Q32 -> 10750 | O32: 10750
N33: =O33-Q33 -> 11732 | O33: 11732
C34: AMOUNT DUE | E34: =E30-E32 -> 0 | N34: =O34-Q34 -> 10934 | O34: 10934 | R34: 700
B35: NOTE | N35: =O35-Q35 -> 10270 | O35: 10270
N36: =O36-Q36 -> 10598 | O36: 10598
N37: =O37-Q37 -> 8770 | O37: 8770
N38: =O38-Q38 -> 8770 | O38: 8770
O39: =SUM(O3:O38) -> 391268 | Q39: =SUM(Q3:Q38) -> 0
O49: ……………

Sheet PASSION
B2: SAMEDHA BOREHOLE | N2: VAR | O2: TAX DUE
B3: ='FROM BOREHOLE'!B3 -> P.O BOX 9473-00200 NAIROBI | N3: =O3-Q3 -> 10270 | O3: 10270
B4: WATER BILL | G4: BILL NO. | H4: ='FROM BOREHOLE'!H4+5-1 -> 20242005 | N4: =O4-Q4 -> 10304 | O4: 10304
N5: =O5-Q5 -> 10988 | O5: 10988
B6: NAME | C6: =meter!A7 -> PASSION FARM A | N6: =O6-Q6 -> 11070 | O6: 11070
N7: =O7-Q7 -> 1197 | O7: 1197
N8: =O8-Q8 -> 9250 | O8: 9250
N9: =O9-Q9 -> 8770 | O9: 8770
B10: ISSUE DATE | C10: ='FROM BOREHOLE'!C10 -> 29TH JAN 2025 | N10: =O10-Q10 -> 23190 | O10: 23190
N11: =O11-Q11 -> 10910 | O11: 10910
B12: LAST PAY DATE | C12: ='FROM BOREHOLE'!C12 -> 5TH FEB 2026 | N12: =O12-Q12 -> 10910 | O12: 10910
N13: =O13-Q13 -> 12190 | O13: 12190
N14: =O14-Q14 -> 11070 | O14: 11070
B15: PREVIOUS READING | C15: CURRENT READING | E15: CONSUMPTION (Units) | N15: =O15-Q15 -> 9090 | O15: 9090
B16: =meter!D7 -> 6881 | C16: =meter!E7 -> 0 | D16: Units | E16: =C16-B16 -> -6881 | N16: =O16-Q16 -> 9420 | O16: 9420
E17: Amount(Kshs) | N17: =O17-Q17 -> 11154 | O17: 11154
C18: LAST ACCOUNT B/F | D18: Kshs. | E18: =meter!J7 -> 0 | N18: =O18-Q18 -> 10430 | O18: 10430
N19: =O19-Q19 -> 11831 | O19: 11831
C20: MONTH BILL | D20: Kshs. | E20: =meter!H7 -> -688100 | N20: =O20-Q20 -> 10590 | O20: 10590
N21: =O21-Q21 -> 22423 | O21: 22423
N22: =O22-Q22 -> 9250 | O22: 9250
N23: =O23-Q23 -> 10162 | O23: 10162
N24: =O24-Q24 -> 10270 | O24: 10270
N25: =O25-Q25 -> 11070 | O25: 11070
N26: =O26-Q26 -> 11550 | O26: 11550
N27: =O27-Q27 -> 11393 | O27: 11393
N28: =O28-Q28 -> 10802 | O28: 10802
N29: =O29-Q29 -> 8930 | O29: 8930
C30: TOTAL PAYABLE | D30: Kshs. | E30: =SUM(E17:E29) -> -688100 | N30: =O30-Q30 -> 9570 | O30: 9570
N31: =O31-Q31 -> 11390 | O31: 11390
C32: PAID | E32: =meter!L7 -> 0 | N32: =O32-Q32 -> 10750 | O32: 10750
N33: =O33-Q33 -> 11732 | O33: 11732
C34: AMOUNT DUE | E34: =E30-E32 -> -688100 | N34: =O34-Q34 -> 10934 | O34: 10934 | R34: 700
B35: NOTE | N35: =O35-Q35 -> 10270 | O35: 10270
A36: a) | N36: =O36-Q36 -> 10598 | O36: 10598
A37: b) | N37: =O37-Q37 -> 8770 | O37: 8770
N38: =O38-Q38 -> 8770 | O38: 8770
A39: c) | O39: =SUM(O3:O38) -> 391268 | Q39: =SUM(Q3:Q38) -> 0
A41: d)
A42: e)
...

Sheet BLOCK A
B2: SAMEDHA BOREHOLE | N2: VAR | O2: TAX DUE
B3: ='FROM BOREHOLE'!B3 -> P.O BOX 9473-00200 NAIROBI | N3: =O3-Q3 -> 10270 | O3: 10270
B4: WATER BILL | F4: BILL NO. | G4: BILL NO. | H4: ='FROM BOREHOLE'!H4+6-1 -> 20242006 | N4: =O4-Q4 -> 10304 | O4: 10304
N5: =O5-Q5 -> 10988 | O5: 10988
B6: NAME | C6: BLOCK A | N6: =O6-Q6 -> 11070 | O6: 11070
N7: =O7-Q7 -> 1197 | O7: 1197
N8: =O8-Q8 -> 9250 | O8: 9250
N9: =O9-Q9 -> 8770 | O9: 8770
B10: ISSUE DATE | C10: ='FROM BOREHOLE'!C10 -> 29TH JAN 2025 | N10: =O10-Q10 -> 23190 | O10: 23190
N11: =O11-Q11 -> 10910 | O11: 10910
B12: LAST PAY DATE | C12: ='FROM BOREHOLE'!C12 -> 5TH FEB 2026 | N12: =O12-Q12 -> 10910 | O12: 10910
N13: =O13-Q13 -> 12190 | O13: 12190
N14: =O14-Q14 -> 11070 | O14: 11070
B15: PREVIOUS READING | C15: CURRENT READING | E15: CONSUMPTION | N15: =O15-Q15 -> 9090 | O15: 9090
B16: =meter!D8 -> 4256 | C16: =meter!E8 -> 4256 | D16: Units | E16: =C16-B16 -> 0 | N16: =O16-Q16 -> 9420 | O16: 9420
E17: Amount(Kshs) | N17: =O17-Q17 -> 11154 | O17: 11154
C18: LAST ACCOUNT | D18: kshs. | E18: =meter!J8 -> 0 | N18: =O18-Q18 -> 10430 | O18: 10430
N19: =O19-Q19 -> 11831 | O19: 11831
C20: MONTH BILL | D20: KSHS. | E20: =meter!H8 -> 0 | N20: =O20-Q20 -> 10590 | O20: 10590
N21: =O21-Q21 -> 22423 | O21: 22423
N22: =O22-Q22 -> 9250 | O22: 9250
N23: =O23-Q23 -> 10162 | O23: 10162
N24: =O24-Q24 -> 10270 | O24: 10270
N25: =O25-Q25 -> 11070 | O25: 11070
C26: ='FROM BOREHOLE'!C26 -> 0 | N26: =O26-Q26 -> 11550 | O26: 11550
N27: =O27-Q27 -> 11393 | O27: 11393
N28: =O28-Q28 -> 10802 | O28: 10802
N29: =O29-Q29 -> 8930 | O29: 8930
C30: TOTAL PAYABLE | D30: Kshs. | E30: =SUM(E17:E29) -> 0 | N30: =O30-Q30 -> 9570 | O30: 9570
N31: =O31-Q31 -> 11390 | O31: 11390
C32: PAID | E32: 0 | N32: =O32-Q32 -> 10750 | O32: 10750
N33: =O33-Q33 -> 11732 | O33: 11732
C34: AMOUNT DUE | E34: =E30-E32 -> 0 | N34: =O34-Q34 -> 10934 | O34: 10934 | R34: 700
B35: NOTE | N35: =O35-Q35 -> 10270 | O35: 10270
A36: a) | N36: =O36-Q36 -> 10598 | O36: 10598
A37: b) | N37: =O37-Q37 -> 8770 | O37: 8770
N38: =O38-Q38 -> 8770 | O38: 8770
A39: c) | O39: =SUM(O3:O38) -> 391268 | Q39: =SUM(Q3:Q38) -> 0
A41: d)
A42: e)
...

Sheet BLOCK B
B2: SAMEDHA BOREHOLE | N2: VAR | O2: TAX DUE
B3: ='FROM BOREHOLE'!B3 -> P.O BOX 9473-00200 NAIROBI | N3: =O3-Q3 -> 10270 | O3: 10270
B4: WATER BILL | G4: BILL NO. | H4: ='FROM BOREHOLE'!H4+7-1 -> 20242007 | N4: =O4-Q4 -> 10304 | O4: 10304
N5: =O5-Q5 -> 10988 | O5: 10988
B6: NAME | C6: =meter!A9 -> BLOCK B | N6: =O6-Q6 -> 11070 | O6: 11070
N7: =O7-Q7 -> 1197 | O7: 1197
N8: =O8-Q8 -> 9250 | O8: 9250
N9: =O9-Q9 -> 8770 | O9: 8770
B10: ISSUE DATE | C10: ='FROM BOREHOLE'!C10 -> 29TH JAN 2025 | N10: =O10-Q10 -> 23190 | O10: 23190
N11: =O11-Q11 -> 10910 | O11: 10910
B12: LAST PAY DATE | C12: ='FROM BOREHOLE'!C12 -> 5TH FEB 2026 | N12: =O12-Q12 -> 10910 | O12: 10910
N13: =O13-Q13 -> 12190 | O13: 12190
N14: =O14-Q14 -> 11070 | O14: 11070
B15: PREVIOUS READING | C15: CURRENT READING | E15: CONSUMPTION | N15: =O15-Q15 -> 9090 | O15: 9090
B16: =meter!D9 -> 1099 | C16: =meter!E9 -> 1099 | D16: Units | E16: =C16-B16 -> 0 | N16: =O16-Q16 -> 9420 | O16: 9420
E17: Amount (Kshs) | N17: =O17-Q17 -> 11154 | O17: 11154
C18: LAST ACCOUNT | D18: kshs. | E18: =meter!J9 -> 0 | N18: =O18-Q18 -> 10430 | O18: 10430
N19: =O19-Q19 -> 11831 | O19: 11831
C20: MONTH BILL | D20: KSHS. | E20: =meter!H9 -> 0 | N20: =O20-Q20 -> 10590 | O20: 10590
N21: =O21-Q21 -> 22423 | O21: 22423
N22: =O22-Q22 -> 9250 | O22: 9250
N23: =O23-Q23 -> 10162 | O23: 10162
N24: =O24-Q24 -> 10270 | O24: 10270
N25: =O25-Q25 -> 11070 | O25: 11070
C26: ='FROM BOREHOLE'!C26 -> 0 | D26: ='FROM BOREHOLE'!D26 -> 0 | N26: =O26-Q26 -> 11550 | O26: 11550
N27: =O27-Q27 -> 11393 | O27: 11393
E28: =IF(E18*6%*3<0,0,E18*6%*3) -> 0 | N28: =O28-Q28 -> 10802 | O28: 10802
N29: =O29-Q29 -> 8930 | O29: 8930
C30: TOTAL PAYABLE | D30: Kshs. | E30: =SUM(E17:E29) -> 0 | N30: =O30-Q30 -> 9570 | O30: 9570
N31: =O31-Q31 -> 11390 | O31: 11390
C32: PAID | E32: 0 | N32: =O32-Q32 -> 10750 | O32: 10750
N33: =O33-Q33 -> 11732 | O33: 11732
C34: AMOUNT DUE | E34: =E30-E32 -> 0 | N34: =O34-Q34 -> 10934 | O34: 10934 | R34: 700
B35: NOTE | N35: =O35-Q35 -> 10270 | O35: 10270
A36: a) | N36: =O36-Q36 -> 10598 | O36: 10598
A37: b) | N37: =O37-Q37 -> 8770 | O37: 8770
N38: =O38-Q38 -> 8770 | O38: 8770
A39: c) | O39: =SUM(O3:O38) -> 391268 | Q39: =SUM(Q3:Q38) -> 0
A41: d)
A42: e)
...

Sheet NEW BLOCK
B2: SAMEDHA BOREHOLE | N2: VAR | O2: TAX DUE
B3: ='FROM BOREHOLE'!B3 -> P.O BOX 9473-00200 NAIROBI | N3: =O3-Q3 -> 10270 | O3: 10270
B4: WATER BILL | G4: BILL NO. | H4: ='FROM BOREHOLE'!H4+8-1 -> 20242008 | N4: =O4-Q4 -> 10304 | O4: 10304
N5: =O5-Q5 -> 10988 | O5: 10988
B6: NAME | C6: =meter!A10 -> NEW BLOCK | N6: =O6-Q6 -> 11070 | O6: 11070
N7: =O7-Q7 -> 1197 | O7: 1197
N8: =O8-Q8 -> 9250 | O8: 9250
N9: =O9-Q9 -> 8770 | O9: 8770
B10: ISSUE DATE | C10: ='FROM BOREHOLE'!C10 -> 29TH JAN 2025 | N10: =O10-Q10 -> 23190 | O10: 23190
N11: =O11-Q11 -> 10910 | O11: 10910
B12: LAST PAY DATE | C12: ='FROM BOREHOLE'!C12 -> 5TH FEB 2026 | N12: =O12-Q12 -> 10910 | O12: 10910
N13: =O13-Q13 -> 12190 | O13: 12190
N14: =O14-Q14 -> 11070 | O14: 11070
B15: PREVIOUS READING | C15: CURRENT READING | E15: CONSUMPTION | N15: =O15-Q15 -> 9090 | O15: 9090
B16: =meter!D10 -> 4205 | C16: =meter!E10 -> 4205 | D16: Units | E16: =C16-B16 -> 0 | N16: =O16-Q16 -> 9420 | O16: 9420
E17: Amount (Kshs.) | N17: =O17-Q17 -> 11154 | O17: 11154
C18: LAST ACCOUNT | D18: kshs. | E18: =meter!J10 -> 0 | N18: =O18-Q18 -> 10430 | O18: 10430
N19: =O19-Q19 -> 11831 | O19: 11831
C20: MONTH BILL | D20: KSHS. | E20: =meter!H10 -> 0 | N20: =O20-Q20 -> 10590 | O20: 10590
N21: =O21-Q21 -> 22423 | O21: 22423
N22: =O22-Q22 -> 9250 | O22: 9250
N23: =O23-Q23 -> 10162 | O23: 10162
N24: =O24-Q24 -> 10270 | O24: 10270
N25: =O25-Q25 -> 11070 | O25: 11070
N26: =O26-Q26 -> 11550 | O26: 11550
N27: =O27-Q27 -> 11393 | O27: 11393
N28: =O28-Q28 -> 10802 | O28: 10802
N29: =O29-Q29 -> 8930 | O29: 8930
C30: TOTAL PAYABLE | D30: Kshs. | E30: =SUM(E17:E29) -> 0 | N30: =O30-Q30 -> 9570 | O30: 9570
N31: =O31-Q31 -> 11390 | O31: 11390
C32: PAID | E32: =meter!L10 -> 0 | N32: =O32-Q32 -> 10750 | O32: 10750
N33: =O33-Q33 -> 11732 | O33: 11732
C34: AMOUNT DUE | E34: =E30-E32 -> 0 | N34: =O34-Q34 -> 10934 | O34: 10934 | R34: 700
B35: NOTE | N35: =O35-Q35 -> 10270 | O35: 10270
A36: a) | N36: =O36-Q36 -> 10598 | O36: 10598
A37: b) | N37: =O37-Q37 -> 8770 | O37: 8770
N38: =O38-Q38 -> 8770 | O38: 8770
A39: c) | O39: =SUM(O3:O38) -> 391268 | Q39: =SUM(Q3:Q38) -> 0
A41: d)
A42: e)
...

Sheet HOUSE JOHN
B2: SAMEDHA BOREHOLE | N2: VAR | O2: TAX DUE
B3: ='FROM BOREHOLE'!B3 -> P.O BOX 9473-00200 NAIROBI | N3: =O3-Q3 -> 10270 | O3: 10270
B4: WATER BILL | G4: BILL NO. | H4: ='FROM BOREHOLE'!H4+9-1 -> 20242009 | N4: =O4-Q4 -> 10304 | O4: 10304
N5: =O5-Q5 -> 10988 | O5: 10988
B6: NAME | C6: =meter!A11 -> HOUSE JOHN | N6: =O6-Q6 -> 11070 | O6: 11070
N7: =O7-Q7 -> 1197 | O7: 1197
N8: =O8-Q8 -> 9250 | O8: 9250
N9: =O9-Q9 -> 8770 | O9: 8770
B10: ISSUE DATE | C10: ='FROM BOREHOLE'!C10 -> 29TH JAN 2025 | N10: =O10-Q10 -> 23190 | O10: 23190
N11: =O11-Q11 -> 10910 | O11: 10910
B12: LAST PAY DATE | C12: ='FROM BOREHOLE'!C12 -> 5TH FEB 2026 | N12: =O12-Q12 -> 10910 | O12: 10910
N13: =O13-Q13 -> 12190 | O13: 12190
N14: =O14-Q14 -> 11070 | O14: 11070
B15: PREVIOUS READING | C15: CURRENT READING | E15: CONSUMPTION | N15: =O15-Q15 -> 9090 | O15: 9090
B16: =meter!D11 -> 56 | C16: =meter!E11 -> 56 | D16: Units | E16: =C16-B16 -> 0 | N16: =O16-Q16 -> 9420 | O16: 9420
E17: Amount (Kshs.) | N17: =O17-Q17 -> 11154 | O17: 11154
C18: LAST ACCOUNT | D18: kshs. | E18: =meter!J11 -> 0 | N18: =O18-Q18 -> 10430 | O18: 10430
N19: =O19-Q19 -> 11831 | O19: 11831
C20: MONTH BILL | D20: KSHS. | E20: =meter!H11 -> 0 | N20: =O20-Q20 -> 10590 | O20: 10590
N21: =O21-Q21 -> 22423 | O21: 22423
N22: =O22-Q22 -> 9250 | O22: 9250
N23: =O23-Q23 -> 10162 | O23: 10162
N24: =O24-Q24 -> 10270 | O24: 10270
N25: =O25-Q25 -> 11070 | O25: 11070
N26: =O26-Q26 -> 11550 | O26: 11550
N27: =O27-Q27 -> 11393 | O27: 11393
E28: =IF(E18*4%*1<0,0,E18*4%*1) -> 0 | N28: =O28-Q28 -> 10802 | O28: 10802
N29: =O29-Q29 -> 8930 | O29: 8930
C30: TOTAL PAYABLE | D30: Kshs. | E30: =SUM(E17:E29) -> 0 | N30: =O30-Q30 -> 9570 | O30: 9570
N31: =O31-Q31 -> 11390 | O31: 11390
C32: PAID | E32: =meter!L11 -> 0 | N32: =O32-Q32 -> 10750 | O32: 10750
N33: =O33-Q33 -> 11732 | O33: 11732
C34: AMOUNT DUE | E34: =E30-E32 -> 0 | N34: =O34-Q34 -> 10934 | O34: 10934 | R34: 700
B35: NOTE | N35: =O35-Q35 -> 10270 | O35: 10270
A36: a) | N36: =O36-Q36 -> 10598 | O36: 10598
A37: b) | N37: =O37-Q37 -> 8770 | O37: 8770
N38: =O38-Q38 -> 8770 | O38: 8770
A39: c) | O39: =SUM(O3:O38) -> 391268 | Q39: =SUM(Q3:Q38) -> 0
A41: d)
A42: e)
...

Sheet KAYAVA
B2: SAMEDHA BOREHOLE | N2: VAR | O2: TAX DUE
B3: ='FROM BOREHOLE'!B3 -> P.O BOX 9473-00200 NAIROBI | N3: =O3-Q3 -> 10270 | O3: 10270
B4: WATER BILL | G4: BILL NO. | H4: ='FROM BOREHOLE'!H4+10-1 -> 20242010 | N4: =O4-Q4 -> 10304 | O4: 10304
N5: =O5-Q5 -> 10988 | O5: 10988
B6: NAME | C6: =meter!A12 -> KAYAVA | N6: =O6-Q6 -> 11070 | O6: 11070
N7: =O7-Q7 -> 1197 | O7: 1197
N8: =O8-Q8 -> 9250 | O8: 9250
N9: =O9-Q9 -> 8770 | O9: 8770
B10: ISSUE DATE | C10: ='FROM BOREHOLE'!C10 -> 29TH JAN 2025 | N10: =O10-Q10 -> 23190 | O10: 23190
N11: =O11-Q11 -> 10910 | O11: 10910
B12: LAST PAY DATE | C12: ='FROM BOREHOLE'!C12 -> 5TH FEB 2026 | N12: =O12-Q12 -> 10910 | O12: 10910
N13: =O13-Q13 -> 12190 | O13: 12190
N14: =O14-Q14 -> 11070 | O14: 11070
B15: PREVIOUS READING | C15: CURRENT READING | E15: CONSUMPTION | N15: =O15-Q15 -> 9090 | O15: 9090
B16: =meter!D12 -> 1808 | C16: =meter!E12 -> 0 | D16: Units | E16: =C16-B16 -> -1808 | N16: =O16-Q16 -> 9420 | O16: 9420
E17: Amount (Kshs) | N17: =O17-Q17 -> 11154 | O17: 11154
C18: LAST ACCOUNT | D18: kshs. | E18: =meter!J12 -> 0 | N18: =O18-Q18 -> 10430 | O18: 10430
N19: =O19-Q19 -> 11831 | O19: 11831
C20: MONTH BILL | D20: KSHS. | E20: =meter!H12 -> -180800 | N20: =O20-Q20 -> 10590 | O20: 10590
N21: =O21-Q21 -> 22423 | O21: 22423
E22: ='FROM BOREHOLE'!E22 -> 0 | N22: =O22-Q22 -> 9250 | O22: 9250
N23: =O23-Q23 -> 10162 | O23: 10162
N24: =O24-Q24 -> 10270 | O24: 10270
N25: =O25-Q25 -> 11070 | O25: 11070
N26: =O26-Q26 -> 11550 | O26: 11550
N27: =O27-Q27 -> 11393 | O27: 11393
N28: =O28-Q28 -> 10802 | O28: 10802
N29: =O29-Q29 -> 8930 | O29: 8930
C30: TOTAL PAYABLE | D30: Kshs. | E30: =SUM(E17:E29) -> -180800 | N30: =O30-Q30 -> 9570 | O30: 9570
N31: =O31-Q31 -> 11390 | O31: 11390
C32: PAID | E32: =meter!L12 -> 0 | N32: =O32-Q32 -> 10750 | O32: 10750
N33: =O33-Q33 -> 11732 | O33: 11732
C34: AMOUNT DUE | E34: =E30-E32 -> -180800 | N34: =O34-Q34 -> 10934 | O34: 10934 | R34: 700
B35: NOTE | N35: =O35-Q35 -> 10270 | O35: 10270
A36: a) | B36: KINDLY PAY FOR WATER LATEST BY 5TH OF THE MONTH AND FORWARD SMS OR WHATSAPP TO 0702325121 | N36: =O36-Q36 -> 10598 | O36: 10598
A37: b) | N37: =O37-Q37 -> 8770 | O37: 8770
N38: =O38-Q38 -> 8770 | O38: 8770
A39: c) | O39: =SUM(O3:O38) -> 391268 | Q39: =SUM(Q3:Q38) -> 0
A41: d)
A42: e)
...

Sheet VINCENT
B2: SAMEDHA BOREHOLE | N2: VAR | O2: TAX DUE
B3: ='FROM BOREHOLE'!B3 -> P.O BOX 9473-00200 NAIROBI | N3: =O3-Q3 -> 10270 | O3: 10270
B4: WATER BILL | G4: BILL NO. | H4: ='FROM BOREHOLE'!H4+11-1 -> 20242011 | N4: =O4-Q4 -> 10304 | O4: 10304
N5: =O5-Q5 -> 10988 | O5: 10988
B6: NAME | C6: =meter!A13 -> Mr Vincent | N6: =O6-Q6 -> 11070 | O6: 11070
N7: =O7-Q7 -> 1197 | O7: 1197
N8: =O8-Q8 -> 9250 | O8: 9250
N9: =O9-Q9 -> 8770 | O9: 8770
B10: ISSUE DATE | C10: 29TH DEC 2025 | N10: =O10-Q10 -> 23190 | O10: 23190
N11: =O11-Q11 -> 10910 | O11: 10910
B12: LAST PAY DATE | C12: 5TH JAN 2026 | N12: =O12-Q12 -> 10910 | O12: 10910
N13: =O13-Q13 -> 12190 | O13: 12190
N14: =O14-Q14 -> 11070 | O14: 11070
B15: PREVIOUS READING | C15: CURRENT READING | E15: CONSUMPTION | N15: =O15-Q15 -> 9090 | O15: 9090
B16: =meter!D13 -> 2728 | C16: =meter!E13 -> 2773 | D16: Units | E16: =C16-B16 -> 45 | N16: =O16-Q16 -> 9420 | O16: 9420
E17: Amount (Kshs.) | N17: =O17-Q17 -> 11154 | O17: 11154
C18: LAST ACCOUNT | D18: kshs. | E18: =meter!J13 -> 0 | N18: =O18-Q18 -> 10430 | O18: 10430
N19: =O19-Q19 -> 11831 | O19: 11831
C20: MONTH BILL | D20: KSHS. | E20: =meter!H13 -> 4500 | N20: =O20-Q20 -> 10590 | O20: 10590
N21: =O21-Q21 -> 22423 | O21: 22423
N22: =O22-Q22 -> 9250 | O22: 9250
N23: =O23-Q23 -> 10162 | O23: 10162
N24: =O24-Q24 -> 10270 | O24: 10270
N25: =O25-Q25 -> 11070 | O25: 11070
N26: =O26-Q26 -> 11550 | O26: 11550
N27: =O27-Q27 -> 11393 | O27: 11393
N28: =O28-Q28 -> 10802 | O28: 10802
N29: =O29-Q29 -> 8930 | O29: 8930
C30: TOTAL PAYABLE | D30: Kshs. | E30: =SUM(E17:E29) -> 4500 | N30: =O30-Q30 -> 9570 | O30: 9570
N31: =O31-Q31 -> 11390 | O31: 11390
C32: PAID | E32: =meter!L13 -> 0 | N32: =O32-Q32 -> 10750 | O32: 10750
N33: =O33-Q33 -> 11732 | O33: 11732
C34: AMOUNT DUE | E34: =E30-E32 -> 4500 | N34: =O34-Q34 -> 10934 | O34: 10934 | R34: 700
B35: NOTE | N35: =O35-Q35 -> 10270 | O35: 10270
A36: a) | B36: KINDLY PAY FOR WATER LATEST BY 5TH OF THE MONTH AND FORWARD SMS OR WHATSAPP TO 0702325121 | N36: =O36-Q36 -> 10598 | O36: 10598
A37: b) | N37: =O37-Q37 -> 8770 | O37: 8770
N38: =O38-Q38 -> 8770 | O38: 8770
A39: c) | O39: =SUM(O3:O38) -> 391268 | Q39: =SUM(Q3:Q38) -> 0
A41: d)
A42: e)
...

Sheet WAMALWA
B2: SAMEDHA BOREHOLE | N2: VAR | O2: TAX DUE
B3: ='FROM BOREHOLE'!B3 -> P.O BOX 9473-00200 NAIROBI | N3: =O3-Q3 -> 10270 | O3: 10270
B4: WATER BILL | H4: BILL NO. | I4: ='FROM BOREHOLE'!H4+12-1 -> 20242012 | J4: ='FROM BOREHOLE'!H4+12-1 -> 20242012 | N4: =O4-Q4 -> 10304 | O4: 10304
N5: =O5-Q5 -> 10988 | O5: 10988
B6: NAME | D6: =meter!A14 -> Mr Wamalwa | N6: =O6-Q6 -> 11070 | O6: 11070
N7: =O7-Q7 -> 1197 | O7: 1197
N8: =O8-Q8 -> 9250 | O8: 9250
N9: =O9-Q9 -> 8770 | O9: 8770
B10: ISSUE DATE | D10: 29TH DEC 2025 | N10: =O10-Q10 -> 23190 | O10: 23190
N11: =O11-Q11 -> 10910 | O11: 10910
B12: LAST PAY DATE | D12: 5TH JAN 2026 | N12: =O12-Q12 -> 10910 | O12: 10910
N13: =O13-Q13 -> 12190 | O13: 12190
N14: =O14-Q14 -> 11070 | O14: 11070
B15: PREVIOUS READING | D15: CURRENT READING | F15: CONSUMPTION | N15: =O15-Q15 -> 9090 | O15: 9090
B16: =meter!D14 -> 918 | D16: =meter!E14 -> 938 | E16: Units | F16: =D16-B16 -> 20 | N16: =O16-Q16 -> 9420 | O16: 9420
F17: Amount (Kshs.) | N17: =O17-Q17 -> 11154 | O17: 11154
D18: LAST ACCOUNT | E18: kshs. | F18: =meter!J14 -> 2500 | N18: =O18-Q18 -> 10430 | O18: 10430
N19: =O19-Q19 -> 11831 | O19: 11831
D20: MONTH BILL | E20: KSHS. | F20: =meter!H14 -> 2000 | N20: =O20-Q20 -> 10590 | O20: 10590
N21: =O21-Q21 -> 22423 | O21: 22423
N22: =O22-Q22 -> 9250 | O22: 9250
N23: =O23-Q23 -> 10162 | O23: 10162
N24: =O24-Q24 -> 10270 | O24: 10270
N25: =O25-Q25 -> 11070 | O25: 11070
N26: =O26-Q26 -> 11550 | O26: 11550
N27: =O27-Q27 -> 11393 | O27: 11393
N28: =O28-Q28 -> 10802 | O28: 10802
N29: =O29-Q29 -> 8930 | O29: 8930
C30: TOTAL PAYABLE | D30: TOTAL PAYABLE | E30: Kshs. | F30: =SUM(F17:F29) -> 4500 | N30: =O30-Q30 -> 9570 | O30: 9570
N31: =O31-Q31 -> 11390 | O31: 11390
C32: PAID | D32: PAID | F32: =meter!L14 -> 0 | N32: =O32-Q32 -> 10750 | O32: 10750
N33: =O33-Q33 -> 11732 | O33: 11732
C34: BALANCE C/F | D34: AMOUNT DUE | F34: =F30-F32 -> 4500 | N34: =O34-Q34 -> 10934 | O34: 10934 | R34: 700
B35: NOTE | N35: =O35-Q35 -> 10270 | O35: 10270
A36: a) | B36: KINDLY PAY FOR WATER LATEST BY 5TH OF THE MONTH AND FORWARD SMS OR WHATSAPP TO 0702325121 | N36: =O36-Q36 -> 10598 | O36: 10598
A37: b) | N37: =O37-Q37 -> 8770 | O37: 8770
N38: =O38-Q38 -> 8770 | O38: 8770
A39: c) | O39: =SUM(O3:O38) -> 391268 | Q39: =SUM(Q3:Q38) -> 0
A41: d)
A42: e)
...

Sheet MWITA
B2: SAMEDHA BOREHOLE | N2: VAR | O2: TAX DUE
B3: ='FROM BOREHOLE'!B3 -> P.O BOX 9473-00200 NAIROBI | N3: =O3-Q3 -> 10270 | O3: 10270
B4: WATER BILL | G4: BILL NO. | H4: ='FROM BOREHOLE'!H4+13-1 -> 20242013 | N4: =O4-Q4 -> 10304 | O4: 10304
N5: =O5-Q5 -> 10988 | O5: 10988
B6: NAME | D6: =meter!A15 -> Mr Mwita | N6: =O6-Q6 -> 11070 | O6: 11070
N7: =O7-Q7 -> 1197 | O7: 1197
N8: =O8-Q8 -> 9250 | O8: 9250
N9: =O9-Q9 -> 8770 | O9: 8770
B10: ISSUE DATE | D10: ='FROM BOREHOLE'!C10 -> 29TH JAN 2025 | N10: =O10-Q10 -> 23190 | O10: 23190
N11: =O11-Q11 -> 10910 | O11: 10910
B12: LAST PAY DATE | D12: ='FROM BOREHOLE'!C12 -> 5TH FEB 2026 | N12: =O12-Q12 -> 10910 | O12: 10910
N13: =O13-Q13 -> 12190 | O13: 12190
N14: =O14-Q14 -> 11070 | O14: 11070
B15: PREVIOUS READING | D15: CURRENT READING | F15: CONSUMPTION | N15: =O15-Q15 -> 9090 | O15: 9090
B16: =meter!D15 -> 67 | D16: =meter!E15 -> 72 | E16: Units | F16: =D16-B16 -> 5 | N16: =O16-Q16 -> 9420 | O16: 9420
F17: Amount (Kshs.) | N17: =O17-Q17 -> 11154 | O17: 11154
D18: LAST ACCOUNT B/F | E18: kshs. | F18: =meter!J15 -> 0 | N18: =O18-Q18 -> 10430 | O18: 10430
N19: =O19-Q19 -> 11831 | O19: 11831
D20: MONTH BILL | E20: KSHS. | F20: =meter!H15 -> 500 | N20: =O20-Q20 -> 10590 | O20: 10590
N21: =O21-Q21 -> 22423 | O21: 22423
N22: =O22-Q22 -> 9250 | O22: 9250
N23: =O23-Q23 -> 10162 | O23: 10162
N24: =O24-Q24 -> 10270 | O24: 10270
N25: =O25-Q25 -> 11070 | O25: 11070
N26: =O26-Q26 -> 11550 | O26: 11550
N27: =O27-Q27 -> 11393 | O27: 11393
N28: =O28-Q28 -> 10802 | O28: 10802
N29: =O29-Q29 -> 8930 | O29: 8930
D30: TOTAL PAYABLE | E30: Kshs. | F30: =SUM(F17:F29) -> 500 | N30: =O30-Q30 -> 9570 | O30: 9570
N31: =O31-Q31 -> 11390 | O31: 11390
D32: PAID | F32: =meter!L15 -> 0 | N32: =O32-Q32 -> 10750 | O32: 10750
N33: =O33-Q33 -> 11732 | O33: 11732
D34: AMOUNT DUE | F34: =F30-F32 -> 500 | N34: =O34-Q34 -> 10934 | O34: 10934 | R34: 700
B35: NOTE | N35: =O35-Q35 -> 10270 | O35: 10270
A36: a) | B36: KINDLY PAY FOR WATER LATEST BY 5TH OF THE MONTH AND FORWARD SMS OR WHATSAPP TO 0702325121 | N36: =O36-Q36 -> 10598 | O36: 10598
A37: b) | N37: =O37-Q37 -> 8770 | O37: 8770
N38: =O38-Q38 -> 8770 | O38: 8770
A39: c) | O39: =SUM(O3:O38) -> 391268 | Q39: =SUM(Q3:Q38) -> 0
A41: d)
A42: e)
...

Sheet NYARANDI
B2: SAMEDHA BOREHOLE | N2: VAR | O2: TAX DUE
B3: ='FROM BOREHOLE'!B3 -> P.O BOX 9473-00200 NAIROBI | N3: =O3-Q3 -> 10270 | O3: 10270
B4: WATER BILL | H4: BILL NO. | I4: ='FROM BOREHOLE'!H4+14-1 -> 20242014 | J4: ='FROM BOREHOLE'!H4+14-1 -> 20242014 | N4: =O4-Q4 -> 10304 | O4: 10304
N5: =O5-Q5 -> 10988 | O5: 10988
B6: NAME | D6: =meter!A16 -> Andrew nyarandi | N6: =O6-Q6 -> 11070 | O6: 11070
N7: =O7-Q7 -> 1197 | O7: 1197
N8: =O8-Q8 -> 9250 | O8: 9250
N9: =O9-Q9 -> 8770 | O9: 8770
B10: ISSUE DATE | D10: ='FROM BOREHOLE'!C10 -> 29TH JAN 2025 | N10: =O10-Q10 -> 23190 | O10: 23190
N11: =O11-Q11 -> 10910 | O11: 10910
B12: LAST PAY DATE | D12: ='FROM BOREHOLE'!C12 -> 5TH FEB 2026 | N12: =O12-Q12 -> 10910 | O12: 10910
N13: =O13-Q13 -> 12190 | O13: 12190
N14: =O14-Q14 -> 11070 | O14: 11070
B15: PREVIOUS READING | D15: CURRENT READING | F15: CONSUMPTION | N15: =O15-Q15 -> 9090 | O15: 9090
B16: =meter!D16 -> 235 | D16: =meter!E16 -> 254 | E16: Units | F16: =D16-B16 -> 19 | H16: ESTIMATE | N16: =O16-Q16 -> 9420 | O16: 9420
F17: Amount (Kshs.) | N17: =O17-Q17 -> 11154 | O17: 11154
D18: LAST ACCOUNT B/F | E18: kshs. | F18: =meter!J16 -> 0 | N18: =O18-Q18 -> 10430 | O18: 10430
N19: =O19-Q19 -> 11831 | O19: 11831
D20: MONTH BILL | E20: KSHS. | F20: =meter!H16 -> 1900 | N20: =O20-Q20 -> 10590 | O20: 10590
N21: =O21-Q21 -> 22423 | O21: 22423
N22: =O22-Q22 -> 9250 | O22: 9250
N23: =O23-Q23 -> 10162 | O23: 10162
N24: =O24-Q24 -> 10270 | O24: 10270
N25: =O25-Q25 -> 11070 | O25: 11070
N26: =O26-Q26 -> 11550 | O26: 11550
N27: =O27-Q27 -> 11393 | O27: 11393
N28: =O28-Q28 -> 10802 | O28: 10802
N29: =O29-Q29 -> 8930 | O29: 8930
D30: TOTAL PAYABLE | E30: Kshs. | F30: =SUM(F17:F29) -> 1900 | N30: =O30-Q30 -> 9570 | O30: 9570
N31: =O31-Q31 -> 11390 | O31: 11390
D32: PAID | F32: =meter!L16 -> 0 | N32: =O32-Q32 -> 10750 | O32: 10750
N33: =O33-Q33 -> 11732 | O33: 11732
D34: AMOUNT DUE | F34: =F30-F32 -> 1900 | N34: =O34-Q34 -> 10934 | O34: 10934 | R34: 700
C35: NOTE | N35: =O35-Q35 -> 10270 | O35: 10270
A36: a) | B36: KINDLY PAY FOR WATER LATEST BY 5TH OF THE MONTH AND FORWARD SMS OR WHATSAPP TO 0702325121 | N36: =O36-Q36 -> 10598 | O36: 10598
A37: b) | N37: =O37-Q37 -> 8770 | O37: 8770
N38: =O38-Q38 -> 8770 | O38: 8770
A39: c) | O39: =SUM(O3:O38) -> 391268 | Q39: =SUM(Q3:Q38) -> 0
A41: d)
A42: e)
...

Sheet NAMBOKAH
B2: SAMEDHA BOREHOLE | N2: VAR | O2: TAX DUE
B3: ='FROM BOREHOLE'!B3 -> P.O BOX 9473-00200 NAIROBI | N3: =O3-Q3 -> 10270 | O3: 10270
B4: WATER BILL | H4: BILL NO. | I4: ='FROM BOREHOLE'!H4+15-1 -> 20242015 | J4: ='FROM BOREHOLE'!H4+15-1 -> 20242015 | N4: =O4-Q4 -> 10304 | O4: 10304
N5: =O5-Q5 -> 10988 | O5: 10988
B6: NAME | D6: =meter!A17 -> NAMBOKAH | N6: =O6-Q6 -> 11070 | O6: 11070
N7: =O7-Q7 -> 1197 | O7: 1197
N8: =O8-Q8 -> 9250 | O8: 9250
N9: =O9-Q9 -> 8770 | O9: 8770
B10: ISSUE DATE | D10: ='FROM BOREHOLE'!C10 -> 29TH JAN 2025 | N10: =O10-Q10 -> 23190 | O10: 23190
N11: =O11-Q11 -> 10910 | O11: 10910
B12: LAST PAY DATE | D12: ='FROM BOREHOLE'!C12 -> 5TH FEB 2026 | N12: =O12-Q12 -> 10910 | O12: 10910
N13: =O13-Q13 -> 12190 | O13: 12190
N14: =O14-Q14 -> 11070 | O14: 11070
B15: PREVIOUS READING | D15: CURRENT READING | F15: CONSUMPTION | N15: =O15-Q15 -> 9090 | O15: 9090
B16: =meter!D17 -> 152 | D16: =meter!E17 -> 0 | E16: Units | F16: =D16-B16 -> -152 | N16: =O16-Q16 -> 9420 | O16: 9420
F17: Amount (Kshs) | N17: =O17-Q17 -> 11154 | O17: 11154
D18: LAST ACCOUNT B/F | E18: kshs. | F18: =meter!J17 -> 0 | N18: =O18-Q18 -> 10430 | O18: 10430
N19: =O19-Q19 -> 11831 | O19: 11831
D20: MONTH BILL | E20: KSHS. | F20: =meter!H17 -> -15200 | N20: =O20-Q20 -> 10590 | O20: 10590
N21: =O21-Q21 -> 22423 | O21: 22423
N22: =O22-Q22 -> 9250 | O22: 9250
N23: =O23-Q23 -> 10162 | O23: 10162
N24: =O24-Q24 -> 10270 | O24: 10270
N25: =O25-Q25 -> 11070 | O25: 11070
N26: =O26-Q26 -> 11550 | O26: 11550
N27: =O27-Q27 -> 11393 | O27: 11393
N28: =O28-Q28 -> 10802 | O28: 10802
N29: =O29-Q29 -> 8930 | O29: 8930
C30: TOTAL PAYABLE | D30: AMOUNT PAYABLE | E30: Kshs. | F30: =SUM(F17:F29) -> -15200 | N30: =O30-Q30 -> 9570 | O30: 9570
N31: =O31-Q31 -> 11390 | O31: 11390
C32: PAID | E32: KSHS | F32: =meter!L17 -> 0 | N32: =O32-Q32 -> 10750 | O32: 10750
N33: =O33-Q33 -> 11732 | O33: 11732
C34: BALANCE C/F | D34: AMOUNT DUE | E34: KSHS. | F34: =F30-F32 -> -15200 | N34: =O34-Q34 -> 10934 | O34: 10934 | R34: 700
B35: NOTE | N35: =O35-Q35 -> 10270 | O35: 10270
A36: a) | B36: KINDLY PAY FOR WATER LATEST BY 5TH OF THE MONTH AND FORWARD SMS OR WHATSAPP TO 0702325121 | N36: =O36-Q36 -> 10598 | O36: 10598
A37: b) | N37: =O37-Q37 -> 8770 | O37: 8770
N38: =O38-Q38 -> 8770 | O38: 8770
A39: c) | O39: =SUM(O3:O38) -> 391268 | Q39: =SUM(Q3:Q38) -> 0
A41: d)
A42: e)
...

Sheet KIMANI
B2: SAMEDHA BOREHOLE | N2: VAR | O2: TAX DUE
B3: ='FROM BOREHOLE'!B3 -> P.O BOX 9473-00200 NAIROBI | N3: =O3-Q3 -> 10270 | O3: 10270
B4: WATER BILL | H4: BILL NO. | I4: ='FROM BOREHOLE'!H4+16-1 -> 20242016 | M4: ='FROM BOREHOLE'!H4+16-1 -> 20242016 | N4: =O4-Q4 -> 10304 | O4: 10304
N5: =O5-Q5 -> 10988 | O5: 10988
B6: NAME | D6: =meter!A18 -> KIMANI | N6: =O6-Q6 -> 11070 | O6: 11070
N7: =O7-Q7 -> 1197 | O7: 1197
N8: =O8-Q8 -> 9250 | O8: 9250
N9: =O9-Q9 -> 8770 | O9: 8770
B10: ISSUE DATE | D10: ='FROM BOREHOLE'!C10 -> 29TH JAN 2025 | N10: =O10-Q10 -> 23190 | O10: 23190
N11: =O11-Q11 -> 10910 | O11: 10910
B12: LAST PAY DATE | D12: ='FROM BOREHOLE'!C12 -> 5TH FEB 2026 | N12: =O12-Q12 -> 10910 | O12: 10910
N13: =O13-Q13 -> 12190 | O13: 12190
N14: =O14-Q14 -> 11070 | O14: 11070
B15: PREVIOUS READING | D15: CURRENT READING | F15: CONSUMPTION | N15: =O15-Q15 -> 9090 | O15: 9090
B16: =meter!D18 -> 33 | D16: =meter!E18 -> 41 | E16: Units | F16: =D16-B16 -> 8 | N16: =O16-Q16 -> 9420 | O16: 9420
F17: Amount (Kshs.) | N17: =O17-Q17 -> 11154 | O17: 11154
D18: LAST ACCOUNT B/F | E18: kshs. | F18: =meter!J18 -> 0 | N18: =O18-Q18 -> 10430 | O18: 10430
N19: =O19-Q19 -> 11831 | O19: 11831
D20: MONTH BILL | E20: KSHS. | F20: =meter!H18 -> 800 | N20: =O20-Q20 -> 10590 | O20: 10590
N21: =O21-Q21 -> 22423 | O21: 22423
N22: =O22-Q22 -> 9250 | O22: 9250
N23: =O23-Q23 -> 10162 | O23: 10162
N24: =O24-Q24 -> 10270 | O24: 10270
N25: =O25-Q25 -> 11070 | O25: 11070
N26: =O26-Q26 -> 11550 | O26: 11550
N27: =O27-Q27 -> 11393 | O27: 11393
N28: =O28-Q28 -> 10802 | O28: 10802
N29: =O29-Q29 -> 8930 | O29: 8930
D30: TOTAL PAYABLE | E30: Kshs. | F30: =SUM(F17:F29) -> 800 | N30: =O30-Q30 -> 9570 | O30: 9570
N31: =O31-Q31 -> 11390 | O31: 11390
D32: PAID | F32: =meter!L18 -> 0 | N32: =O32-Q32 -> 10750 | O32: 10750
N33: =O33-Q33 -> 11732 | O33: 11732
D34: AMOUNT DUE | F34: =F30-F32 -> 800 | N34: =O34-Q34 -> 10934 | O34: 10934 | R34: 700
C35: NOTE | N35: =O35-Q35 -> 10270 | O35: 10270
A36: a) | B36: KINDLY PAY FOR WATER LATEST BY 5TH OF THE MONTH AND FORWARD SMS OR WHATSAPP TO 0702325121 | N36: =O36-Q36 -> 10598 | O36: 10598
A37: b) | N37: =O37-Q37 -> 8770 | O37: 8770
N38: =O38-Q38 -> 8770 | O38: 8770
A39: c) | O39: =SUM(O3:O38) -> 391268 | Q39: =SUM(Q3:Q38) -> 0
A41: d)
A42: e)
...

Sheet AGNES
B2: SAMEDHA BOREHOLE | N2: VAR | O2: TAX DUE
B3: ='FROM BOREHOLE'!B3 -> P.O BOX 9473-00200 NAIROBI | N3: =O3-Q3 -> 10270 | O3: 10270
B4: WATER BILL | H4: BILL NO. | I4: ='FROM BOREHOLE'!H4+17-1 -> 20242017 | J4: ='FROM BOREHOLE'!H4+17-1 -> 20242017 | N4: =O4-Q4 -> 10304 | O4: 10304
N5: =O5-Q5 -> 10988 | O5: 10988
B6: NAME | D6: =meter!A19 -> Agnes | N6: =O6-Q6 -> 11070 | O6: 11070
N7: =O7-Q7 -> 1197 | O7: 1197
N8: =O8-Q8 -> 9250 | O8: 9250
N9: =O9-Q9 -> 8770 | O9: 8770
B10: ISSUE DATE | D10: ='FROM BOREHOLE'!C10 -> 29TH JAN 2025 | N10: =O10-Q10 -> 23190 | O10: 23190
N11: =O11-Q11 -> 10910 | O11: 10910
B12: LAST PAY DATE | D12: ='FROM BOREHOLE'!C12 -> 5TH FEB 2026 | N12: =O12-Q12 -> 10910 | O12: 10910
N13: =O13-Q13 -> 12190 | O13: 12190
N14: =O14-Q14 -> 11070 | O14: 11070
B15: PREVIOUS READING | D15: CURRENT READING | F15: CONSUMPTION | N15: =O15-Q15 -> 9090 | O15: 9090
B16: =meter!D19 -> 14 | D16: =meter!E19 -> 14 | E16: Units | F16: =D16-B16 -> 0 | N16: =O16-Q16 -> 9420 | O16: 9420
F17: Amount (Kshs.) | N17: =O17-Q17 -> 11154 | O17: 11154
D18: LAST ACCOUNT B/F | E18: kshs. | F18: =meter!J19 -> 0 | N18: =O18-Q18 -> 10430 | O18: 10430
N19: =O19-Q19 -> 11831 | O19: 11831
D20: MONTH BILL | E20: KSHS. | F20: =meter!H19 -> 0 | N20: =O20-Q20 -> 10590 | O20: 10590
N21: =O21-Q21 -> 22423 | O21: 22423
N22: =O22-Q22 -> 9250 | O22: 9250
N23: =O23-Q23 -> 10162 | O23: 10162
N24: =O24-Q24 -> 10270 | O24: 10270
N25: =O25-Q25 -> 11070 | O25: 11070
N26: =O26-Q26 -> 11550 | O26: 11550
N27: =O27-Q27 -> 11393 | O27: 11393
N28: =O28-Q28 -> 10802 | O28: 10802
N29: =O29-Q29 -> 8930 | O29: 8930
D30: TOTAL PAYABLE | E30: Kshs. | F30: =SUM(F17:F29) -> 0 | N30: =O30-Q30 -> 9570 | O30: 9570
N31: =O31-Q31 -> 11390 | O31: 11390
D32: PAID | F32: =meter!L19 -> 0 | N32: =O32-Q32 -> 10750 | O32: 10750
N33: =O33-Q33 -> 11732 | O33: 11732
D34: AMOUNT DUE | F34: =F30-F32 -> 0 | N34: =O34-Q34 -> 10934 | O34: 10934 | R34: 700
C35: NOTE | N35: =O35-Q35 -> 10270 | O35: 10270
A36: a) | B36: KINDLY PAY FOR WATER LATEST BY 5TH OF THE MONTH AND FORWARD SMS OR WHATSAPP TO 0702325121 | N36: =O36-Q36 -> 10598 | O36: 10598
A37: b) | N37: =O37-Q37 -> 8770 | O37: 8770
N38: =O38-Q38 -> 8770 | O38: 8770
A39: c) | O39: =SUM(O3:O38) -> 391268 | Q39: =SUM(Q3:Q38) -> 0
A41: d)
A42: e)
...

Sheet NANCY
B2: SAMEDHA BOREHOLE | N2: VAR | O2: TAX DUE
B3: ='FROM BOREHOLE'!B3 -> P.O BOX 9473-00200 NAIROBI | N3: =O3-Q3 -> 10270 | O3: 10270
B4: WATER BILL | H4: BILL NO. | I4: ='FROM BOREHOLE'!H4+18-1 -> 20242018 | K4: ='FROM BOREHOLE'!H4+18-1 -> 20242018 | N4: =O4-Q4 -> 10304 | O4: 10304
N5: =O5-Q5 -> 10988 | O5: 10988
B6: NAME | D6: =meter!A20 -> Nancy | N6: =O6-Q6 -> 11070 | O6: 11070
N7: =O7-Q7 -> 1197 | O7: 1197
N8: =O8-Q8 -> 9250 | O8: 9250
N9: =O9-Q9 -> 8770 | O9: 8770
B10: ISSUE DATE | D10: ='FROM BOREHOLE'!C10 -> 29TH JAN 2025 | N10: =O10-Q10 -> 23190 | O10: 23190
N11: =O11-Q11 -> 10910 | O11: 10910
B12: LAST PAY DATE | D12: ='FROM BOREHOLE'!C12 -> 5TH FEB 2026 | N12: =O12-Q12 -> 10910 | O12: 10910
N13: =O13-Q13 -> 12190 | O13: 12190
N14: =O14-Q14 -> 11070 | O14: 11070
B15: PREVIOUS READING | D15: CURRENT READING | F15: CONSUMPTION | N15: =O15-Q15 -> 9090 | O15: 9090
B16: =meter!D20 -> 289 | D16: =meter!E20 -> 0 | E16: Units | F16: =D16-B16 -> -289 | N16: =O16-Q16 -> 9420 | O16: 9420
F17: Amount (Kshs.) | N17: =O17-Q17 -> 11154 | O17: 11154
D18: LAST ACCOUNT B/F | E18: Kshs. | F18: =meter!J20 -> 0 | N18: =O18-Q18 -> 10430 | O18: 10430
N19: =O19-Q19 -> 11831 | O19: 11831
D20: MONTH BILL | E20: KSHS. | F20: =meter!H20 -> -28900 | N20: =O20-Q20 -> 10590 | O20: 10590
N21: =O21-Q21 -> 22423 | O21: 22423
N22: =O22-Q22 -> 9250 | O22: 9250
N23: =O23-Q23 -> 10162 | O23: 10162
N24: =O24-Q24 -> 10270 | O24: 10270
N25: =O25-Q25 -> 11070 | O25: 11070
N26: =O26-Q26 -> 11550 | O26: 11550
N27: =O27-Q27 -> 11393 | O27: 11393
N28: =O28-Q28 -> 10802 | O28: 10802
N29: =O29-Q29 -> 8930 | O29: 8930
D30: TOTAL PAYABLE | E30: Kshs. | F30: =SUM(F17:F29) -> -28900 | N30: =O30-Q30 -> 9570 | O30: 9570
N31: =O31-Q31 -> 11390 | O31: 11390
D32: PAID | F32: =meter!L20 -> 0 | N32: =O32-Q32 -> 10750 | O32: 10750
N33: =O33-Q33 -> 11732 | O33: 11732
D34: AMOUNT DUE | F34: =F30-F32 -> -28900 | N34: =O34-Q34 -> 10934 | O34: 10934 | R34: 700
C35: NOTE | N35: =O35-Q35 -> 10270 | O35: 10270
A36: a) | B36: KINDLY PAY FOR WATER LATEST BY 5TH OF THE MONTH AND FORWARD SMS OR WHATSAPP TO 0702325121 | N36: =O36-Q36 -> 10598 | O36: 10598
A37: b) | N37: =O37-Q37 -> 8770 | O37: 8770
N38: =O38-Q38 -> 8770 | O38: 8770
A39: c) | O39: =SUM(O3:O38) -> 391268 | Q39: =SUM(Q3:Q38) -> 0
A41: d)
A42: e)
...

Sheet KURGAT
B2: SAMEDHA BOREHOLE | N2: VAR | O2: TAX DUE
B3: ='FROM BOREHOLE'!B3 -> P.O BOX 9473-00200 NAIROBI | N3: =O3-Q3 -> 10270 | O3: 10270
B4: WATER BILL | G4: BILL NO. | H4: ='FROM BOREHOLE'!H4+19-1 -> 20242019 | I4: ='FROM BOREHOLE'!H4+19-1 -> 20242019 | N4: =O4-Q4 -> 10304 | O4: 10304
G5: ='FROM BOREHOLE'!H4+19-1 -> 20242019 | N5: =O5-Q5 -> 10988 | O5: 10988
B6: NAME | D6: =meter!A21 -> Kurgat samson | N6: =O6-Q6 -> 11070 | O6: 11070
N7: =O7-Q7 -> 1197 | O7: 1197
N8: =O8-Q8 -> 9250 | O8: 9250
N9: =O9-Q9 -> 8770 | O9: 8770
B10: ISSUE DATE | D10: ='FROM BOREHOLE'!C10 -> 29TH JAN 2025 | N10: =O10-Q10 -> 23190 | O10: 23190
N11: =O11-Q11 -> 10910 | O11: 10910
B12: LAST PAY DATE | D12: ='FROM BOREHOLE'!C12 -> 5TH FEB 2026 | N12: =O12-Q12 -> 10910 | O12: 10910
N13: =O13-Q13 -> 12190 | O13: 12190
N14: =O14-Q14 -> 11070 | O14: 11070
B15: PREVIOUS READING | D15: CURRENT READING | F15: CONSUMPTION | N15: =O15-Q15 -> 9090 | O15: 9090
B16: =meter!D21 -> 300 | D16: =meter!E21 -> 0 | E16: Units | F16: =D16-B16+I16 -> -300 | N16: =O16-Q16 -> 9420 | O16: 9420
F17: Amount (Kshs.) | N17: =O17-Q17 -> 11154 | O17: 11154
D18: LAST ACCOUNT B/F | E18: Kshs. | F18: =meter!J21 -> 0 | N18: =O18-Q18 -> 10430 | O18: 10430
N19: =O19-Q19 -> 11831 | O19: 11831
D20: MONTH BILL | E20: KSHS. | F20: =meter!H21 -> -30000 | N20: =O20-Q20 -> 10590 | O20: 10590
N21: =O21-Q21 -> 22423 | O21: 22423
N22: =O22-Q22 -> 9250 | O22: 9250
N23: =O23-Q23 -> 10162 | O23: 10162
N24: =O24-Q24 -> 10270 | O24: 10270
N25: =O25-Q25 -> 11070 | O25: 11070
N26: =O26-Q26 -> 11550 | O26: 11550
N27: =O27-Q27 -> 11393 | O27: 11393
N28: =O28-Q28 -> 10802 | O28: 10802
N29: =O29-Q29 -> 8930 | O29: 8930
D30: TOTAL PAYABLE | E30: Kshs. | F30: =SUM(F17:F29) -> -30000 | N30: =O30-Q30 -> 9570 | O30: 9570
N31: =O31-Q31 -> 11390 | O31: 11390
D32: PAID | F32: =meter!L21 -> 0 | N32: =O32-Q32 -> 10750 | O32: 10750
N33: =O33-Q33 -> 11732 | O33: 11732
D34: AMOUNT DUE | F34: =F30-F32 -> -30000 | N34: =O34-Q34 -> 10934 | O34: 10934 | R34: 700
C35: NOTE | N35: =O35-Q35 -> 10270 | O35: 10270
A36: a) | B36: KINDLY PAY FOR WATER LATEST BY 5TH OF THE MONTH AND FORWARD SMS OR WHATSAPP TO 0702325121 | N36: =O36-Q36 -> 10598 | O36: 10598
A37: b) | N37: =O37-Q37 -> 8770 | O37: 8770
N38: =O38-Q38 -> 8770 | O38: 8770
A39: c) | O39: =SUM(O3:O38) -> 391268 | Q39: =SUM(Q3:Q38) -> 0
A41: d)
A42: e)
...

Sheet JANE 
B2: SAMEDHA BOREHOLE | N2: VAR | O2: TAX DUE
B3: ='FROM BOREHOLE'!B3 -> P.O BOX 9473-00200 NAIROBI | N3: =O3-Q3 -> 10270 | O3: 10270
B4: WATER BILL | H4: BILL NO. | I4: ='FROM BOREHOLE'!H4+20-1 -> 20242020 | J4: ='FROM BOREHOLE'!H4+20-1 -> 20242020 | N4: =O4-Q4 -> 10304 | O4: 10304
N5: =O5-Q5 -> 10988 | O5: 10988
B6: NAME | D6: =meter!A22 -> Jane Mwangi | N6: =O6-Q6 -> 11070 | O6: 11070
N7: =O7-Q7 -> 1197 | O7: 1197
N8: =O8-Q8 -> 9250 | O8: 9250
N9: =O9-Q9 -> 8770 | O9: 8770
B10: ISSUE DATE | D10: ='FROM BOREHOLE'!C10 -> 29TH JAN 2025 | N10: =O10-Q10 -> 23190 | O10: 23190
N11: =O11-Q11 -> 10910 | O11: 10910
B12: LAST PAY DATE | D12: ='FROM BOREHOLE'!C12 -> 5TH FEB 2026 | N12: =O12-Q12 -> 10910 | O12: 10910
N13: =O13-Q13 -> 12190 | O13: 12190
N14: =O14-Q14 -> 11070 | O14: 11070
B15: PREVIOUS READING | D15: CURRENT READING | F15: CONSUMPTION | N15: =O15-Q15 -> 9090 | O15: 9090
B16: =meter!D22 -> 264 | D16: =meter!E22 -> 278 | E16: Units | F16: =D16-B16 -> 14 | N16: =O16-Q16 -> 9420 | O16: 9420
N17: =O17-Q17 -> 11154 | O17: 11154
D18: LAST ACCOUNT B/F | E18: Kshs. | F18: =meter!J22 -> 0 | N18: =O18-Q18 -> 10430 | O18: 10430
N19: =O19-Q19 -> 11831 | O19: 11831
D20: MONTH BILL | E20: KSHS. | F20: =meter!H22 -> 1400 | N20: =O20-Q20 -> 10590 | O20: 10590
N21: =O21-Q21 -> 22423 | O21: 22423
N22: =O22-Q22 -> 9250 | O22: 9250
N23: =O23-Q23 -> 10162 | O23: 10162
N24: =O24-Q24 -> 10270 | O24: 10270
N25: =O25-Q25 -> 11070 | O25: 11070
N26: =O26-Q26 -> 11550 | O26: 11550
N27: =O27-Q27 -> 11393 | O27: 11393
N28: =O28-Q28 -> 10802 | O28: 10802
N29: =O29-Q29 -> 8930 | O29: 8930
D30: TOTAL PAYABLE | E30: Kshs. | F30: =SUM(F17:F29) -> 1400 | N30: =O30-Q30 -> 9570 | O30: 9570
N31: =O31-Q31 -> 11390 | O31: 11390
D32: PAID | N32: =O32-Q32 -> 10750 | O32: 10750
N33: =O33-Q33 -> 11732 | O33: 11732
D34: AMOUNT DUE | F34: =F30-F32 -> 1400 | N34: =O34-Q34 -> 10934 | O34: 10934 | R34: 700
C35: NOTE | N35: =O35-Q35 -> 10270 | O35: 10270
A36: a) | B36: KINDLY PAY FOR WATER LATEST BY 5TH OF THE MONTH AND FORWARD SMS OR WHATSAPP TO 0702325121 | N36: =O36-Q36 -> 10598 | O36: 10598
A37: b) | N37: =O37-Q37 -> 8770 | O37: 8770
N38: =O38-Q38 -> 8770 | O38: 8770
A39: c) | O39: =SUM(O3:O38) -> 391268 | Q39: =SUM(Q3:Q38) -> 0
A41: d)
A42: e)
...

Sheet BRIAN
B2: SAMEDHA BOREHOLE | N2: VAR | O2: TAX DUE
B3: ='FROM BOREHOLE'!B3 -> P.O BOX 9473-00200 NAIROBI | N3: =O3-Q3 -> 10270 | O3: 10270
B4: WATER BILL | H4: BILL NO. | I4: ='FROM BOREHOLE'!H4+21-1 -> 20242021 | L4: ='FROM BOREHOLE'!H4+21-1 -> 20242021 | N4: =O4-Q4 -> 10304 | O4: 10304
N5: =O5-Q5 -> 10988 | O5: 10988
B6: NAME | D6: =meter!A23 -> Brian murithi | N6: =O6-Q6 -> 11070 | O6: 11070
N7: =O7-Q7 -> 1197 | O7: 1197
N8: =O8-Q8 -> 9250 | O8: 9250
N9: =O9-Q9 -> 8770 | O9: 8770
B10: ISSUE DATE | D10: ='FROM BOREHOLE'!C10 -> 29TH JAN 2025 | N10: =O10-Q10 -> 23190 | O10: 23190
N11: =O11-Q11 -> 10910 | O11: 10910
B12: LAST PAY DATE | D12: ='FROM BOREHOLE'!C12 -> 5TH FEB 2026 | N12: =O12-Q12 -> 10910 | O12: 10910
N13: =O13-Q13 -> 12190 | O13: 12190
N14: =O14-Q14 -> 11070 | O14: 11070
B15: PREVIOUS READING | D15: CURRENT READING | F15: CONSUMPTION | N15: =O15-Q15 -> 9090 | O15: 9090
B16: =meter!D23 -> 1164 | D16: =meter!E23 -> 1184 | E16: Units | F16: =D16-B16 -> 20 | N16: =O16-Q16 -> 9420 | O16: 9420
F17: Amount (Kshs.) | N17: =O17-Q17 -> 11154 | O17: 11154
D18: LAST ACCOUNT B/F | E18: Kshs. | F18: =meter!J23 -> 0 | N18: =O18-Q18 -> 10430 | O18: 10430
N19: =O19-Q19 -> 11831 | O19: 11831
D20: MONTH BILL | E20: KSHS. | F20: =meter!H23 -> 2000 | N20: =O20-Q20 -> 10590 | O20: 10590
N21: =O21-Q21 -> 22423 | O21: 22423
N22: =O22-Q22 -> 9250 | O22: 9250
N23: =O23-Q23 -> 10162 | O23: 10162
N24: =O24-Q24 -> 10270 | O24: 10270
N25: =O25-Q25 -> 11070 | O25: 11070
N26: =O26-Q26 -> 11550 | O26: 11550
N27: =O27-Q27 -> 11393 | O27: 11393
N28: =O28-Q28 -> 10802 | O28: 10802
N29: =O29-Q29 -> 8930 | O29: 8930
D30: TOTAL PAYABLE | E30: Kshs. | F30: =SUM(F17:F29) -> 2000 | N30: =O30-Q30 -> 9570 | O30: 9570
N31: =O31-Q31 -> 11390 | O31: 11390
D32: PAID | F32: =meter!L23 -> 0 | N32: =O32-Q32 -> 10750 | O32: 10750
N33: =O33-Q33 -> 11732 | O33: 11732
D34: AMOUNT DUE | F34: =F30-F32 -> 2000 | N34: =O34-Q34 -> 10934 | O34: 10934 | R34: 700
C35: NOTE | N35: =O35-Q35 -> 10270 | O35: 10270
A36: a) | B36: KINDLY PAY FOR WATER LATEST BY 5TH OF THE MONTH AND FORWARD SMS OR WHATSAPP TO 0702325121 | N36: =O36-Q36 -> 10598 | O36: 10598
A37: b) | N37: =O37-Q37 -> 8770 | O37: 8770
N38: =O38-Q38 -> 8770 | O38: 8770
A39: c) | O39: =SUM(O3:O38) -> 391268 | Q39: =SUM(Q3:Q38) -> 0
A41: d)
A42: e)
...

Sheet UKA
B2: SAMEDHA BOREHOLE | N2: VAR | O2: TAX DUE
B3: ='FROM BOREHOLE'!B3 -> P.O BOX 9473-00200 NAIROBI | N3: =O3-Q3 -> 10270 | O3: 10270
B4: WATER BILL | H4: BILL NO. | I4: ='FROM BOREHOLE'!H4+22-1 -> 20242022 | J4: ='FROM BOREHOLE'!H4+22-1 -> 20242022 | N4: =O4-Q4 -> 10304 | O4: 10304
N5: =O5-Q5 -> 10988 | O5: 10988
B6: NAME | D6: =meter!A24 -> Daniel uka | N6: =O6-Q6 -> 11070 | O6: 11070
N7: =O7-Q7 -> 1197 | O7: 1197
N8: =O8-Q8 -> 9250 | O8: 9250
N9: =O9-Q9 -> 8770 | O9: 8770
B10: ISSUE DATE | D10: ='FROM BOREHOLE'!C10 -> 29TH JAN 2025 | N10: =O10-Q10 -> 23190 | O10: 23190
N11: =O11-Q11 -> 10910 | O11: 10910
B12: LAST PAY DATE | D12: ='FROM BOREHOLE'!C12 -> 5TH FEB 2026 | N12: =O12-Q12 -> 10910 | O12: 10910
N13: =O13-Q13 -> 12190 | O13: 12190
N14: =O14-Q14 -> 11070 | O14: 11070
B15: PREVIOUS READING | D15: CURRENT READING | F15: CONSUMPTION | N15: =O15-Q15 -> 9090 | O15: 9090
B16: =meter!D24 -> 820 | D16: =meter!E24 -> 836 | E16: Units | F16: =D16-B16 -> 16 | N16: =O16-Q16 -> 9420 | O16: 9420
F17: Amount (Kshs.) | N17: =O17-Q17 -> 11154 | O17: 11154
D18: LAST ACCOUNT B/F | E18: Kshs. | F18: =meter!J24 -> 0 | N18: =O18-Q18 -> 10430 | O18: 10430
N19: =O19-Q19 -> 11831 | O19: 11831
D20: MONTH BILL | E20: KSHS. | F20: =meter!H24 -> 1600 | N20: =O20-Q20 -> 10590 | O20: 10590
N21: =O21-Q21 -> 22423 | O21: 22423
N22: =O22-Q22 -> 9250 | O22: 9250
N23: =O23-Q23 -> 10162 | O23: 10162
N24: =O24-Q24 -> 10270 | O24: 10270
N25: =O25-Q25 -> 11070 | O25: 11070
N26: =O26-Q26 -> 11550 | O26: 11550
N27: =O27-Q27 -> 11393 | O27: 11393
N28: =O28-Q28 -> 10802 | O28: 10802
N29: =O29-Q29 -> 8930 | O29: 8930
D30: TOTAL PAYABLE | E30: Kshs. | F30: =SUM(F17:F29) -> 1600 | N30: =O30-Q30 -> 9570 | O30: 9570
N31: =O31-Q31 -> 11390 | O31: 11390
D32: PAID | F32: =meter!L24 -> 0 | N32: =O32-Q32 -> 10750 | O32: 10750
N33: =O33-Q33 -> 11732 | O33: 11732
D34: AMOUNT DUE | F34: =F30-F32 -> 1600 | N34: =O34-Q34 -> 10934 | O34: 10934 | R34: 700
C35: NOTE | N35: =O35-Q35 -> 10270 | O35: 10270
A36: a) | B36: KINDLY PAY FOR WATER LATEST BY 5TH OF THE MONTH AND FORWARD SMS OR WHATSAPP TO 0702325121 | N36: =O36-Q36 -> 10598 | O36: 10598
A37: b) | N37: =O37-Q37 -> 8770 | O37: 8770
N38: =O38-Q38 -> 8770 | O38: 8770
A39: c) | B39: PAYBILL 4139271 ACC NO KSJ 13 | O39: =SUM(O3:O38) -> 391268 | Q39: =SUM(Q3:Q38) -> 0
A41: d)
A42: e)
...

Sheet DANSTON
B1: OLE SAMEDHA APARTMENTS-Kitengela
B2: ='FROM BOREHOLE'!B3 -> P.O BOX 9473-00200 NAIROBI | D2: SAMEDHA BOREHOLE | N2: VAR | O2: TAX DUE
B3: WATER BILL | N3: =O3-Q3 -> 10270 | O3: 10270
H4: BILL NO. | I4: ='FROM BOREHOLE'!H4+23-1 -> 20242023 | K4: ='FROM BOREHOLE'!H4+23-1 -> 20242023 | N4: =O4-Q4 -> 10304 | O4: 10304
N5: =O5-Q5 -> 10988 | O5: 10988
A6: NAME | B6: TENANT NAME | D6: =meter!A25 -> Danstone amaitsa | N6: =O6-Q6 -> 11070 | O6: 11070
N7: =O7-Q7 -> 1197 | O7: 1197
B8: HOUSE NUMBER | N8: =O8-Q8 -> 9250 | O8: 9250
N9: =O9-Q9 -> 8770 | O9: 8770
A10: ISUE DATE | B10: ISSUE DATE | D10: ='FROM BOREHOLE'!C10 -> 29TH JAN 2025 | N10: =O10-Q10 -> 23190 | O10: 23190
N11: =O11-Q11 -> 10910 | O11: 10910
A12: LAST PDY | B12: LAST PAY DATE | D12: ='FROM BOREHOLE'!C12 -> 5TH FEB 2026 | N12: =O12-Q12 -> 10910 | O12: 10910
N13: =O13-Q13 -> 12190 | O13: 12190
N14: =O14-Q14 -> 11070 | O14: 11070
B15: PREVIOUS READING | D15: CURRENT READING | F15: CONSUMPTION | N15: =O15-Q15 -> 9090 | O15: 9090
B16: =meter!D25 -> 724 | D16: =meter!E25 -> 796 | E16: Units | F16: =D16-B16 -> 72 | N16: =O16-Q16 -> 9420 | O16: 9420
F17: Amount (Kshs.) | N17: =O17-Q17 -> 11154 | O17: 11154
D18: LAST ACCOUNT B/F | E18: Kshs. | F18: =meter!J25 -> 3400 | N18: =O18-Q18 -> 10430 | O18: 10430
N19: =O19-Q19 -> 11831 | O19: 11831
D20: MONTH BILL | F20: =meter!H25 -> 7200 | N20: =O20-Q20 -> 10590 | O20: 10590
N21: =O21-Q21 -> 22423 | O21: 22423
N22: =O22-Q22 -> 9250 | O22: 9250
N23: =O23-Q23 -> 10162 | O23: 10162
N24: =O24-Q24 -> 10270 | O24: 10270
N25: =O25-Q25 -> 11070 | O25: 11070
N26: =O26-Q26 -> 11550 | O26: 11550
N27: =O27-Q27 -> 11393 | O27: 11393
N28: =O28-Q28 -> 10802 | O28: 10802
N29: =O29-Q29 -> 8930 | O29: 8930
D30: TOTAL PAYABLE | E30: Kshs. | F30: =SUM(F17:F29) -> 10600 | N30: =O30-Q30 -> 9570 | O30: 9570
N31: =O31-Q31 -> 11390 | O31: 11390
D32: PAID | F32: =meter!L25 -> 0 | N32: =O32-Q32 -> 10750 | O32: 10750
N33: =O33-Q33 -> 11732 | O33: 11732
D34: AMOUNT DUE | F34: =F30-F32 -> 10600 | N34: =O34-Q34 -> 10934 | O34: 10934 | R34: 700
C35: NOTE | N35: =O35-Q35 -> 10270 | O35: 10270
A36: a) | B36: Rent is due on or before 5th of the month. By 7th day, any rent not paid will attract interest at 2% per day. | C36: KINDLY PAY FOR WATER LATEST BY 5TH OF THE MONTH AND FORWARD SMS OR WHATSAPP TO 0702325121 | O36: 10598
A37: b) | B37: Any default in Rent payment by 10th of the following month the house shall be locked without notice and belongings removed for re-letting. | O37: 8770
O38: 8770
A39: c) | B39: Amounts not cleared by last pay date will render to water disconnection. | O39: =SUM(O3:O38) -> 391268 | Q39: =SUM(Q3:Q38) -> 0
A41: d) | B41: A reconnection fee of Kshs. 1,000 will be charged and paid before supply is reconnected.
...

Sheet ERICK
B1: SAMEDHA BOREHOLE
B2: ='FROM BOREHOLE'!B3 -> P.O BOX 9473-00200 NAIROBI | N2: VAR | O2: TAX DUE
B3: WATER BILL | N3: =O3-Q3 -> 10270 | O3: 10270
H4: BILL NO. | I4: ='FROM BOREHOLE'!H4+24-1 -> 20242024 | M4: ='FROM BOREHOLE'!H4+24-1 -> 20242024 | N4: =O4-Q4 -> 10304 | O4: 10304
N5: =O5-Q5 -> 10988 | O5: 10988
B6: NAME | D6: =meter!A26 -> Eric | N6: =O6-Q6 -> 11070 | O6: 11070
N7: =O7-Q7 -> 1197 | O7: 1197
N8: =O8-Q8 -> 9250 | O8: 9250
N9: =O9-Q9 -> 8770 | O9: 8770
B10: ISSUE DATE | D10: ='FROM BOREHOLE'!C10 -> 29TH JAN 2025 | N10: =O10-Q10 -> 23190 | O10: 23190
N11: =O11-Q11 -> 10910 | O11: 10910
B12: LAST PAY DATE | D12: ='FROM BOREHOLE'!C12 -> 5TH FEB 2026 | N12: =O12-Q12 -> 10910 | O12: 10910
N13: =O13-Q13 -> 12190 | O13: 12190
N14: =O14-Q14 -> 11070 | O14: 11070
B15: PREVIOUS READING | D15: CURRENT READING | F15: CONSUMPTION | N15: =O15-Q15 -> 9090 | O15: 9090
B16: =meter!D26 -> 155 | D16: =meter!E26 -> 159 | E16: Units | F16: =D16-B16 -> 4 | N16: =O16-Q16 -> 9420 | O16: 9420
F17: Amount (Kshs.) | N17: =O17-Q17 -> 11154 | O17: 11154
D18: LAST ACCOUNT B/F | E18: Kshs. | F18: =meter!J26 -> 0 | N18: =O18-Q18 -> 10430 | O18: 10430
N19: =O19-Q19 -> 11831 | O19: 11831
D20: MONTH BILL | E20: KSHS. | F20: =meter!H26 -> 400 | N20: =O20-Q20 -> 10590 | O20: 10590
N21: =O21-Q21 -> 22423 | O21: 22423
N22: =O22-Q22 -> 9250 | O22: 9250
N23: =O23-Q23 -> 10162 | O23: 10162
N24: =O24-Q24 -> 10270 | O24: 10270
N25: =O25-Q25 -> 11070 | O25: 11070
N26: =O26-Q26 -> 11550 | O26: 11550
N27: =O27-Q27 -> 11393 | O27: 11393
N28: =O28-Q28 -> 10802 | O28: 10802
N29: =O29-Q29 -> 8930 | O29: 8930
D30: TOTAL PAYABLE | E30: Kshs. | F30: =SUM(F17:F29) -> 400 | N30: =O30-Q30 -> 9570 | O30: 9570
N31: =O31-Q31 -> 11390 | O31: 11390
D32: PAID | F32: =meter!L26 -> 0 | N32: =O32-Q32 -> 10750 | O32: 10750
N33: =O33-Q33 -> 11732 | O33: 11732
D34: AMOUNT DUE | F34: =F30-F32 -> 400 | N34: =O34-Q34 -> 10934 | O34: 10934 | R34: 700
C35: NOTE | N35: =O35-Q35 -> 10270 | O35: 10270
A36: a) | B36: KINDLY PAY FOR WATER LATEST BY 5TH OF THE MONTH AND FORWARD SMS OR WHATSAPP TO 0702325121 | N36: =O36-Q36 -> 10598 | O36: 10598
A37: b) | N37: =O37-Q37 -> 8770 | O37: 8770
N38: =O38-Q38 -> 8770 | O38: 8770
A39: c) | O39: =SUM(O3:O38) -> 391268 | Q39: =SUM(Q3:Q38) -> 0
A41: d)
...

Sheet PAMELA
B1: SAMEDHA BOREHOLE
B2: ='FROM BOREHOLE'!B3 -> P.O BOX 9473-00200 NAIROBI | N2: VAR | O2: TAX DUE
B3: WATER BILL | N3: =O3-Q3 -> 10270 | O3: 10270
H4: BILL NO. | I4: ='FROM BOREHOLE'!H4+25-1 -> 20242025 | K4: ='FROM BOREHOLE'!H4+25-1 -> 20242025 | N4: =O4-Q4 -> 10304 | O4: 10304
N5: =O5-Q5 -> 10988 | O5: 10988
B6: NAME | D6: =meter!A27 -> Pamela | N6: =O6-Q6 -> 11070 | O6: 11070
N7: =O7-Q7 -> 1197 | O7: 1197
N8: =O8-Q8 -> 9250 | O8: 9250
N9: =O9-Q9 -> 8770 | O9: 8770
B10: ISSUE DATE | D10: ='FROM BOREHOLE'!C10 -> 29TH JAN 2025 | N10: =O10-Q10 -> 23190 | O10: 23190
N11: =O11-Q11 -> 10910 | O11: 10910
B12: LAST PAY DATE | D12: ='FROM BOREHOLE'!C12 -> 5TH FEB 2026 | N12: =O12-Q12 -> 10910 | O12: 10910
N13: =O13-Q13 -> 12190 | O13: 12190
N14: =O14-Q14 -> 11070 | O14: 11070
B15: PREVIOUS READING | D15: CURRENT READING | F15: CONSUMPTION | N15: =O15-Q15 -> 9090 | O15: 9090
B16: =meter!D27 -> 217 | C16: 643 | D16: =meter!E27 -> 223 | E16: Units | F16: =D16-B16 -> 6 | N16: =O16-Q16 -> 9420 | O16: 9420
F17: Amount (Kshs.) | N17: =O17-Q17 -> 11154 | O17: 11154
D18: LAST ACCOUNT B/F | E18: Kshs. | F18: =meter!J27 -> 0 | N18: =O18-Q18 -> 10430 | O18: 10430
N19: =O19-Q19 -> 11831 | O19: 11831
D20: MONTH BILL | E20: KSHS. | F20: =meter!H27 -> 600 | N20: =O20-Q20 -> 10590 | O20: 10590
N21: =O21-Q21 -> 22423 | O21: 22423
N22: =O22-Q22 -> 9250 | O22: 9250
N23: =O23-Q23 -> 10162 | O23: 10162
N24: =O24-Q24 -> 10270 | O24: 10270
N25: =O25-Q25 -> 11070 | O25: 11070
N26: =O26-Q26 -> 11550 | O26: 11550
N27: =O27-Q27 -> 11393 | O27: 11393
F28: =IF(F18*4%*1<0,0,F18*4%*1) -> 0 | N28: =O28-Q28 -> 10802 | O28: 10802
N29: =O29-Q29 -> 8930 | O29: 8930
D30: TOTAL PAYABLE | E30: Kshs. | F30: =SUM(F17:F29) -> 600 | N30: =O30-Q30 -> 9570 | O30: 9570
N31: =O31-Q31 -> 11390 | O31: 11390
D32: PAID | F32: =meter!L27 -> 0 | N32: =O32-Q32 -> 10750 | O32: 10750
N33: =O33-Q33 -> 11732 | O33: 11732
D34: AMOUNT DUE | F34: =F30-F32 -> 600 | N34: =O34-Q34 -> 10934 | O34: 10934 | R34: 700
C35: NOTE | N35: =O35-Q35 -> 10270 | O35: 10270
A36: a) | B36: KINDLY PAY FOR WATER LATEST BY 5TH OF THE MONTH AND FORWARD SMS OR WHATSAPP TO 0702325121 | N36: =O36-Q36 -> 10598 | O36: 10598
A37: b) | N37: =O37-Q37 -> 8770 | O37: 8770
N38: =O38-Q38 -> 8770 | O38: 8770
A39: c) | O39: =SUM(O3:O38) -> 391268 | Q39: =SUM(Q3:Q38) -> 0
A41: d)
...

Sheet BISMARK
B1: OLE SAMEDHA BOREHOLE KISAJU
B2: ='FROM BOREHOLE'!B3 -> P.O BOX 9473-00200 NAIROBI | N2: VAR | O2: TAX DUE
B3: WATER BILL | N3: =O3-Q3 -> 10270 | O3: 10270
H4: BILL NO. | I4: ='FROM BOREHOLE'!H4+30-1 -> 20242030 | J4: ='FROM BOREHOLE'!H4+30-1 -> 20242030 | N4: =O4-Q4 -> 10304 | O4: 10304
N5: =O5-Q5 -> 10988 | O5: 10988
B6: NAME | D6: BISMARK NYAKUNDI | N6: =O6-Q6 -> 11070 | O6: 11070
N7: =O7-Q7 -> 1197 | O7: 1197
N8: =O8-Q8 -> 9250 | O8: 9250
N9: =O9-Q9 -> 8770 | O9: 8770
B10: ISSUE DATE | D10: ='FROM BOREHOLE'!C10 -> 29TH JAN 2025 | N10: =O10-Q10 -> 23190 | O10: 23190
N11: =O11-Q11 -> 10910 | O11: 10910
B12: LAST PAY DATE | D12: ='FROM BOREHOLE'!C12 -> 5TH FEB 2026 | N12: =O12-Q12 -> 10910 | O12: 10910
N13: =O13-Q13 -> 12190 | O13: 12190
N14: =O14-Q14 -> 11070 | O14: 11070
B15: PREVIOUS READING | D15: CURRENT READING | F15: CONSUMPTION | N15: =O15-Q15 -> 9090 | O15: 9090
B16: =meter!D28 -> 302 | D16: =meter!E28 -> 0 | E16: Units | F16: =D16-B16 -> -302 | N16: =O16-Q16 -> 9420 | O16: 9420
F17: Amount (Kshs.) | N17: =O17-Q17 -> 11154 | O17: 11154
D18: LAST ACCOUNT B/F | E18: Kshs. | F18: =meter!J28 -> 0 | N18: =O18-Q18 -> 10430 | O18: 10430
N19: =O19-Q19 -> 11831 | O19: 11831
D20: MONTH BILL | E20: KSHS. | F20: =meter!H28 -> -30200 | N20: =O20-Q20 -> 10590 | O20: 10590
N21: =O21-Q21 -> 22423 | O21: 22423
N22: =O22-Q22 -> 9250 | O22: 9250
N23: =O23-Q23 -> 10162 | O23: 10162
N24: =O24-Q24 -> 10270 | O24: 10270
N25: =O25-Q25 -> 11070 | O25: 11070
N26: =O26-Q26 -> 11550 | O26: 11550
N27: =O27-Q27 -> 11393 | O27: 11393
N28: =O28-Q28 -> 10802 | O28: 10802
N29: =O29-Q29 -> 8930 | O29: 8930
D30: TOTAL PAYABLE | E30: Kshs. | F30: =SUM(F17:F29) -> -30200 | N30: =O30-Q30 -> 9570 | O30: 9570
N31: =O31-Q31 -> 11390 | O31: 11390
D32: PAID | F32: =meter!L32 -> 0 | N32: =O32-Q32 -> 10750 | O32: 10750
N33: =O33-Q33 -> 11732 | O33: 11732
D34: AMOUNT DUE | F34: =F30-F32 -> -30200 | N34: =O34-Q34 -> 10934 | O34: 10934 | R34: 700
C35: NOTE | N35: =O35-Q35 -> 10270 | O35: 10270
A36: a) | D36: KINDLY PAY FOR WATER LATEST BY 5TH OF THE MONTH AND FORWARD SMS OR WHATSAPP TO 0702325121 | N36: =O36-Q36 -> 10598 | O36: 10598
A37: b) | N37: =O37-Q37 -> 8770 | O37: 8770
N38: =O38-Q38 -> 8770 | O38: 8770
A39: c) | O39: =SUM(O3:O38) -> 391268 | Q39: =SUM(Q3:Q38) -> 0
A41: d)
...

Sheet PATRICK
B1: SAMEDHA BOREHOLE
B2: ='FROM BOREHOLE'!B3 -> P.O BOX 9473-00200 NAIROBI | N2: VAR | O2: TAX DUE
B3: WATER BILL | N3: =O3-Q3 -> 10270 | O3: 10270
H4: BILL NO. | I4: ='FROM BOREHOLE'!H4+31-1 -> 20242031 | J4: ='FROM BOREHOLE'!H4+31-1 -> 20242031 | N4: =O4-Q4 -> 10304 | O4: 10304
N5: =O5-Q5 -> 10988 | O5: 10988
B6: NAME | D6: =meter!A29 -> Patrick | N6: =O6-Q6 -> 11070 | O6: 11070
N7: =O7-Q7 -> 1197 | O7: 1197
N8: =O8-Q8 -> 9250 | O8: 9250
N9: =O9-Q9 -> 8770 | O9: 8770
B10: ISSUE DATE | D10: ='FROM BOREHOLE'!C10 -> 29TH JAN 2025 | N10: =O10-Q10 -> 23190 | O10: 23190
N11: =O11-Q11 -> 10910 | O11: 10910
B12: LAST PAY DATE | D12: ='FROM BOREHOLE'!C12 -> 5TH FEB 2026 | N12: =O12-Q12 -> 10910 | O12: 10910
N13: =O13-Q13 -> 12190 | O13: 12190
N14: =O14-Q14 -> 11070 | O14: 11070
B15: PREVIOUS READING | D15: CURRENT READING | F15: CONSUMPTION | N15: =O15-Q15 -> 9090 | O15: 9090
