Workbook

Sheet GFA
B2: OLE SAMEDHA EMBASSY | M2: VAR | N2: TAX DUE
B3: P.O BOX 9473-00200 NAIROBI | M3: =N3-P3 -> 10270 | N3: 10270
B4: WATER BILL | F4: BILL NO. | G4: 20242001 | M4: =N4-P4 -> 10304 | N4: 10304
M5: =N5-P5 -> 10988 | N5: 10988
B6: TENANT NAME | M6: =N6-P6 -> 11070 | N6: 11070
M7: =N7-P7 -> 1197 | N7: 1197
B8: HOUSE NUMBER | M8: =N8-P8 -> 9250 | N8: 9250
M9: =N9-P9 -> 8770 | N9: 8770
B10: ISSUE DATE | C10: 29TH JAN 026 | M10: =N10-P10 -> 23190 | N10: 23190
B11: phone number | C11: o718176579 | M11: =N11-P11 -> 10910 | N11: 10910
B12: LAST PAY DATE | C12: 5TH FEB 2026 | M12: =N12-P12 -> 10910 | N12: 10910
M13: =N13-P13 -> 12190 | N13: 12190
M14: =N14-P14 -> 11070 | N14: 11070
B15: PREVIOUS READING | D15: CONSUMPTION (Units) | M15: =N15-P15 -> 9090 | N15: 9090
B16: =meter!E3 -> 177 | C16: =meter!F3 -> 179 | D16: =C16-B16 -> 2 | M16: =N16-P16 -> 9420 | N16: 9420
D17: AMOUNT KSHS | M17: =N17-P17 -> 11154 | N17: 11154
C18: LAST COUNT | D18: =meter!O3 -> 5 | M18: =N18-P18 -> 10430 | N18: 10430
M19: =N19-P19 -> 11831 | N19: 11831
C20: month bill | D20: =meter!I3 -> 210 | M20: =N20-P20 -> 10590 | N20: 10590
M21: =N21-P21 -> 22423 | N21: 22423
C22: pump pwr charge | D22: =meter!J3 -> 70 | M22: =N22-P22 -> 9250 | N22: 9250
M23: =N23-P23 -> 10162 | N23: 10162
C24: month hse rent | D24: =meter!N3 -> 6000 | M24: =N24-P24 -> 10270 | N24: 10270
M25: =N25-P25 -> 11070 | N25: 11070
M26: =N26-P26 -> 11550 | N26: 11550
C27: gabbage fee | D27: 30 | M27: =N27-P27 -> 11393 | N27: 11393
C28: Intrest on arrears | D28: =IF(D18*2%*1<0,0,D18*2%*1) -> 0.1 | M28: =N28-P28 -> 10802 | N28: 10802
M29: =N29-P29 -> 8930 | N29: 8930
C30: Kshs. | D30: =D18+D20+D22+D24+D26+D27+D28 -> 6315.1 | M30: =N30-P30 -> 9570 | N30: 9570
M31: =N31-P31 -> 11390 | N31: 11390
D32: =meter!R3 -> 0 | M32: =N32-P32 -> 10750 | N32: 10750
M33: =N33-P33 -> 11732 | N33: 11732
D34: =D30-D32 -> 6315.1 | M34: =N34-P34 -> 10934 | N34: 10934 | Q34: 700
B35: NOTE | M35: =N35-P35 -> 10270 | N35: 10270
A36: a) | B36: Rent is due on or before 5th of the month. By 7th day, any rent not paid will attract interest at 2% per day. | M36: =N36-P36 -> 10598 | N36: 10598
B37: PAY BILL 4139271 | M37: =N37-P37 -> 8770 | N37: 8770
B38: ACC NO EMB GFA | M38: =N38-P38 -> 8770 | N38: 8770
N39: =SUM(N3:N38) -> 391268 | P39: =SUM(P3:P38) -> 0
B42: NOTE:KINDLY FORWARD SMS AFTER PAYMENT TO 0700194262 INDICATING HOUSE NO
N49: ……………

Sheet GFB
B2: OLE SAMEDHA EMBASSY | N2: VAR | O2: TAX DUE
B3: =GFA!B3 -> P.O BOX 9473-00200 NAIROBI | N3: =O3-Q3 -> 10270 | O3: 10270
B4: WATER BILL | F4: BILL NO. | G4: =GFA!G4+2-1 -> 20242002 | N4: =O4-Q4 -> 10304 | O4: 10304
N5: =O5-Q5 -> 10988 | O5: 10988
B6: TENANT NAME | D6: =meter!A4 -> VACCANT | N6: =O6-Q6 -> 11070 | O6: 11070
D7: O715656000 | N7: =O7-Q7 -> 1197 | O7: 1197
B8: HOUSE NUMBER | D8: GFB | N8: =O8-Q8 -> 9250 | O8: 9250
N9: =O9-Q9 -> 8770 | O9: 8770
B10: ISSUE DATE | D10: =GFA!C10 -> 29TH JAN 026 | N10: =O10-Q10 -> 23190 | O10: 23190
N11: =O11-Q11 -> 10910 | O11: 10910
B12: LAST PAY DATE | D12: =GFA!C12 -> 5TH FEB 2026 | N12: =O12-Q12 -> 10910 | O12: 10910
N13: =O13-Q13 -> 12190 | O13: 12190
N14: =O14-Q14 -> 11070 | O14: 11070
B15: PREVIOUS READING | D15: CURRENT READING | F15: CONSUMPTION (Units) | N15: =O15-Q15 -> 9090 | O15: 9090
B16: =meter!E4 -> 110 | D16: =meter!F4 -> 110 | E16: Units | F16: =D16-B16 -> 0 | N16: =O16-Q16 -> 9420 | O16: 9420
F17: Amount (Kshs.) | N17: =O17-Q17 -> 11154 | O17: 11154
D18: LAST ACCOUNT B/F | E18: Kshs. | F18: =meter!O4 -> 0 | N18: =O18-Q18 -> 10430 | O18: 10430
N19: =O19-Q19 -> 11831 | O19: 11831
D20: MONTH BILL | E20: Kshs. | F20: =meter!I4 -> 0 | N20: =O20-Q20 -> 10590 | O20: 10590
N21: =O21-Q21 -> 22423 | O21: 22423
D22: PUMP/POWER CHARGES | E22: Kshs. | F22: =GFA!D22 -> 70 | N22: =O22-Q22 -> 9250 | O22: 9250
N23: =O23-Q23 -> 10162 | O23: 10162
D24: MONTH HOUSE RENT | E24: Kshs. | F24: =meter!N4 -> 5000 | N24: =O24-Q24 -> 10270 | O24: 10270
N25: =O25-Q25 -> 11070 | O25: 11070
E26: Kshs. | F26: =GFA!D26 -> 0 | N26: =O26-Q26 -> 11550 | O26: 11550
D27: GARBAGE FEE | F27: 30 | N27: =O27-Q27 -> 11393 | O27: 11393
D28: INTEREST ON ARREARS | E28: Kshs. | F28: =IF(F18*2%*1<0,0,F18*2%*1) -> 0 | N28: =O28-Q28 -> 10802 | O28: 10802
F29: 0 | N29: =O29-Q29 -> 8930 | O29: 8930
D30: TOTAL PAYABLE | E30: Kshs. | F30: =SUM(F17:F29) -> 5100 | N30: =O30-Q30 -> 9570 | O30: 9570
N31: =O31-Q31 -> 11390 | O31: 11390
D32: PAID | F32: =meter!R4 -> 0 | N32: =O32-Q32 -> 10750 | O32: 10750
N33: =O33-Q33 -> 11732 | O33: 11732
D34: AMOUNT DUE | F34: =F30-F32 -> 5100 | N34: =O34-Q34 -> 10934 | O34: 10934 | R34: 700
C35: NOTE | N35: =O35-Q35 -> 10270 | O35: 10270
B36: a) | C36: Rent is due on or before 5th of the month. By 7th day, any rent not paid will attract interest at 2% per day. | N36: =O36-Q36 -> 10598 | O36: 10598
N37: =O37-Q37 -> 8770 | O37: 8770
N38: =O38-Q38 -> 8770 | O38: 8770
O39: =SUM(O3:O38) -> 391268 | Q39: =SUM(Q3:Q38) -> 0
B41: NOTE:KINDLY FORWARD SMS AFTER PAYMENT TO 0700194262 INDICATING HOUSE NO
D42: PAY BILL 4139271
...

Sheet 1A
B2: OLE SAMEDHA EMBASSY | N2: VAR | O2: TAX DUE
B3: =GFA!B3 -> P.O BOX 9473-00200 NAIROBI | N3: =O3-Q3 -> 10270 | O3: 10270
B4: WATER BILL | G4: BILL NO. | H4: =GFA!G4+3-1 -> 20242003 | N4: =O4-Q4 -> 10304 | O4: 10304
N5: =O5-Q5 -> 10988 | O5: 10988
B6: TENANT NAME | C6: =meter!A5 -> CHARLES MOMANYI | N6: =O6-Q6 -> 11070 | O6: 11070
C7: O726263214 | N7: =O7-Q7 -> 1197 | O7: 1197
B8: HOUSE NUMBER: | C8: 1A | N8: =O8-Q8 -> 9250 | O8: 9250
N9: =O9-Q9 -> 8770 | O9: 8770
B10: ISSUE DATE | C10: =GFA!C10 -> 29TH JAN 026 | N10: =O10-Q10 -> 23190 | O10: 23190
N11: =O11-Q11 -> 10910 | O11: 10910
B12: LAST PAY DATE | C12: =GFA!C12 -> 5TH FEB 2026 | N12: =O12-Q12 -> 10910 | O12: 10910
N13: =O13-Q13 -> 12190 | O13: 12190
N14: =O14-Q14 -> 11070 | O14: 11070
B15: PREVIOUS READING | C15: CURRENT READING | E15: CONSUMPTION (Units) | N15: =O15-Q15 -> 9090 | O15: 9090
B16: =meter!E5 -> 144 | C16: =meter!F5 -> 147 | D16: Units | E16: =C16-B16 -> 3 | N16: =O16-Q16 -> 9420 | O16: 9420
E17: Amount (Kshs.) | N17: =O17-Q17 -> 11154 | O17: 11154
C18: LAST ACCOUNT B/F | D18: Kshs. | E18: =meter!O5 -> 2925 | N18: =O18-Q18 -> 10430 | O18: 10430
N19: =O19-Q19 -> 11831 | O19: 11831
C20: MONTH BILL | D20: Kshs. | E20: =meter!I5 -> 315 | N20: =O20-Q20 -> 10590 | O20: 10590
N21: =O21-Q21 -> 22423 | O21: 22423
C22: PUMP/POWER CHARGES | D22: Kshs. | E22: =meter!J5 -> 70 | N22: =O22-Q22 -> 9250 | O22: 9250
N23: =O23-Q23 -> 10162 | O23: 10162
C24: MONTH HOUSE RENT | D24: Kshs. | E24: =meter!N5 -> 6000 | N24: =O24-Q24 -> 10270 | O24: 10270
N25: =O25-Q25 -> 11070 | O25: 11070
D26: Kshs. | N26: =O26-Q26 -> 11550 | O26: 11550
C27: GARBAGE FEE | D27: Kshs. | E27: 30 | N27: =O27-Q27 -> 11393 | O27: 11393
C28: ADJUSTMENT | D28: Kshs. | E28: =IF(E18*2%*1<0,0,E18*2%*1) -> 58.5 | N28: =O28-Q28 -> 10802 | O28: 10802
N29: =O29-Q29 -> 8930 | O29: 8930
C30: TOTAL PAYABLE | D30: Kshs. | E30: =SUM(E17:E29) -> 9398.5 | N30: =O30-Q30 -> 9570 | O30: 9570
N31: =O31-Q31 -> 11390 | O31: 11390
C32: PAID | E32: =meter!R5 -> 0 | N32: =O32-Q32 -> 10750 | O32: 10750
N33: =O33-Q33 -> 11732 | O33: 11732
C34: AMOUNT DUE | E34: =E30-E32 -> 9398.5 | N34: =O34-Q34 -> 10934 | O34: 10934 | R34: 700
B35: NOTE | N35: =O35-Q35 -> 10270 | O35: 10270
A36: a) | B36: Rent is due on or before 5th of the month. By 7th day, any rent not paid will attract interest at 2% per day. | N36: =O36-Q36 -> 10598 | O36: 10598
A37: b) | N37: =O37-Q37 -> 8770 | O37: 8770
B38: PAY BILL 4139271 | N38: =O38-Q38 -> 8770 | O38: 8770
A39: c) | B39: ACC NO EMB 1A | O39: =SUM(O3:O38) -> 391268 | Q39: =SUM(Q3:Q38) -> 0
A41: d)
A42: e) | B42: NOTE:KINDLY FORWARD SMS AFTER PAYMENT TO 0700194262 INDICATING HOUSE NO
...

Sheet 2A
B2: OLE SAMEDHA EMBASSY | N2: VAR | O2: TAX DUE
B3: =GFA!B3 -> P.O BOX 9473-00200 NAIROBI | N3: =O3-Q3 -> 10270 | O3: 10270
B4: WATER BILL | G4: BILL NO. | H4: =GFA!G4+4-1 -> 20242004 | N4: =O4-Q4 -> 10304 | O4: 10304
N5: =O5-Q5 -> 10988 | O5: 10988
B6: TENANT NAME | C6: =meter!A6 -> GLADYS | N6: =O6-Q6 -> 11070 | O6: 11070
C7: O722953105 | N7: =O7-Q7 -> 1197 | O7: 1197
B8: HOUSE NUMBER: | C8: 2A | N8: =O8-Q8 -> 9250 | O8: 9250
N9: =O9-Q9 -> 8770 | O9: 8770
B10: ISSUE DATE | C10: =GFA!C10 -> 29TH JAN 026 | N10: =O10-Q10 -> 23190 | O10: 23190
N11: =O11-Q11 -> 10910 | O11: 10910
B12: LAST PAY DATE | C12: =GFA!C12 -> 5TH FEB 2026 | N12: =O12-Q12 -> 10910 | O12: 10910
N13: =O13-Q13 -> 12190 | O13: 12190
N14: =O14-Q14 -> 11070 | O14: 11070
B15: PREVIOUS READING | C15: CURRENT READING | E15: CONSUMPTION | N15: =O15-Q15 -> 9090 | O15: 9090
B16: =meter!E6 -> 213 | C16: =meter!F6 -> 213 | D16: Units | E16: =C16-B16 -> 0 | N16: =O16-Q16 -> 9420 | O16: 9420
E17: Amount (Kshs) | N17: =O17-Q17 -> 11154 | O17: 11154
C18: LAST ACCOUNT B/F | D18: Kshs. | E18: =meter!O6 -> 6310 | N18: =O18-Q18 -> 10430 | O18: 10430
N19: =O19-Q19 -> 11831 | O19: 11831
C20: MONTH BILL | D20: Kshs. | E20: =meter!I6 -> 0 | N20: =O20-Q20 -> 10590 | O20: 10590
N21: =O21-Q21 -> 22423 | O21: 22423
C22: PUMP/POWER CHARGES | D22: Kshs. | E22: =meter!J6 -> 70 | N22: =O22-Q22 -> 9250 | O22: 9250
N23: =O23-Q23 -> 10162 | O23: 10162
C24: MONTH HOUSE RENT | D24: Kshs. | E24: =meter!N6 -> 6000 | N24: =O24-Q24 -> 10270 | O24: 10270
N25: =O25-Q25 -> 11070 | O25: 11070
D26: Kshs. | N26: =O26-Q26 -> 11550 | O26: 11550
C27: GARBAGE FEE | D27: Kshs. | E27: 30 | N27: =O27-Q27 -> 11393 | O27: 11393
C28: INTEREST ON ARREARS | D28: Kshs. | E28: =IF(E18*2%*1<0,0,E18*2%*1) -> 126.2 | N28: =O28-Q28 -> 10802 | O28: 10802
N29: =O29-Q29 -> 8930 | O29: 8930
C30: TOTAL PAYABLE | D30: Kshs. | E30: =SUM(E17:E29) -> 12536.2 | N30: =O30-Q30 -> 9570 | O30: 9570
N31: =O31-Q31 -> 11390 | O31: 11390
C32: PAID | E32: =meter!R6 -> 0 | N32: =O32-Q32 -> 10750 | O32: 10750
N33: =O33-Q33 -> 11732 | O33: 11732
C34: AMOUNT DUE | E34: =E30-E32 -> 12536.2 | N34: =O34-Q34 -> 10934 | O34: 10934 | R34: 700
B35: NOTE | N35: =O35-Q35 -> 10270 | O35: 10270
A36: a) | B36: Rent is due on or before 5th of the month. By 7th day, any rent not paid will attract interest at 2% per day. | N36: =O36-Q36 -> 10598 | O36: 10598
N37: =O37-Q37 -> 8770 | O37: 8770
B38: PAY BILL 4139271 | N38: =O38-Q38 -> 8770 | O38: 8770
B39: ACC NO EMB 2A | O39: =SUM(O3:O38) -> 391268 | Q39: =SUM(Q3:Q38) -> 0
B43: NOTE:KINDLY FORWARD SMS AFTER PAYMENT TO 0700194262 INDICATING HOUSE NO
O49: ……………

Sheet 3A
B2: OLE SAMEDHA EMBASSY | N2: VAR | O2: TAX DUE
B3: =GFA!B3 -> P.O BOX 9473-00200 NAIROBI | N3: =O3-Q3 -> 10270 | O3: 10270
B4: WATER BILL | G4: BILL NO. | H4: =GFA!G4+5-1 -> 20242005 | N4: =O4-Q4 -> 10304 | O4: 10304
N5: =O5-Q5 -> 10988 | O5: 10988
B6: TENANT NAME | C6: =meter!A7 -> VINCENT | N6: =O6-Q6 -> 11070 | O6: 11070
C7: O793790309 | N7: =O7-Q7 -> 1197 | O7: 1197
B8: HOUSE NUMBER; | C8: 3A | N8: =O8-Q8 -> 9250 | O8: 9250
N9: =O9-Q9 -> 8770 | O9: 8770
B10: ISSUE DATE | C10: =GFA!C10 -> 29TH JAN 026 | N10: =O10-Q10 -> 23190 | O10: 23190
N11: =O11-Q11 -> 10910 | O11: 10910
B12: LAST PAY DATE | C12: =GFA!C12 -> 5TH FEB 2026 | N12: =O12-Q12 -> 10910 | O12: 10910
N13: =O13-Q13 -> 12190 | O13: 12190
N14: =O14-Q14 -> 11070 | O14: 11070
B15: PREVIOUS READING | C15: CURRENT READING | E15: CONSUMPTION (Units) | N15: =O15-Q15 -> 9090 | O15: 9090
B16: =meter!E7 -> 159 | C16: =meter!F7 -> 160 | D16: Units | E16: =C16-B16 -> 1 | N16: =O16-Q16 -> 9420 | O16: 9420
E17: Amount(Kshs) | N17: =O17-Q17 -> 11154 | O17: 11154
C18: LAST ACCOUNT B/F | D18: Kshs. | E18: =meter!O7 -> 20665 | N18: =O18-Q18 -> 10430 | O18: 10430
N19: =O19-Q19 -> 11831 | O19: 11831
C20: MONTH BILL | D20: Kshs. | E20: =meter!I7 -> 105 | N20: =O20-Q20 -> 10590 | O20: 10590
N21: =O21-Q21 -> 22423 | O21: 22423
C22: PUMP/POWER CHARGES | D22: Kshs. | E22: =GFA!D22 -> 70 | N22: =O22-Q22 -> 9250 | O22: 9250
N23: =O23-Q23 -> 10162 | O23: 10162
C24: MONTH HOUSE RENT | D24: Kshs. | E24: =meter!N7 -> 6000 | N24: =O24-Q24 -> 10270 | O24: 10270
N25: =O25-Q25 -> 11070 | O25: 11070
D26: =GFA!C26 -> 0 | E26: =meter!M7 -> 0 | N26: =O26-Q26 -> 11550 | O26: 11550
C27: GARBAGE FEE | D27: Kshs. | E27: 30 | N27: =O27-Q27 -> 11393 | O27: 11393
C28: INTEREST ON ARREARS | D28: Kshs. | E28: =IF(E18*2%*1<0,0,E18*2%*1) -> 413.3 | N28: =O28-Q28 -> 10802 | O28: 10802
N29: =O29-Q29 -> 8930 | O29: 8930
C30: TOTAL PAYABLE | D30: Kshs. | E30: =SUM(E17:E29) -> 27283.3 | N30: =O30-Q30 -> 9570 | O30: 9570
N31: =O31-Q31 -> 11390 | O31: 11390
C32: PAID | E32: =meter!R7 -> 0 | N32: =O32-Q32 -> 10750 | O32: 10750
N33: =O33-Q33 -> 11732 | O33: 11732
C34: AMOUNT DUE | E34: =E30-E32 -> 27283.3 | N34: =O34-Q34 -> 10934 | O34: 10934 | R34: 700
B35: NOTE | N35: =O35-Q35 -> 10270 | O35: 10270
A36: a) | B36: Rent is due on or before 5th of the month. By 7th day, any rent not paid will attract interest at 2% per day. | N36: =O36-Q36 -> 10598 | O36: 10598
B37: PAY BILL 4139271 | N37: =O37-Q37 -> 8770 | O37: 8770
B38: ACC NO EMB 3A | N38: =O38-Q38 -> 8770 | O38: 8770
O39: =SUM(O3:O38) -> 391268 | Q39: =SUM(Q3:Q38) -> 0
B42: NOTE:KINDLY FORWARD SMS AFTER PAYMENT TO 0700194262 INDICATING HOUSE NO
O49: ……………

Sheet 1B
B2: OLE SAMEDHA EMBASSY | N2: VAR | O2: TAX DUE
B3: =GFA!B3 -> P.O BOX 9473-00200 NAIROBI | N3: =O3-Q3 -> 10270 | O3: 10270
B4: WATER BILL | F4: BILL NO. | G4: BILL NO. | H4: =GFA!G4+6-1 -> 20242006 | N4: =O4-Q4 -> 10304 | O4: 10304
N5: =O5-Q5 -> 10988 | O5: 10988
B6: TENANT NAME | C6: =meter!A8 -> VERONICAH | N6: =O6-Q6 -> 11070 | O6: 11070
C7: O702681920 | N7: =O7-Q7 -> 1197 | O7: 1197
B8: HOUSE NUMBER: | C8: 1B | N8: =O8-Q8 -> 9250 | O8: 9250
N9: =O9-Q9 -> 8770 | O9: 8770
B10: ISSUE DATE | C10: =GFA!C10 -> 29TH JAN 026 | N10: =O10-Q10 -> 23190 | O10: 23190
N11: =O11-Q11 -> 10910 | O11: 10910
B12: LAST PAY DATE | C12: =GFA!C12 -> 5TH FEB 2026 | N12: =O12-Q12 -> 10910 | O12: 10910
N13: =O13-Q13 -> 12190 | O13: 12190
N14: =O14-Q14 -> 11070 | O14: 11070
B15: PREVIOUS READING | C15: CURRENT READING | E15: CONSUMPTION | N15: =O15-Q15 -> 9090 | O15: 9090
B16: =meter!E8 -> 195 | C16: =meter!F8 -> 196 | D16: Units | E16: =C16-B16 -> 1 | N16: =O16-Q16 -> 9420 | O16: 9420
E17: Amount(Kshs) | N17: =O17-Q17 -> 11154 | O17: 11154
C18: LAST ACCOUNT | D18: kshs. | E18: =meter!O8 -> 110 | N18: =O18-Q18 -> 10430 | O18: 10430
N19: =O19-Q19 -> 11831 | O19: 11831
C20: MONTH BILL | D20: KSHS. | E20: =meter!I8 -> 105 | N20: =O20-Q20 -> 10590 | O20: 10590
N21: =O21-Q21 -> 22423 | O21: 22423
C22: PUMP/POWER CHARGES | D22: KSHS. | E22: =GFA!D22 -> 70 | N22: =O22-Q22 -> 9250 | O22: 9250
N23: =O23-Q23 -> 10162 | O23: 10162
C24: MONTH HOUSE RENT | D24: KSHS. | E24: =meter!N8 -> 6000 | N24: =O24-Q24 -> 10270 | O24: 10270
N25: =O25-Q25 -> 11070 | O25: 11070
D26: =GFA!C26 -> 0 | E26: =meter!M8 -> 0 | N26: =O26-Q26 -> 11550 | O26: 11550
C27: GARBAGE FEE | E27: 30 | N27: =O27-Q27 -> 11393 | O27: 11393
C28: ADJUSTMENT (Interest late payment) | D28: KSHS. | E28: =IF(E18*2%*1<0,0,E18*2%*1) -> 2.2 | N28: =O28-Q28 -> 10802 | O28: 10802
N29: =O29-Q29 -> 8930 | O29: 8930
C30: TOTAL PAYABLE | D30: Kshs. | E30: =SUM(E17:E29) -> 6317.2 | N30: =O30-Q30 -> 9570 | O30: 9570
N31: =O31-Q31 -> 11390 | O31: 11390
C32: PAID | E32: =meter!R8 -> 0 | N32: =O32-Q32 -> 10750 | O32: 10750
N33: =O33-Q33 -> 11732 | O33: 11732
C34: AMOUNT DUE | E34: =E30-E32 -> 6317.2 | N34: =O34-Q34 -> 10934 | O34: 10934 | R34: 700
B35: NOTE | C35: PAY & VACATE, REPAIRS CHARGES OF 8,400/- REMAINS TILL NEW TENANT LEAVES, THEN WE REPAIR | N35: =O35-Q35 -> 10270 | O35: 10270
A36: a) | B36: Rent is due on or before 5th of the month. By 7th day, any rent not paid will attract interest at 2% per day. | N36: =O36-Q36 -> 10598 | O36: 10598
B37: PAY BILL 4139271 | N37: =O37-Q37 -> 8770 | O37: 8770
B38: ACC NO EMB 1B | N38: =O38-Q38 -> 8770 | O38: 8770
O39: =SUM(O3:O38) -> 391268 | Q39: =SUM(Q3:Q38) -> 0
B42: NOTE:KINDLY FORWARD SMS AFTER PAYMENT TO 0700194262 INDICATING HOUSE NO
O49: ……………

Sheet 2B
B2: OLE SAMEDHA EMBASSY | N2: VAR | O2: TAX DUE
B3: =GFA!B3 -> P.O BOX 9473-00200 NAIROBI | N3: =O3-Q3 -> 10270 | O3: 10270
B4: WATER BILL | G4: BILL NO. | H4: =GFA!G4+7-1 -> 20242007 | N4: =O4-Q4 -> 10304 | O4: 10304
N5: =O5-Q5 -> 10988 | O5: 10988
B6: TENANT NAME | C6: =meter!A9 -> DUKE | N6: =O6-Q6 -> 11070 | O6: 11070
C7: O799745396 | N7: =O7-Q7 -> 1197 | O7: 1197
B8: HOUSE NUMBER: | C8: 2B | N8: =O8-Q8 -> 9250 | O8: 9250
N9: =O9-Q9 -> 8770 | O9: 8770
B10: ISSUE DATE | C10: =GFA!C10 -> 29TH JAN 026 | N10: =O10-Q10 -> 23190 | O10: 23190
N11: =O11-Q11 -> 10910 | O11: 10910
B12: LAST PAY DATE | C12: =GFA!C12 -> 5TH FEB 2026 | N12: =O12-Q12 -> 10910 | O12: 10910
N13: =O13-Q13 -> 12190 | O13: 12190
N14: =O14-Q14 -> 11070 | O14: 11070
B15: PREVIOUS READING | C15: CURRENT READING | E15: CONSUMPTION | N15: =O15-Q15 -> 9090 | O15: 9090
B16: =meter!E9 -> 129 | C16: =meter!F9 -> 129 | D16: Units | E16: =C16-B16 -> 0 | N16: =O16-Q16 -> 9420 | O16: 9420
E17: Amount (Kshs) | N17: =O17-Q17 -> 11154 | O17: 11154
C18: LAST ACCOUNT | D18: kshs. | E18: =meter!O9 -> 6600 | N18: =O18-Q18 -> 10430 | O18: 10430
N19: =O19-Q19 -> 11831 | O19: 11831
C20: MONTH BILL | D20: KSHS. | E20: =meter!I9 -> 0 | N20: =O20-Q20 -> 10590 | O20: 10590
N21: =O21-Q21 -> 22423 | O21: 22423
C22: PUMP/POWER CHARGES | D22: KSHS. | E22: =GFA!D22 -> 70 | N22: =O22-Q22 -> 9250 | O22: 9250
N23: =O23-Q23 -> 10162 | O23: 10162
C24: MONTH HOUSE RENT | D24: KSHS. | E24: =meter!N9 -> 6000 | N24: =O24-Q24 -> 10270 | O24: 10270
N25: =O25-Q25 -> 11070 | O25: 11070
D26: =GFA!C26 -> 0 | E26: =GFA!D26 -> 0 | N26: =O26-Q26 -> 11550 | O26: 11550
C27: GARBAGE FEE | E27: 30 | N27: =O27-Q27 -> 11393 | O27: 11393
C28: ADJUSTMENT-interest on arrears | D28: KSHS. | E28: =IF(E18*2%*1<0,0,E18*2%*1) -> 132 | N28: =O28-Q28 -> 10802 | O28: 10802
N29: =O29-Q29 -> 8930 | O29: 8930
C30: TOTAL PAYABLE | D30: Kshs. | E30: =SUM(E17:E29) -> 12832 | N30: =O30-Q30 -> 9570 | O30: 9570
N31: =O31-Q31 -> 11390 | O31: 11390
C32: PAID | E32: =meter!R10 -> 0 | N32: =O32-Q32 -> 10750 | O32: 10750
N33: =O33-Q33 -> 11732 | O33: 11732
C34: AMOUNT DUE | E34: =E30-E32 -> 12832 | N34: =O34-Q34 -> 10934 | O34: 10934 | R34: 700
B35: NOTE | N35: =O35-Q35 -> 10270 | O35: 10270
A36: a) | B36: Rent is due on or before 5th of the month. By 7th day, any rent not paid will attract interest at 2% per day. | N36: =O36-Q36 -> 10598 | O36: 10598
B37: PAY BILL 4139271 | N37: =O37-Q37 -> 8770 | O37: 8770
B38: ACC NO EMB 2B | N38: =O38-Q38 -> 8770 | O38: 8770
O39: =SUM(O3:O38) -> 391268 | Q39: =SUM(Q3:Q38) -> 0
O49: ……………
B53: NOTE:KINDLY FORWARD SMS AFTER PAYMENT TO 0700194262 INDICATING HOUSE NO

Sheet 3B
B2: OLE SAMEDHA EMBASSY | N2: VAR | O2: TAX DUE
B3: =GFA!B3 -> P.O BOX 9473-00200 NAIROBI | N3: =O3-Q3 -> 10270 | O3: 10270
B4: WATER BILL | G4: BILL NO. | H4: =GFA!G4+8-1 -> 20242008 | N4: =O4-Q4 -> 10304 | O4: 10304
N5: =O5-Q5 -> 10988 | O5: 10988
B6: TENANT NAME | C6: =meter!A10 -> NECODEMUS | N6: =O6-Q6 -> 11070 | O6: 11070
C7: O725253220 | N7: =O7-Q7 -> 1197 | O7: 1197
B8: HOUSE NUMBER: | C8: 3B | N8: =O8-Q8 -> 9250 | O8: 9250
N9: =O9-Q9 -> 8770 | O9: 8770
B10: ISSUE DATE | C10: =GFA!C10 -> 29TH JAN 026 | N10: =O10-Q10 -> 23190 | O10: 23190
N11: =O11-Q11 -> 10910 | O11: 10910
B12: LAST PAY DATE | C12: =GFA!C12 -> 5TH FEB 2026 | N12: =O12-Q12 -> 10910 | O12: 10910
N13: =O13-Q13 -> 12190 | O13: 12190
N14: =O14-Q14 -> 11070 | O14: 11070
B15: PREVIOUS READING | C15: CURRENT READING | E15: CONSUMPTION | N15: =O15-Q15 -> 9090 | O15: 9090
B16: =meter!E10 -> 88 | C16: =meter!F10 -> 88 | D16: Units | E16: =C16-B16 -> 0 | N16: =O16-Q16 -> 9420 | O16: 9420
E17: Amount (Kshs.) | N17: =O17-Q17 -> 11154 | O17: 11154
C18: LAST ACCOUNT | D18: kshs. | E18: =meter!O10 -> 6389 | N18: =O18-Q18 -> 10430 | O18: 10430
N19: =O19-Q19 -> 11831 | O19: 11831
C20: MONTH BILL | D20: KSHS. | E20: =meter!I10 -> 0 | N20: =O20-Q20 -> 10590 | O20: 10590
N21: =O21-Q21 -> 22423 | O21: 22423
C22: PUMP/POWER CHARGES | D22: KSHS. | E22: =GFA!D22 -> 70 | N22: =O22-Q22 -> 9250 | O22: 9250
N23: =O23-Q23 -> 10162 | O23: 10162
C24: MONTH HOUSE RENT | D24: KSHS. | E24: =meter!N10 -> 6000 | N24: =O24-Q24 -> 10270 | O24: 10270
N25: =O25-Q25 -> 11070 | O25: 11070
D26: =GFA!C26 -> 0 | E26: =GFA!D26 -> 0 | N26: =O26-Q26 -> 11550 | O26: 11550
C27: GARBAGE FEE | D27: Kshs. | E27: 30 | N27: =O27-Q27 -> 11393 | O27: 11393
C28: ADJUSTMENT-interest on arrears | D28: KSHS. | E28: =IF(E18*2%*1<0,0,E18*2%*1) -> 127.78 | N28: =O28-Q28 -> 10802 | O28: 10802
N29: =O29-Q29 -> 8930 | O29: 8930
C30: TOTAL PAYABLE | D30: Kshs. | E30: =SUM(E17:E29) -> 12616.78 | N30: =O30-Q30 -> 9570 | O30: 9570
N31: =O31-Q31 -> 11390 | O31: 11390
C32: PAID | E32: =meter!R10 -> 0 | N32: =O32-Q32 -> 10750 | O32: 10750
N33: =O33-Q33 -> 11732 | O33: 11732
C34: AMOUNT DUE | E34: =E30-E32 -> 12616.78 | N34: =O34-Q34 -> 10934 | O34: 10934 | R34: 700
B35: NOTE | N35: =O35-Q35 -> 10270 | O35: 10270
A36: a) | B36: Rent is due on or before 5th of the month. By 7th day, any rent not paid will attract interest at 2% per day. | N36: =O36-Q36 -> 10598 | O36: 10598
B37: PAY BILL 4139271 | N37: =O37-Q37 -> 8770 | O37: 8770
B38: ACC NO EMB 3B | N38: =O38-Q38 -> 8770 | O38: 8770
O39: =SUM(O3:O38) -> 391268 | Q39: =SUM(Q3:Q38) -> 0
B41: NOTE:KINDLY FORWARD SMS AFTER PAYMENT TO 0700194262 INDICATING HOUSE NO
O49: ……………

Sheet 1C
B2: OLE SAMEDHA EMBASSY | N2: VAR | O2: TAX DUE
B3: =GFA!B3 -> P.O BOX 9473-00200 NAIROBI | N3: =O3-Q3 -> 10270 | O3: 10270
B4: WATER BILL | G4: BILL NO. | H4: =GFA!G4+9-1 -> 20242009 | N4: =O4-Q4 -> 10304 | O4: 10304
N5: =O5-Q5 -> 10988 | O5: 10988
B6: TENANT NAME | C6: =meter!A11 -> EVELYNE | N6: =O6-Q6 -> 11070 | O6: 11070
C7: O713373975 | N7: =O7-Q7 -> 1197 | O7: 1197
B8: HOUSE NUMBER: | C8: 1C | N8: =O8-Q8 -> 9250 | O8: 9250
N9: =O9-Q9 -> 8770 | O9: 8770
B10: ISSUE DATE | C10: =GFA!C10 -> 29TH JAN 026 | N10: =O10-Q10 -> 23190 | O10: 23190
N11: =O11-Q11 -> 10910 | O11: 10910
B12: LAST PAY DATE | C12: =GFA!C12 -> 5TH FEB 2026 | N12: =O12-Q12 -> 10910 | O12: 10910
N13: =O13-Q13 -> 12190 | O13: 12190
N14: =O14-Q14 -> 11070 | O14: 11070
B15: PREVIOUS READING | C15: CURRENT READING | E15: CONSUMPTION | N15: =O15-Q15 -> 9090 | O15: 9090
B16: =meter!E11 -> 134 | C16: =meter!F11 -> 136 | D16: Units | E16: =C16-B16 -> 2 | N16: =O16-Q16 -> 9420 | O16: 9420
E17: Amount (Kshs.) | N17: =O17-Q17 -> 11154 | O17: 11154
C18: LAST ACCOUNT | D18: kshs. | E18: =meter!O11 -> 9205 | N18: =O18-Q18 -> 10430 | O18: 10430
N19: =O19-Q19 -> 11831 | O19: 11831
C20: MONTH BILL | D20: KSHS. | E20: =meter!I11 -> 210 | N20: =O20-Q20 -> 10590 | O20: 10590
N21: =O21-Q21 -> 22423 | O21: 22423
C22: PUMP/POWER CHARGES | D22: KSHS. | E22: =GFA!D22 -> 70 | N22: =O22-Q22 -> 9250 | O22: 9250
N23: =O23-Q23 -> 10162 | O23: 10162
C24: MONTH HOUSE RENT | D24: KSHS. | E24: =meter!N11 -> 9000 | N24: =O24-Q24 -> 10270 | O24: 10270
N25: =O25-Q25 -> 11070 | O25: 11070
D26: =GFA!C26 -> 0 | E26: =GFA!D26 -> 0 | N26: =O26-Q26 -> 11550 | O26: 11550
C27: GARBAGE FEE | D27: Kshs. | E27: 30 | N27: =O27-Q27 -> 11393 | O27: 11393
C28: Penalty & Interest late payment | D28: KSHS. | E28: =IF(E18*2%*1<0,0,E18*2%*1) -> 184.1 | N28: =O28-Q28 -> 10802 | O28: 10802
N29: =O29-Q29 -> 8930 | O29: 8930
C30: TOTAL PAYABLE | D30: Kshs. | E30: =SUM(E17:E29) -> 18699.1 | N30: =O30-Q30 -> 9570 | O30: 9570
N31: =O31-Q31 -> 11390 | O31: 11390
C32: PAID | E32: =meter!R11 -> 0 | N32: =O32-Q32 -> 10750 | O32: 10750
N33: =O33-Q33 -> 11732 | O33: 11732
C34: AMOUNT DUE | E34: =E30-E32 -> 18699.1 | N34: =O34-Q34 -> 10934 | O34: 10934 | R34: 700
B35: NOTE | N35: =O35-Q35 -> 10270 | O35: 10270
A36: a) | B36: Rent is due on or before 5th of the month. By 7th day, any rent not paid will attract interest at 2% per day. | N36: =O36-Q36 -> 10598 | O36: 10598
N37: =O37-Q37 -> 8770 | O37: 8770
B38: PAY BILL 4139271 | N38: =O38-Q38 -> 8770 | O38: 8770
B39: ACC NO EMB 1C | O39: =SUM(O3:O38) -> 391268 | Q39: =SUM(Q3:Q38) -> 0
B41: NOTE:KINDLY FORWARD SMS AFTER PAYMENT TO 0700194262 INDICATING HOUSE NO
O49: ……………

Sheet 2C
B2: OLE SAMEDHA EMBASSY | N2: VAR | O2: TAX DUE
B3: =GFA!B3 -> P.O BOX 9473-00200 NAIROBI | N3: =O3-Q3 -> 10270 | O3: 10270
B4: WATER BILL | G4: BILL NO. | H4: =GFA!G4+10-1 -> 20242010 | N4: =O4-Q4 -> 10304 | O4: 10304
N5: =O5-Q5 -> 10988 | O5: 10988
B6: TENANT NAME | C6: =meter!A12 -> NELSON | N6: =O6-Q6 -> 11070 | O6: 11070
C7: O701403937 | N7: =O7-Q7 -> 1197 | O7: 1197
B8: HOUSE NUMBER: | C8: 2C | N8: =O8-Q8 -> 9250 | O8: 9250
N9: =O9-Q9 -> 8770 | O9: 8770
B10: ISSUE DATE | C10: =GFA!C10 -> 29TH JAN 026 | N10: =O10-Q10 -> 23190 | O10: 23190
N11: =O11-Q11 -> 10910 | O11: 10910
B12: LAST PAY DATE | C12: =GFA!C12 -> 5TH FEB 2026 | N12: =O12-Q12 -> 10910 | O12: 10910
N13: =O13-Q13 -> 12190 | O13: 12190
N14: =O14-Q14 -> 11070 | O14: 11070
B15: PREVIOUS READING | C15: CURRENT READING | E15: CONSUMPTION | N15: =O15-Q15 -> 9090 | O15: 9090
B16: =meter!E12 -> 258 | C16: =meter!F12 -> 258 | D16: Units | E16: =C16-B16 -> 0 | N16: =O16-Q16 -> 9420 | O16: 9420
E17: Amount (Kshs) | N17: =O17-Q17 -> 11154 | O17: 11154
C18: LAST ACCOUNT | D18: kshs. | E18: =meter!O12 -> 74 | N18: =O18-Q18 -> 10430 | O18: 10430
N19: =O19-Q19 -> 11831 | O19: 11831
C20: MONTH BILL | D20: KSHS. | E20: =meter!I12 -> 0 | N20: =O20-Q20 -> 10590 | O20: 10590
N21: =O21-Q21 -> 22423 | O21: 22423
C22: PUMP/POWER CHARGES | D22: KSHS. | E22: =GFA!D22 -> 70 | N22: =O22-Q22 -> 9250 | O22: 9250
N23: =O23-Q23 -> 10162 | O23: 10162
C24: MONTH HOUSE RENT | D24: KSHS. | E24: =meter!N12 -> 9500 | N24: =O24-Q24 -> 10270 | O24: 10270
N25: =O25-Q25 -> 11070 | O25: 11070
D26: KSHS. | E26: =meter!M12 -> 0 | N26: =O26-Q26 -> 11550 | O26: 11550
C27: GARBAGE FEE | D27: KSHS. | E27: 30 | N27: =O27-Q27 -> 11393 | O27: 11393
C28: INTEREST ON LATE PAYMENT | D28: KSHS. | E28: =IF(E18*2%*1<0,0,E18*2%*1) -> 1.48 | N28: =O28-Q28 -> 10802 | O28: 10802
N29: =O29-Q29 -> 8930 | O29: 8930
C30: TOTAL PAYABLE | D30: Kshs. | E30: =SUM(E17:E29) -> 9675.48 | N30: =O30-Q30 -> 9570 | O30: 9570
N31: =O31-Q31 -> 11390 | O31: 11390
C32: PAID | E32: =meter!R12 -> 0 | N32: =O32-Q32 -> 10750 | O32: 10750
N33: =O33-Q33 -> 11732 | O33: 11732
C34: AMOUNT DUE | E34: =E30-E32 -> 9675.48 | N34: =O34-Q34 -> 10934 | O34: 10934 | R34: 700
B35: NOTE | N35: =O35-Q35 -> 10270 | O35: 10270
A36: a) | B36: Rent is due on or before 5th of the month. By 7th day, any rent not paid will attract interest at 2% per day. | N36: =O36-Q36 -> 10598 | O36: 10598
B37: PAY BILL 4139271
B38: ACC NO EMB 2C
B39: NOTE:KINDLY FORWARD SMS AFTER PAYMENT TO 0700194262 INDICATING HOUSE NO
O49: ……………

Sheet 3C
B2: OLE SAMEDHA EMBASSY | N2: VAR | O2: TAX DUE
B3: =GFA!B3 -> P.O BOX 9473-00200 NAIROBI | N3: =O3-Q3 -> 10270 | O3: 10270
B4: WATER BILL | G4: BILL NO. | H4: =GFA!G4+11-1 -> 20242011 | N4: =O4-Q4 -> 10304 | O4: 10304
N5: =O5-Q5 -> 10988 | O5: 10988
B6: TENANT NAME | C6: =meter!A13 -> agnes | N6: =O6-Q6 -> 11070 | O6: 11070
C7: O701269097 | N7: =O7-Q7 -> 1197 | O7: 1197
B8: HOUSE NUMBER: | C8: 3C | N8: =O8-Q8 -> 9250 | O8: 9250
N9: =O9-Q9 -> 8770 | O9: 8770
B10: ISSUE DATE | C10: =GFA!C10 -> 29TH JAN 026 | N10: =O10-Q10 -> 23190 | O10: 23190
N11: =O11-Q11 -> 10910 | O11: 10910
B12: LAST PAY DATE | C12: =GFA!C12 -> 5TH FEB 2026 | N12: =O12-Q12 -> 10910 | O12: 10910
N13: =O13-Q13 -> 12190 | O13: 12190
N14: =O14-Q14 -> 11070 | O14: 11070
B15: PREVIOUS READING | C15: CURRENT READING | E15: CONSUMPTION | N15: =O15-Q15 -> 9090 | O15: 9090
B16: =meter!E13 -> 148 | C16: =meter!F13 -> 149 | D16: Units | E16: =C16-B16 -> 1 | N16: =O16-Q16 -> 9420 | O16: 9420
E17: Amount (Kshs.) | N17: =O17-Q17 -> 11154 | O17: 11154
C18: LAST ACCOUNT | D18: kshs. | E18: =meter!O13 -> 205 | N18: =O18-Q18 -> 10430 | O18: 10430
N19: =O19-Q19 -> 11831 | O19: 11831
C20: MONTH BILL | D20: KSHS. | E20: =meter!I13 -> 105 | N20: =O20-Q20 -> 10590 | O20: 10590
N21: =O21-Q21 -> 22423 | O21: 22423
C22: PUMP/POWER CHARGES | D22: KSHS. | E22: =GFA!D22 -> 70 | N22: =O22-Q22 -> 9250 | O22: 9250
N23: =O23-Q23 -> 10162 | O23: 10162
C24: MONTH HOUSE RENT | D24: KSHS. | E24: =meter!N13 -> 7000 | N24: =O24-Q24 -> 10270 | O24: 10270
N25: =O25-Q25 -> 11070 | O25: 11070
D26: KSHS. | E26: =GFA!D26 -> 0 | N26: =O26-Q26 -> 11550 | O26: 11550
C27: GARBAGE FEE | D27: KSHS. | E27: 30 | N27: =O27-Q27 -> 11393 | O27: 11393
C28: INTEREST ON LATE PAYMENT | D28: KSHS. | E28: =IF(E18*2%*1<0,0,E18*2%*1) -> 4.1 | N28: =O28-Q28 -> 10802 | O28: 10802
N29: =O29-Q29 -> 8930 | O29: 8930
C30: TOTAL PAYABLE | D30: Kshs. | E30: =SUM(E17:E29) -> 7414.1 | N30: =O30-Q30 -> 9570 | O30: 9570
N31: =O31-Q31 -> 11390 | O31: 11390
C32: PAID | E32: =meter!R13 -> 0 | N32: =O32-Q32 -> 10750 | O32: 10750
N33: =O33-Q33 -> 11732 | O33: 11732
C34: AMOUNT DUE | E34: =E30-E32 -> 7414.1 | N34: =O34-Q34 -> 10934 | O34: 10934 | R34: 700
B35: NOTE | N35: =O35-Q35 -> 10270 | O35: 10270
A36: a) | B36: Rent is due on or before 5th of the month. By 7th day, any rent not paid will attract interest at 2% per day. | N36: =O36-Q36 -> 10598 | O36: 10598
N37: =O37-Q37 -> 8770 | O37: 8770
N38: =O38-Q38 -> 8770 | O38: 8770
B39: PAY BILL 4139271
B40: ACC NO EMB 3C
B41: NOTE:KINDLY FORWARD SMS AFTER PAYMENT TO 0700194262 INDICATING HOUSE NO
...

Sheet meter
A2: NAMES | C2: HOUSE | D2: PERIOD | E2: PREVIOUS | F2: CURRENT | G2: READING | H2: RATE | I2: cost @160/= | J2: Fixed Charge | K2: Total H2O Bill | L2: GARBAGE FEE | N2: RENT | O2: BAL B/F | P2: INTEREST & PENALTY | Q2: TOTAL | R2: PAID | S2: BAL C/F | T2: EARLY DISCOUNT 3% | U2: REMARKS | V2: Hse No.
A3: GFA | B3: 1 | C3: G FA | D3: 46023 | E3: 177 | F3: 179 | G3: =F3-E3 -> 2 | H3: 105 | I3: =G3*H3 -> 210 | J3: 70 | K3: =SUM(I3+J3) -> 280 | L3: 30 | M3: 0 | N3: 6000 | O3: 5 | P3: =GFA!D28 -> 0.1 | Q3: =K3+L3+M3+N3+O3+P3 -> 6315.1 | R3: 0 | S3: =Q3-R3 -> 6315.1 | V3: 1 | W3: 10700 | X3: =W3-Q3 -> 4384.9
A4: VACCANT | B4: 2 | C4: G FB | D4: 46023 | E4: 110 | F4: 110 | G4: =F4-E4 -> 0 | H4: 105 | I4: =G4*H4 -> 0 | J4: 70 | K4: =I4+J4 -> 70 | L4: 30 | M4: 0 | N4: 5000 | P4: =GFB!F28 -> 0 | Q4: =K4+L4+M4+N4+O4+P4 -> 5100 | R4: 0 | S4: =Q4-R4 -> 5100 | V4: 2 | W4: 11800 | X4: =W4-Q4 -> 6700
A5: CHARLES MOMANYI | B5: 3 | C5: 1A | D5: =SUM(D4) -> 46023 | E5: 144 | F5: 147 | G5: =F5-E5 -> 3 | H5: 105 | I5: =G5*H5 -> 315 | J5: 70 | K5: =I5+J5 -> 385 | L5: 30 | M5: 0 | N5: 6000 | O5: 2925 | P5: ='1A'!E28 -> 58.5 | Q5: =K5+L5+M5+N5+O5+P5 -> 9398.5 | R5: 0 | S5: =Q5-R5 -> 9398.5 | V5: 3 | W5: 11640 | X5: =W5-Q5 -> 2241.5
A6: GLADYS | B6: 4 | C6: 2A | D6: =SUM(D4) -> 46023 | E6: 213 | F6: 213 | G6: =F6-E6 -> 0 | H6: 105 | I6: =G6*H6 -> 0 | J6: 70 | K6: =I6+J6 -> 70 | L6: 30 | M6: 0 | N6: 6000 | O6: 6310 | P6: ='2A'!E28 -> 126.2 | Q6: =K6+L6+M6+N6+O6+P6 -> 12536.2 | R6: 0 | S6: =Q6-R6 -> 12536.2 | V6: 4 | W6: 10700 | X6: =W6-Q6 -> -1836.2
A7: VINCENT | B7: 5 | C7: 3A | D7: =SUM(D4) -> 46023 | E7: 159 | F7: 160 | G7: =F7-E7 -> 1 | H7: 105 | I7: =G7*H7 -> 105 | J7: 70 | K7: =I7+J7 -> 175 | L7: 30 | M7: 0 | N7: 6000 | O7: 20665 | P7: ='3A'!E28 -> 413.3 | Q7: =K7+L7+M7+N7+O7+P7 -> 27283.3 | R7: 0 | S7: =Q7-R7 -> 27283.3 | V7: 5 | W7: 2300 | X7: =W7-Q7 -> -24983.3
A8: VERONICAH | B8: 6 | C8: 1B | D8: =SUM(D5) -> 46023 | E8: 195 | F8: 196 | G8: =F8-E8 -> 1 | H8: 105 | I8: =G8*H8 -> 105 | J8: 70 | K8: =I8+J8 -> 175 | L8: 30 | M8: 0 | N8: 6000 | O8: 110 | P8: ='1B'!E28 -> 2.2 | Q8: =K8+L8+M8+N8+O8+P8 -> 6317.2 | R8: 0 | S8: =Q8-R8 -> 6317.2 | V8: 6 | W8: 9420 | X8: =W8-Q8 -> 3102.8
A9: DUKE | B9: 7 | C9: 2B | D9: =SUM(D6) -> 46023 | E9: 129 | F9: 129 | G9: =F9-E9 -> 0 | H9: 105 | I9: =G9*H9 -> 0 | J9: 70 | K9: =I9+J9 -> 70 | L9: 30 | M9: 0 | N9: 6000 | O9: 6600 | P9: ='2B'!E28 -> 132 | Q9: =K9+L9+M9+N9+O9+P9 -> 12832 | R9: 0 | S9: =Q9-R9 -> 12832 | V9: 7 | W9: 9920 | X9: =W9-Q9 -> -2912
A10: NECODEMUS | B10: 8 | C10: 3B | D10: =SUM(D7) -> 46023 | E10: 88 | F10: 88 | G10: =F10-E10 -> 0 | H10: 105 | I10: =G10*H10 -> 0 | J10: 70 | K10: =I10+J10 -> 70 | L10: 30 | M10: 0 | N10: 6000 | O10: 6389 | P10: ='3B'!E28 -> 127.78 | Q10: =K10+L10+M10+N10+O10+P10 -> 12616.78 | R10: 0 | S10: =Q10-R10 -> 12616.78 | V10: 8 | W10: 11860 | X10: =W10-Q10 -> -756.78
A11: EVELYNE | B11: 9 | C11: 1C | D11: =SUM(D8) -> 46023 | E11: 134 | F11: 136 | G11: =F11-E11 -> 2 | H11: 105 | I11: =G11*H11 -> 210 | J11: 70 | K11: =I11+J11 -> 280 | L11: 30 | M11: 0 | N11: 9000 | O11: 9205 | P11: ='1C'!E28 -> 184.1 | Q11: =K11+L11+M11+N11+O11+P11 -> 18699.1 | R11: 0 | S11: =Q11-R11 -> 18699.1 | V11: 9 | W11: 11640 | X11: =W11-Q11 -> -7059.1
A12: NELSON | B12: 10 | C12: 2C | D12: =SUM(D9) -> 46023 | E12: 258 | F12: 258 | G12: =F12-E12 -> 0 | H12: 105 | I12: =G12*H12 -> 0 | J12: 70 | K12: =I12+J12 -> 70 | L12: 30 | M12: 0 | N12: 9500 | O12: 74 | P12: ='2C'!E28 -> 1.48 | Q12: =K12+L12+M12+N12+O12+P12 -> 9675.48 | R12: 0 | S12: =Q12-R12 -> 9675.48 | V12: 10 | W12: 11860 | X12: =W12-Q12 -> 2184.52
A13: agnes | B13: 11 | C13: 3C | D13: =SUM(D10) -> 46023 | E13: 148 | F13: 149 | G13: =F13-E13 -> 1 | H13: 105 | I13: =G13*H13 -> 105 | J13: 70 | K13: =I13+J13 -> 175 | L13: 30 | M13: 0 | N13: 7000 | O13: 205 | P13: ='3C'!E28 -> 4.1 | Q13: =K13+L13+M13+N13+O13+P13 -> 7414.1 | R13: 0 | S13: =Q13-R13 -> 7414.1 | V13: 11 | W13: 11360 | X13: =W13-Q13 -> 3945.9
A14: TOTAL | G14: =SUM(G3:G13) -> 10 | N14: =SUM(N3:N13) -> 72500 | Q14: =SUM(Q3:Q13) -> 128187.76

Sheet Sheet3

Sheet Sheet1
L16: 101456
L17: 21
L18: 1364
L19: 81411 | M19: salary
L21: =L16-L19 -> 20045
L22: =L19-55000 -> 26411

Sheet Sheet2
I1: MAY | J1: JUNE | K1: JUL
I2: 8300 | J2: 21000 | K2: 9962
I3: 9608 | J3: 9962 | K3: 10623
I4: 9608 | J4: 11039 | K4: 8510
I5: 7525 | J5: 10117 | K5: 10100
I6: 11000 | J6: 10778
I7: 8985 | J7: 10750
I8: 7857 | J8: 8510
I9: 6000 | J9: 11230
I10: 9005 | J10: 8500
I11: 10665 | J11: 10590
I12: 9335 | J12: 10400
I13: 8040 | J13: 10000
I14: 8000 | J14: 10840
I15: 10560 | J15: 10200 | K15: 11200
I16: 11000 | J16: 10225 | K16: 11360
I17: 9421 | J17: 9000 | K17: 9787
I18: 10000 | J18: 9945 | K18: 9130
I19: 10700 | J19: 10000 | K19: 10250
I20: 10055 | J20: 5000 | K20: 10740
I21: 10200 | J21: 8900 | K21: 10910
I22: 1977 | J22: 9962 | K22: 9000
I23: 10155 | J23: 10583 | K23: 10353
I24: 10000 | J24: 11200 | K24: 10910
I25: 8000 | J25: 9930 | K25: 8930
I26: 9925 | J26: 8662 | K26: 1200
... I32: 10000 | J32: 10860 | K32: 6000
I33: 5520 | K33: 8500
I34: 9805 | K34: 10430
I35: 20000 | K35: 10000
E36: 119472 | I36: 7000 | K36: 10000
E37: 64399 | I37: 5000 | K37: 11000
E38: =SUM(E36:E37) -> 183871 | I38: 20000 | K38: 8950
I39: 13000 | K39: 11230
I40: 10910 | K40: 400
K41: 7800
K42: 1000
K43: 8000
K44: 6294
I45: =SUM(I2:I44) -> 366751 | J45: =SUM(J2:J44) -> 307193 | K45: =SUM(K2:K44) -> 301808
