Workbook

Sheet 1A
B1: OLE SAMEDHA PREMIER HOSTELS
B2: P.O BOX 9473-00200 NAIROBI | N2: VAR | O2: TAX DUE
B3: WATER BILL | G3: BILL NO. | H3: 38 | N3: =O3-Q3 -> 10270 | O3: 10270
N4: =O4-Q4 -> 10304 | O4: 10304
B5: TENANT NAME | C5: =meter!B4 -> ABDI NALMA | N5: =O5-Q5 -> 10988 | O5: 10988
N6: =O6-Q6 -> 11070 | O6: 11070
B7: HOUSE NUMBER | C7: 1A | N7: =O7-Q7 -> 1197 | O7: 1197
N8: =O8-Q8 -> 9250 | O8: 9250
B9: ISSUE DATE | C9: 30TH JAN 2026 | N9: =O9-Q9 -> 8770 | O9: 8770
N10: =O10-Q10 -> 23190 | O10: 23190
B11: LAST PAY DATE | C11: 5TH FEB 2026 | N11: =O11-Q11 -> 10910 | O11: 10910
N12: =O12-Q12 -> 10910 | O12: 10910
N13: =O13-Q13 -> 12190 | O13: 12190
B14: PREVIOUS READING | C14: CURRENT READING | E14: CONSUMPTION (Units) | N14: =O14-Q14 -> 11070 | O14: 11070
B15: =meter!E4 -> 23 | C15: =meter!F4 -> 24 | D15: Units | E15: =C15-B15 -> 1 | N15: =O15-Q15 -> 9090 | O15: 9090
E16: AMOUNT KSHS | N16: =O16-Q16 -> 9420 | O16: 9420
C17: LAST ACCOUNT B/F | D17: Kshs. | E17: =meter!O4 -> 0 | N17: =O17-Q17 -> 11154 | O17: 11154
N18: =O18-Q18 -> 10430 | O18: 10430
C19: MONTH Water BILL | D19: Kshs. | E19: =meter!I4 -> 150 | N19: =O19-Q19 -> 11831 | O19: 11831
N20: =O20-Q20 -> 10590 | O20: 10590
C21: PUMP/POWER CHARGES | D21: Kshs. | E21: =meter!J4 -> 0 | N21: =O21-Q21 -> 22423 | O21: 22423
N22: =O22-Q22 -> 9250 | O22: 9250
C23: MONTH HOUSE RENT | D23: Kshs. | E23: =meter!N4 -> 7000 | N23: =O23-Q23 -> 10162 | O23: 10162
N24: =O24-Q24 -> 10270 | O24: 10270
C25: SECURITY | D25: Kshs. | E25: 0 | N25: =O25-Q25 -> 11070 | O25: 11070
C26: GARBAGE FEE | D26: Kshs. | N26: =O26-Q26 -> 11550 | O26: 11550
C27: LATE PAY INTEREST | D27: Kshs. | E27: =IF(E17*6%*3<0,0,E17*6%*3) -> 0 | N27: =O27-Q27 -> 11393 | O27: 11393
N28: =O28-Q28 -> 10802 | O28: 10802
C29: TOTAL PAYABLE | D29: Kshs. | E29: =E17+E19+E21+E23+E25+E26+E27 -> 7150 | N29: =O29-Q29 -> 8930 | O29: 8930
N30: =O30-Q30 -> 9570 | O30: 9570
C31: PAID | E31: =meter!T4 -> 0 | N31: =O31-Q31 -> 11390 | O31: 11390
N32: =O32-Q32 -> 10750 | O32: 10750
C33: AMOUNT DUE | E33: =E29-E31 -> 7150 | N33: =O33-Q33 -> 11732 | O33: 11732
B34: NOTE | N34: =O34-Q34 -> 10934 | O34: 10934 | R34: 700
N35: =O35-Q35 -> 10270 | O35: 10270
B36: PAY BILL 4139271 ACC NO UM 1A | N36: =O36-Q36 -> 10598 | O36: 10598
N37: =O37-Q37 -> 8770 | O37: 8770
N38: =O38-Q38 -> 8770 | O38: 8770
O39: =SUM(O3:O38) -> 391268 | Q39: =SUM(Q3:Q38) -> 0

Sheet 2A
B2: OLE SAMEDHA PREMIER HOSTELS | N2: VAR | O2: TAX DUE
B3: ='1A'!B2 -> P.O BOX 9473-00200 NAIROBI | N3: =O3-Q3 -> 10270 | O3: 10270
B4: WATER BILL | F4: BILL NO. | G4: ='1A'!H3+2-1 -> 39 | N4: =O4-Q4 -> 10304 | O4: 10304
N5: =O5-Q5 -> 10988 | O5: 10988
B6: TENANT NAME | D6: =meter!B5 -> NEW TENANT | N6: =O6-Q6 -> 11070 | O6: 11070
N7: =O7-Q7 -> 1197 | O7: 1197
B8: HOUSE NUMBER | D8: 2A | N8: =O8-Q8 -> 9250 | O8: 9250
N9: =O9-Q9 -> 8770 | O9: 8770
B10: ISSUE DATE | D10: ='1A'!C9 -> 30TH JAN 2026 | N10: =O10-Q10 -> 23190 | O10: 23190
N11: =O11-Q11 -> 10910 | O11: 10910
B12: LAST PAY DATE | D12: ='1A'!C11 -> 5TH FEB 2026 | N12: =O12-Q12 -> 10910 | O12: 10910
N13: =O13-Q13 -> 12190 | O13: 12190
N14: =O14-Q14 -> 11070 | O14: 11070
B15: PREVIOUS READING | D15: CURRENT READING | F15: CONSUMPTION (Units) | N15: =O15-Q15 -> 9090 | O15: 9090
B16: =meter!E5 -> 34 | D16: =meter!F5 -> 37 | E16: Units | F16: =D16-B16 -> 3 | N16: =O16-Q16 -> 9420 | O16: 9420
F17: Amount (Kshs.) | N17: =O17-Q17 -> 11154 | O17: 11154
D18: LAST ACCOUNT B/F | E18: Kshs. | F18: =meter!O5 -> 0 | N18: =O18-Q18 -> 10430 | O18: 10430
N19: =O19-Q19 -> 11831 | O19: 11831
D20: MONTH BILL | E20: Kshs. | F20: =meter!I5 -> 450 | N20: =O20-Q20 -> 10590 | O20: 10590
N21: =O21-Q21 -> 22423 | O21: 22423
D22: PUMP/POWER CHARGES | E22: Kshs. | F22: ='1A'!E21 -> 0 | N22: =O22-Q22 -> 9250 | O22: 9250
N23: =O23-Q23 -> 10162 | O23: 10162
D24: MONTH HOUSE RENT | E24: Kshs. | F24: =meter!N5 -> 7000 | N24: =O24-Q24 -> 10270 | O24: 10270
N25: =O25-Q25 -> 11070 | O25: 11070
D26: ='1A'!C25 -> SECURITY | E26: Kshs. | F26: ='1A'!E25 -> 0 | N26: =O26-Q26 -> 11550 | O26: 11550
D27: GARBAGE FEE | N27: =O27-Q27 -> 11393 | O27: 11393
D28: INTEREST ON ARREARS | E28: Kshs. | F28: =IF(F18*6%*3<0,0,F18*6%*3) -> 0 | N28: =O28-Q28 -> 10802 | O28: 10802
F29: 0 | N29: =O29-Q29 -> 8930 | O29: 8930
D30: TOTAL PAYABLE | E30: Kshs. | F30: =SUM(F17:F29) -> 7450 | N30: =O30-Q30 -> 9570 | O30: 9570
N31: =O31-Q31 -> 11390 | O31: 11390
D32: PAID | F32: =meter!T5 -> 0 | N32: =O32-Q32 -> 10750 | O32: 10750
N33: =O33-Q33 -> 11732 | O33: 11732
D34: AMOUNT DUE | F34: =F30-F32 -> 7450 | N34: =O34-Q34 -> 10934 | O34: 10934 | R34: 700
C35: NOTE | N35: =O35-Q35 -> 10270 | O35: 10270
N36: =O36-Q36 -> 10598 | O36: 10598
B37: PAY BILL 4139271 ACC NO UM 2A | N37: =O37-Q37 -> 8770 | O37: 8770
N38: =O38-Q38 -> 8770 | O38: 8770
O39: =SUM(O3:O38) -> 391268 | Q39: =SUM(Q3:Q38) -> 0
A43: f) | B43: .
A51: E & O E | B51: .
...

Sheet 3A
B2: OLE SAMEDHA PREMIER HOSTELS | N2: VAR | O2: TAX DUE
B3: ='1A'!B2 -> P.O BOX 9473-00200 NAIROBI | N3: =O3-Q3 -> 10270 | O3: 10270
B4: WATER BILL | G4: BILL NO. | H4: ='1A'!H3+3-1 -> 40 | N4: =O4-Q4 -> 10304 | O4: 10304
N5: =O5-Q5 -> 10988 | O5: 10988
B6: TENANT NAME | C6: =meter!B6 -> RAMADHAN | N6: =O6-Q6 -> 11070 | O6: 11070
N7: =O7-Q7 -> 1197 | O7: 1197
B8: HOUSE NUMBER: | C8: 3A | N8: =O8-Q8 -> 9250 | O8: 9250
N9: =O9-Q9 -> 8770 | O9: 8770
B10: ISSUE DATE | C10: ='1A'!C9 -> 30TH JAN 2026 | N10: =O10-Q10 -> 23190 | O10: 23190
N11: =O11-Q11 -> 10910 | O11: 10910
B12: LAST PAY DATE | C12: ='1A'!C11 -> 5TH FEB 2026 | N12: =O12-Q12 -> 10910 | O12: 10910
N13: =O13-Q13 -> 12190 | O13: 12190
N14: =O14-Q14 -> 11070 | O14: 11070
B15: PREVIOUS READING | C15: CURRENT READING | E15: CONSUMPTION (Units) | N15: =O15-Q15 -> 9090 | O15: 9090
B16: =meter!E6 -> 14 | C16: =meter!F6 -> 15 | D16: Units | E16: =C16-B16 -> 1 | N16: =O16-Q16 -> 9420 | O16: 9420
E17: Amount (Kshs.) | N17: =O17-Q17 -> 11154 | O17: 11154
C18: LAST ACCOUNT B/F | D18: Kshs. | E18: =meter!O6 -> 0 | N18: =O18-Q18 -> 10430 | O18: 10430
N19: =O19-Q19 -> 11831 | O19: 11831
C20: MONTH BILL | D20: Kshs. | E20: =meter!I6 -> 150 | N20: =O20-Q20 -> 10590 | O20: 10590
N21: =O21-Q21 -> 22423 | O21: 22423
C22: PUMP/POWER CHARGES | D22: Kshs. | E22: =meter!J6 -> 0 | N22: =O22-Q22 -> 9250 | O22: 9250
N23: =O23-Q23 -> 10162 | O23: 10162
C24: MONTH HOUSE RENT | D24: Kshs. | E24: =meter!N6 -> 7000 | N24: =O24-Q24 -> 10270 | O24: 10270
N25: =O25-Q25 -> 11070 | O25: 11070
C26: SECURITY | D26: Kshs. | E26: 0 | N26: =O26-Q26 -> 11550 | O26: 11550
C27: GARBAGE FEE | D27: Kshs. | N27: =O27-Q27 -> 11393 | O27: 11393
C28: ADJUSTMENT | D28: Kshs. | E28: =IF(E18*6%*3<0,0,E18*6%*3) -> 0 | N28: =O28-Q28 -> 10802 | O28: 10802
N29: =O29-Q29 -> 8930 | O29: 8930
C30: TOTAL PAYABLE | D30: Kshs. | E30: =SUM(E17:E29) -> 7150 | N30: =O30-Q30 -> 9570 | O30: 9570
N31: =O31-Q31 -> 11390 | O31: 11390
C32: PAID | E32: =meter!T6 -> 0 | N32: =O32-Q32 -> 10750 | O32: 10750
N33: =O33-Q33 -> 11732 | O33: 11732
C34: AMOUNT DUE | E34: =E30-E32 -> 7150 | N34: =O34-Q34 -> 10934 | O34: 10934 | R34: 700
B35: NOTE | N35: =O35-Q35 -> 10270 | O35: 10270
N36: =O36-Q36 -> 10598 | O36: 10598
N37: =O37-Q37 -> 8770 | O37: 8770
B38: PAYBILL 4139271 ACC NO UM 3A | N38: =O38-Q38 -> 8770 | O38: 8770
O39: =SUM(O3:O38) -> 391268 | Q39: =SUM(Q3:Q38) -> 0

Sheet 4A
B2: OLE SAMEDHA PREMIER HOSTELS | N2: VAR | O2: TAX DUE
B3: ='1A'!B2 -> P.O BOX 9473-00200 NAIROBI | N3: =O3-Q3 -> 10270 | O3: 10270
B4: WATER BILL | G4: BILL NO. | H4: ='1A'!H3+4-1 -> 41 | N4: =O4-Q4 -> 10304 | O4: 10304
N5: =O5-Q5 -> 10988 | O5: 10988
B6: TENANT NAME | C6: =meter!B7 -> NASRA | N6: =O6-Q6 -> 11070 | O6: 11070
N7: =O7-Q7 -> 1197 | O7: 1197
B8: HOUSE NUMBER: | C8: 4A | N8: =O8-Q8 -> 9250 | O8: 9250
N9: =O9-Q9 -> 8770 | O9: 8770
B10: ISSUE DATE | C10: ='1A'!C9 -> 30TH JAN 2026 | N10: =O10-Q10 -> 23190 | O10: 23190
N11: =O11-Q11 -> 10910 | O11: 10910
B12: LAST PAY DATE | C12: ='1A'!C11 -> 5TH FEB 2026 | N12: =O12-Q12 -> 10910 | O12: 10910
N13: =O13-Q13 -> 12190 | O13: 12190
N14: =O14-Q14 -> 11070 | O14: 11070
B15: PREVIOUS READING | C15: CURRENT READING | E15: CONSUMPTION | N15: =O15-Q15 -> 9090 | O15: 9090
B16: =meter!E7 -> 10 | C16: =meter!F7 -> 12 | D16: Units | E16: =C16-B16 -> 2 | N16: =O16-Q16 -> 9420 | O16: 9420
E17: Amount (Kshs) | N17: =O17-Q17 -> 11154 | O17: 11154
C18: LAST ACCOUNT B/F | D18: Kshs. | E18: =meter!O7 -> 451 | N18: =O18-Q18 -> 10430 | O18: 10430
N19: =O19-Q19 -> 11831 | O19: 11831
C20: MONTH BILL | D20: Kshs. | E20: =meter!I7 -> 300 | N20: =O20-Q20 -> 10590 | O20: 10590
N21: =O21-Q21 -> 22423 | O21: 22423
C22: PUMP/POWER CHARGES | D22: Kshs. | E22: =meter!J7 -> 0 | N22: =O22-Q22 -> 9250 | O22: 9250
N23: =O23-Q23 -> 10162 | O23: 10162
C24: MONTH HOUSE RENT | D24: Kshs. | E24: =meter!N7 -> 7000 | N24: =O24-Q24 -> 10270 | O24: 10270
N25: =O25-Q25 -> 11070 | O25: 11070
C26: SECURITY | D26: Kshs. | E26: =meter!M7 -> 0 | N26: =O26-Q26 -> 11550 | O26: 11550
C27: GARBAGE FEE | D27: Kshs. | N27: =O27-Q27 -> 11393 | O27: 11393
C28: INTEREST ON ARREARS | D28: Kshs. | E28: =IF(E18*6%*3<0,0,E18*6%*3) -> 81.18 | N28: =O28-Q28 -> 10802 | O28: 10802
N29: =O29-Q29 -> 8930 | O29: 8930
C30: TOTAL PAYABLE | D30: Kshs. | E30: =SUM(E17:E29) -> 7832.18 | N30: =O30-Q30 -> 9570 | O30: 9570
N31: =O31-Q31 -> 11390 | O31: 11390
C32: PAID | E32: =meter!T7 -> 0 | N32: =O32-Q32 -> 10750 | O32: 10750
N33: =O33-Q33 -> 11732 | O33: 11732
C34: AMOUNT DUE | E34: =E30-E32 -> 7832.18 | N34: =O34-Q34 -> 10934 | O34: 10934 | R34: 700
B35: NOTE | N35: =O35-Q35 -> 10270 | O35: 10270
N36: =O36-Q36 -> 10598 | O36: 10598
C37: PAY BILL 4139271 ACC NO UM 4A | N37: =O37-Q37 -> 8770 | O37: 8770
N38: =O38-Q38 -> 8770 | O38: 8770
O39: =SUM(O3:O38) -> 391268 | Q39: =SUM(Q3:Q38) -> 0

Sheet 5A
B2: OLE SAMEDHA PREMIER HOSTELS | N2: VAR | O2: TAX DUE
B3: ='1A'!B2 -> P.O BOX 9473-00200 NAIROBI | N3: =O3-Q3 -> 10270 | O3: 10270
B4: WATER BILL | G4: BILL NO. | H4: ='1A'!H3+5-1 -> 42 | N4: =O4-Q4 -> 10304 | O4: 10304
N5: =O5-Q5 -> 10988 | O5: 10988
B6: TENANT NAME | C6: =meter!B8 -> NADYA JAMAL & AMINA ABDUL | N6: =O6-Q6 -> 11070 | O6: 11070
N7: =O7-Q7 -> 1197 | O7: 1197
B8: HOUSE NUMBER; | C8: 5A | N8: =O8-Q8 -> 9250 | O8: 9250
N9: =O9-Q9 -> 8770 | O9: 8770
B10: ISSUE DATE | C10: ='1A'!C9 -> 30TH JAN 2026 | N10: =O10-Q10 -> 23190 | O10: 23190
N11: =O11-Q11 -> 10910 | O11: 10910
B12: LAST PAY DATE | C12: ='1A'!C11 -> 5TH FEB 2026 | N12: =O12-Q12 -> 10910 | O12: 10910
N13: =O13-Q13 -> 12190 | O13: 12190
N14: =O14-Q14 -> 11070 | O14: 11070
B15: PREVIOUS READING | C15: CURRENT READING | E15: CONSUMPTION (Units) | N15: =O15-Q15 -> 9090 | O15: 9090
B16: =meter!E8 -> 18 | C16: =meter!F8 -> 21 | D16: Units | E16: =C16-B16 -> 3 | N16: =O16-Q16 -> 9420 | O16: 9420
E17: Amount(Kshs) | N17: =O17-Q17 -> 11154 | O17: 11154
C18: LAST ACCOUNT B/F | D18: Kshs. | E18: =meter!O8 -> 451 | N18: =O18-Q18 -> 10430 | O18: 10430
N19: =O19-Q19 -> 11831 | O19: 11831
C20: MONTH BILL | D20: Kshs. | E20: =meter!I8 -> 450 | N20: =O20-Q20 -> 10590 | O20: 10590
N21: =O21-Q21 -> 22423 | O21: 22423
C22: PUMP/POWER CHARGES | D22: Kshs. | E22: ='1A'!E21 -> 0 | N22: =O22-Q22 -> 9250 | O22: 9250
N23: =O23-Q23 -> 10162 | O23: 10162
C24: MONTH HOUSE RENT | D24: Kshs. | E24: =meter!N8 -> 7000 | N24: =O24-Q24 -> 10270 | O24: 10270
N25: =O25-Q25 -> 11070 | O25: 11070
C26: ='1A'!C25 -> SECURITY | D26: ='1A'!D25 -> Kshs. | E26: =meter!M8 -> 0 | N26: =O26-Q26 -> 11550 | O26: 11550
C27: GARBAGE FEE | D27: Kshs. | N27: =O27-Q27 -> 11393 | O27: 11393
C28: INTEREST ON ARREARS | D28: Kshs. | E28: =IF(E18*6%*3<0,0,E18*6%*3) -> 81.18 | N28: =O28-Q28 -> 10802 | O28: 10802
N29: =O29-Q29 -> 8930 | O29: 8930
C30: TOTAL PAYABLE | D30: Kshs. | E30: =SUM(E17:E29) -> 7982.18 | N30: =O30-Q30 -> 9570 | O30: 9570
N31: =O31-Q31 -> 11390 | O31: 11390
C32: PAID | E32: =meter!T8 -> 0 | N32: =O32-Q32 -> 10750 | O32: 10750
N33: =O33-Q33 -> 11732 | O33: 11732
C34: AMOUNT DUE | E34: =E30-E32 -> 7982.18 | N34: =O34-Q34 -> 10934 | O34: 10934 | R34: 700
B35: NOTE | N35: =O35-Q35 -> 10270 | O35: 10270
C36: PAY BILL 4139271 ACC NO UM 5A | N36: =O36-Q36 -> 10598 | O36: 10598
N37: =O37-Q37 -> 8770 | O37: 8770
N38: =O38-Q38 -> 8770 | O38: 8770
O39: =SUM(O3:O38) -> 391268 | Q39: =SUM(Q3:Q38) -> 0

Sheet 6A
B2: OLE SAMEDHA PREMIER HOSTELS | N2: VAR | O2: TAX DUE
B3: ='1A'!B2 -> P.O BOX 9473-00200 NAIROBI | N3: =O3-Q3 -> 10270 | O3: 10270
B4: WATER BILL | F4: BILL NO. | G4: BILL NO. | H4: ='1A'!H3+6-1 -> 43 | N4: =O4-Q4 -> 10304 | O4: 10304
N5: =O5-Q5 -> 10988 | O5: 10988
B6: TENANT NAME | C6: =meter!B9 -> 0 | N6: =O6-Q6 -> 11070 | O6: 11070
N7: =O7-Q7 -> 1197 | O7: 1197
B8: HOUSE NUMBER: | C8: 6A | N8: =O8-Q8 -> 9250 | O8: 9250
N9: =O9-Q9 -> 8770 | O9: 8770
B10: ISSUE DATE | C10: ='1A'!C9 -> 30TH JAN 2026 | N10: =O10-Q10 -> 23190 | O10: 23190
N11: =O11-Q11 -> 10910 | O11: 10910
B12: LAST PAY DATE | C12: ='1A'!C11 -> 5TH FEB 2026 | N12: =O12-Q12 -> 10910 | O12: 10910
N13: =O13-Q13 -> 12190 | O13: 12190
N14: =O14-Q14 -> 11070 | O14: 11070
B15: PREVIOUS READING | C15: CURRENT READING | E15: CONSUMPTION | N15: =O15-Q15 -> 9090 | O15: 9090
B16: =meter!E9 -> 11 | C16: =meter!F9 -> 11 | D16: Units | E16: =C16-B16 -> 0 | N16: =O16-Q16 -> 9420 | O16: 9420
E17: Amount(Kshs) | N17: =O17-Q17 -> 11154 | O17: 11154
C18: LAST ACCOUNT | D18: kshs. | E18: =meter!O9 -> 580 | N18: =O18-Q18 -> 10430 | O18: 10430
N19: =O19-Q19 -> 11831 | O19: 11831
C20: MONTH BILL | D20: KSHS. | E20: =meter!I9 -> 0 | N20: =O20-Q20 -> 10590 | O20: 10590
N21: =O21-Q21 -> 22423 | O21: 22423
C22: PUMP/POWER CHARGES | D22: KSHS. | E22: ='1A'!E21 -> 0 | N22: =O22-Q22 -> 9250 | O22: 9250
N23: =O23-Q23 -> 10162 | O23: 10162
C24: MONTH HOUSE RENT | D24: KSHS. | E24: =meter!N9 -> 6000 | N24: =O24-Q24 -> 10270 | O24: 10270
N25: =O25-Q25 -> 11070 | O25: 11070
C26: ='1A'!C25 -> SECURITY | D26: ='1A'!D25 -> Kshs. | E26: =meter!M9 -> 0 | N26: =O26-Q26 -> 11550 | O26: 11550
C27: GARBAGE FEE | N27: =O27-Q27 -> 11393 | O27: 11393
C28: ADJUSTMENT (Interest late payment) | D28: KSHS. | N28: =O28-Q28 -> 10802 | O28: 10802
N29: =O29-Q29 -> 8930 | O29: 8930
C30: TOTAL PAYABLE | D30: Kshs. | E30: =SUM(E17:E29) -> 6580 | N30: =O30-Q30 -> 9570 | O30: 9570
N31: =O31-Q31 -> 11390 | O31: 11390
C32: PAID | E32: =meter!T9 -> 0 | N32: =O32-Q32 -> 10750 | O32: 10750
N33: =O33-Q33 -> 11732 | O33: 11732
C34: AMOUNT DUE | E34: =E30-E32 -> 6580 | N34: =O34-Q34 -> 10934 | O34: 10934 | R34: 700
B35: NOTE | C35: PAY & VACATE, REPAIRS CHARGES OF 8,400/- REMAINS TILL NEW TENANT LEAVES, THEN WE REPAIR | N35: =O35-Q35 -> 10270 | O35: 10270
N36: =O36-Q36 -> 10598 | O36: 10598
C37: PAY BILL 4139271 ACC NO UM 6A | N37: =O37-Q37 -> 8770 | O37: 8770
N38: =O38-Q38 -> 8770 | O38: 8770
O39: =SUM(O3:O38) -> 391268 | Q39: =SUM(Q3:Q38) -> 0

Sheet 1B
B2: OLE SAMEDHA PREMIER HOSTELS | N2: VAR | O2: TAX DUE
B3: ='1A'!B2 -> P.O BOX 9473-00200 NAIROBI | N3: =O3-Q3 -> 10270 | O3: 10270
B4: WATER BILL | G4: BILL NO. | H4: ='1A'!H3+7-1 -> 44 | N4: =O4-Q4 -> 10304 | O4: 10304
N5: =O5-Q5 -> 10988 | O5: 10988
B6: TENANT NAME | C6: =meter!B10 -> MOHAMED | N6: =O6-Q6 -> 11070 | O6: 11070
N7: =O7-Q7 -> 1197 | O7: 1197
B8: HOUSE NUMBER: | C8: 1B | N8: =O8-Q8 -> 9250 | O8: 9250
C9: 072 | N9: =O9-Q9 -> 8770 | O9: 8770
B10: ISSUE DATE | C10: ='1A'!C9 -> 30TH JAN 2026 | N10: =O10-Q10 -> 23190 | O10: 23190
N11: =O11-Q11 -> 10910 | O11: 10910
B12: LAST PAY DATE | C12: ='1A'!C11 -> 5TH FEB 2026 | N12: =O12-Q12 -> 10910 | O12: 10910
N13: =O13-Q13 -> 12190 | O13: 12190
N14: =O14-Q14 -> 11070 | O14: 11070
B15: PREVIOUS READING | C15: CURRENT READING | E15: CONSUMPTION | N15: =O15-Q15 -> 9090 | O15: 9090
B16: =meter!E10 -> 9 | C16: =meter!F10 -> 10 | D16: Units | E16: =C16-B16 -> 1 | N16: =O16-Q16 -> 9420 | O16: 9420
E17: Amount (Kshs) | N17: =O17-Q17 -> 11154 | O17: 11154
C18: LAST ACCOUNT | D18: kshs. | E18: =meter!O10 -> 0 | N18: =O18-Q18 -> 10430 | O18: 10430
N19: =O19-Q19 -> 11831 | O19: 11831
C20: MONTH BILL | D20: KSHS. | E20: =meter!I10 -> 150 | N20: =O20-Q20 -> 10590 | O20: 10590
N21: =O21-Q21 -> 22423 | O21: 22423
C22: PUMP/POWER CHARGES | D22: KSHS. | E22: ='1A'!E21 -> 0 | N22: =O22-Q22 -> 9250 | O22: 9250
N23: =O23-Q23 -> 10162 | O23: 10162
C24: MONTH HOUSE RENT | D24: KSHS. | E24: =meter!N10 -> 7000 | N24: =O24-Q24 -> 10270 | O24: 10270
N25: =O25-Q25 -> 11070 | O25: 11070
C26: ='1A'!C25 -> SECURITY | D26: ='1A'!D25 -> Kshs. | E26: ='1A'!E25 -> 0 | N26: =O26-Q26 -> 11550 | O26: 11550
C27: GARBAGE FEE | N27: =O27-Q27 -> 11393 | O27: 11393
C28: ADJUSTMENT-interest on arrears | D28: KSHS. | E28: =IF(E18*6%*3<0,0,E18*6%*3) -> 0 | N28: =O28-Q28 -> 10802 | O28: 10802
N29: =O29-Q29 -> 8930 | O29: 8930
C30: TOTAL PAYABLE | D30: Kshs. | E30: =SUM(E17:E29) -> 7150 | N30: =O30-Q30 -> 9570 | O30: 9570
N31: =O31-Q31 -> 11390 | O31: 11390
C32: PAID | E32: =meter!T11 -> 0 | N32: =O32-Q32 -> 10750 | O32: 10750
N33: =O33-Q33 -> 11732 | O33: 11732
C34: AMOUNT DUE | E34: =E30-E32 -> 7150 | N34: =O34-Q34 -> 10934 | O34: 10934 | R34: 700
B35: NOTE | N35: =O35-Q35 -> 10270 | O35: 10270
C36: PAY BILL 4139271 ACC NO UM 1B | N36: =O36-Q36 -> 10598 | O36: 10598
N37: =O37-Q37 -> 8770 | O37: 8770
N38: =O38-Q38 -> 8770 | O38: 8770
O39: =SUM(O3:O38) -> 391268 | Q39: =SUM(Q3:Q38) -> 0

Sheet 2B
B2: OLE SAMEDHA PREMIER HOSTELS | N2: VAR | O2: TAX DUE
B3: ='1A'!B2 -> P.O BOX 9473-00200 NAIROBI | N3: =O3-Q3 -> 10270 | O3: 10270
B4: WATER BILL | G4: BILL NO. | H4: ='1A'!H3+8-1 -> 45 | N4: =O4-Q4 -> 10304 | O4: 10304
N5: =O5-Q5 -> 10988 | O5: 10988
B6: TENANT NAME | C6: =meter!B11 -> 0 | N6: =O6-Q6 -> 11070 | O6: 11070
N7: =O7-Q7 -> 1197 | O7: 1197
B8: HOUSE NUMBER: | C8: 2B | N8: =O8-Q8 -> 9250 | O8: 9250
N9: =O9-Q9 -> 8770 | O9: 8770
B10: ISSUE DATE | C10: ='1A'!C9 -> 30TH JAN 2026 | N10: =O10-Q10 -> 23190 | O10: 23190
N11: =O11-Q11 -> 10910 | O11: 10910
B12: LAST PAY DATE | C12: ='1A'!C11 -> 5TH FEB 2026 | N12: =O12-Q12 -> 10910 | O12: 10910
N13: =O13-Q13 -> 12190 | O13: 12190
N14: =O14-Q14 -> 11070 | O14: 11070
B15: PREVIOUS READING | C15: CURRENT READING | E15: CONSUMPTION | N15: =O15-Q15 -> 9090 | O15: 9090
B16: =meter!E11 -> 13 | C16: =meter!F11 -> 15 | D16: Units | E16: =C16-B16 -> 2 | N16: =O16-Q16 -> 9420 | O16: 9420
E17: Amount (Kshs.) | N17: =O17-Q17 -> 11154 | O17: 11154
C18: LAST ACCOUNT | D18: kshs. | E18: =meter!O11 -> 0 | N18: =O18-Q18 -> 10430 | O18: 10430
N19: =O19-Q19 -> 11831 | O19: 11831
C20: MONTH BILL | D20: KSHS. | E20: =meter!I11 -> 300 | N20: =O20-Q20 -> 10590 | O20: 10590
N21: =O21-Q21 -> 22423 | O21: 22423
C22: PUMP/POWER CHARGES | D22: KSHS. | E22: ='1A'!E21 -> 0 | N22: =O22-Q22 -> 9250 | O22: 9250
N23: =O23-Q23 -> 10162 | O23: 10162
C24: MONTH HOUSE RENT | D24: KSHS. | E24: =meter!N11 -> 7000 | N24: =O24-Q24 -> 10270 | O24: 10270
N25: =O25-Q25 -> 11070 | O25: 11070
C26: ='1A'!C25 -> SECURITY | D26: ='1A'!D25 -> Kshs. | E26: ='1A'!E25 -> 0 | N26: =O26-Q26 -> 11550 | O26: 11550
C27: GARBAGE FEE | D27: Kshs. | N27: =O27-Q27 -> 11393 | O27: 11393
C28: ADJUSTMENT-interest on arrears | D28: KSHS. | E28: =IF(E18*6%*3<0,0,E18*6%*3) -> 0 | N28: =O28-Q28 -> 10802 | O28: 10802
N29: =O29-Q29 -> 8930 | O29: 8930
C30: TOTAL PAYABLE | D30: Kshs. | E30: =SUM(E17:E29) -> 7300 | N30: =O30-Q30 -> 9570 | O30: 9570
N31: =O31-Q31 -> 11390 | O31: 11390
C32: PAID | E32: =meter!T11 -> 0 | N32: =O32-Q32 -> 10750 | O32: 10750
N33: =O33-Q33 -> 11732 | O33: 11732
C34: AMOUNT DUE | E34: =E30-E32 -> 7300 | N34: =O34-Q34 -> 10934 | O34: 10934 | R34: 700
N35: =O35-Q35 -> 10270 | O35: 10270
C36: PAY BILL 4139271 ACC NO UM 2B | N36: =O36-Q36 -> 10598 | O36: 10598
N37: =O37-Q37 -> 8770 | O37: 8770
N38: =O38-Q38 -> 8770 | O38: 8770
O39: =SUM(O3:O38) -> 391268 | Q39: =SUM(Q3:Q38) -> 0

Sheet 3B
B2: OLE SAMEDHA PREMIER HOSTELS | N2: VAR | O2: TAX DUE
B3: ='1A'!B2 -> P.O BOX 9473-00200 NAIROBI | N3: =O3-Q3 -> 10270 | O3: 10270
B4: WATER BILL | G4: BILL NO. | H4: ='1A'!H3+9-1 -> 46 | N4: =O4-Q4 -> 10304 | O4: 10304
N5: =O5-Q5 -> 10988 | O5: 10988
B6: TENANT NAME | C6: =meter!B12 -> NEW | N6: =O6-Q6 -> 11070 | O6: 11070
N7: =O7-Q7 -> 1197 | O7: 1197
B8: HOUSE NUMBER: | C8: 3B | N8: =O8-Q8 -> 9250 | O8: 9250
N9: =O9-Q9 -> 8770 | O9: 8770
B10: ISSUE DATE | C10: ='1A'!C9 -> 30TH JAN 2026 | N10: =O10-Q10 -> 23190 | O10: 23190
N11: =O11-Q11 -> 10910 | O11: 10910
B12: LAST PAY DATE | C12: ='1A'!C11 -> 5TH FEB 2026 | N12: =O12-Q12 -> 10910 | O12: 10910
N13: =O13-Q13 -> 12190 | O13: 12190
N14: =O14-Q14 -> 11070 | O14: 11070
B15: PREVIOUS READING | C15: CURRENT READING | E15: CONSUMPTION | N15: =O15-Q15 -> 9090 | O15: 9090
B16: =meter!E12 -> 10 | C16: =meter!F12 -> 15 | D16: Units | E16: =C16-B16 -> 5 | N16: =O16-Q16 -> 9420 | O16: 9420
E17: Amount (Kshs.) | N17: =O17-Q17 -> 11154 | O17: 11154
C18: LAST ACCOUNT | D18: kshs. | E18: =meter!O12 -> 0 | N18: =O18-Q18 -> 10430 | O18: 10430
N19: =O19-Q19 -> 11831 | O19: 11831
C20: MONTH BILL | D20: KSHS. | E20: =meter!I12 -> 750 | N20: =O20-Q20 -> 10590 | O20: 10590
N21: =O21-Q21 -> 22423 | O21: 22423
C22: PUMP/POWER CHARGES | D22: KSHS. | E22: ='1A'!E21 -> 0 | N22: =O22-Q22 -> 9250 | O22: 9250
N23: =O23-Q23 -> 10162 | O23: 10162
C24: MONTH HOUSE RENT | D24: KSHS. | E24: =meter!N12 -> 7000 | N24: =O24-Q24 -> 10270 | O24: 10270
N25: =O25-Q25 -> 11070 | O25: 11070
C26: ='1A'!C25 -> SECURITY | D26: ='1A'!D25 -> Kshs. | E26: ='1A'!E25 -> 0 | N26: =O26-Q26 -> 11550 | O26: 11550
C27: GARBAGE FEE | D27: Kshs. | N27: =O27-Q27 -> 11393 | O27: 11393
C28: Penalty & Interest late payment | D28: KSHS. | E28: =IF(E18*4%*1<0,0,E18*4%*1) -> 0 | N28: =O28-Q28 -> 10802 | O28: 10802
N29: =O29-Q29 -> 8930 | O29: 8930
C30: TOTAL PAYABLE | D30: Kshs. | E30: =SUM(E17:E29) -> 7750 | N30: =O30-Q30 -> 9570 | O30: 9570
N31: =O31-Q31 -> 11390 | O31: 11390
C32: PAID | E32: =meter!T12 -> 0 | N32: =O32-Q32 -> 10750 | O32: 10750
N33: =O33-Q33 -> 11732 | O33: 11732
C34: AMOUNT DUE | E34: =E30-E32 -> 7750 | N34: =O34-Q34 -> 10934 | O34: 10934 | R34: 700
B35: NOTE | N35: =O35-Q35 -> 10270 | O35: 10270
N36: =O36-Q36 -> 10598 | O36: 10598
C37: PAY BILL 4139271 ACC NO UM 3B | N37: =O37-Q37 -> 8770 | O37: 8770
N38: =O38-Q38 -> 8770 | O38: 8770
O39: =SUM(O3:O38) -> 391268 | Q39: =SUM(Q3:Q38) -> 0

Sheet 4B
B2: OLE SAMEDHA PREMIER HOSTELS | N2: VAR | O2: TAX DUE
B3: ='1A'!B2 -> P.O BOX 9473-00200 NAIROBI | N3: =O3-Q3 -> 10270 | O3: 10270
B4: WATER BILL | G4: BILL NO. | H4: ='1A'!H3+10-1 -> 47 | N4: =O4-Q4 -> 10304 | O4: 10304
N5: =O5-Q5 -> 10988 | O5: 10988
B6: TENANT NAME | C6: =meter!B13 -> 0 | N6: =O6-Q6 -> 11070 | O6: 11070
N7: =O7-Q7 -> 1197 | O7: 1197
B8: HOUSE NUMBER: | C8: 4B | N8: =O8-Q8 -> 9250 | O8: 9250
N9: =O9-Q9 -> 8770 | O9: 8770
B10: ISSUE DATE | C10: ='1A'!C9 -> 30TH JAN 2026 | N10: =O10-Q10 -> 23190 | O10: 23190
N11: =O11-Q11 -> 10910 | O11: 10910
B12: LAST PAY DATE | C12: ='1A'!C11 -> 5TH FEB 2026 | N12: =O12-Q12 -> 10910 | O12: 10910
N13: =O13-Q13 -> 12190 | O13: 12190
N14: =O14-Q14 -> 11070 | O14: 11070
B15: PREVIOUS READING | C15: CURRENT READING | E15: CONSUMPTION | N15: =O15-Q15 -> 9090 | O15: 9090
B16: =meter!E13 -> 16 | C16: =meter!F13 -> 17 | D16: Units | E16: =C16-B16 -> 1 | N16: =O16-Q16 -> 9420 | O16: 9420
E17: Amount (Kshs) | N17: =O17-Q17 -> 11154 | O17: 11154
C18: LAST ACCOUNT | D18: kshs. | E18: =meter!O13 -> 0 | N18: =O18-Q18 -> 10430 | O18: 10430
N19: =O19-Q19 -> 11831 | O19: 11831
C20: MONTH BILL | D20: KSHS. | E20: =meter!I13 -> 150 | N20: =O20-Q20 -> 10590 | O20: 10590
N21: =O21-Q21 -> 22423 | O21: 22423
C22: PUMP/POWER CHARGES | D22: KSHS. | E22: ='1A'!E21 -> 0 | N22: =O22-Q22 -> 9250 | O22: 9250
N23: =O23-Q23 -> 10162 | O23: 10162
C24: MONTH HOUSE RENT | D24: KSHS. | E24: =meter!N13 -> 7000 | N24: =O24-Q24 -> 10270 | O24: 10270
N25: =O25-Q25 -> 11070 | O25: 11070
C26: ='1A'!C25 -> SECURITY | D26: KSHS. | E26: =meter!M13 -> 0 | N26: =O26-Q26 -> 11550 | O26: 11550
C27: GARBAGE FEE | D27: KSHS. | N27: =O27-Q27 -> 11393 | O27: 11393
C28: INTEREST ON LATE PAYMENT | D28: KSHS. | E28: =IF(E18*4%*1<0,0,E18*4%*1) -> 0 | N28: =O28-Q28 -> 10802 | O28: 10802
N29: =O29-Q29 -> 8930 | O29: 8930
C30: TOTAL PAYABLE | D30: Kshs. | E30: =SUM(E17:E29) -> 7150 | N30: =O30-Q30 -> 9570 | O30: 9570
N31: =O31-Q31 -> 11390 | O31: 11390
C32: PAID | E32: =meter!T13 -> 0 | N32: =O32-Q32 -> 10750 | O32: 10750
N33: =O33-Q33 -> 11732 | O33: 11732
C34: AMOUNT DUE | E34: =E30-E32 -> 7150 | N34: =O34-Q34 -> 10934 | O34: 10934 | R34: 700
B35: NOTE | N35: =O35-Q35 -> 10270 | O35: 10270
C36: PAY BILL 4139271 ACC NO UM 4B | N36: =O36-Q36 -> 10598 | O36: 10598
N37: =O37-Q37 -> 8770 | O37: 8770
N38: =O38-Q38 -> 8770 | O38: 8770
O39: =SUM(O3:O38) -> 391268 | Q39: =SUM(Q3:Q38) -> 0

Sheet 5B
B2: OLE SAMEDHA PREMIER HOSTELS | N2: VAR | O2: TAX DUE
B3: ='1A'!B2 -> P.O BOX 9473-00200 NAIROBI | N3: =O3-Q3 -> 10270 | O3: 10270
B4: WATER BILL | G4: BILL NO. | H4: ='1A'!H3+11-1 -> 48 | N4: =O4-Q4 -> 10304 | O4: 10304
N5: =O5-Q5 -> 10988 | O5: 10988
B6: TENANT NAME | C6: =meter!B14 -> 0 | N6: =O6-Q6 -> 11070 | O6: 11070
N7: =O7-Q7 -> 1197 | O7: 1197
B8: HOUSE NUMBER: | C8: 5B | N8: =O8-Q8 -> 9250 | O8: 9250
N9: =O9-Q9 -> 8770 | O9: 8770
B10: ISSUE DATE | C10: ='1A'!C9 -> 30TH JAN 2026 | N10: =O10-Q10 -> 23190 | O10: 23190
N11: =O11-Q11 -> 10910 | O11: 10910
B12: LAST PAY DATE | C12: ='1A'!C11 -> 5TH FEB 2026 | N12: =O12-Q12 -> 10910 | O12: 10910
N13: =O13-Q13 -> 12190 | O13: 12190
N14: =O14-Q14 -> 11070 | O14: 11070
B15: PREVIOUS READING | C15: CURRENT READING | E15: CONSUMPTION | N15: =O15-Q15 -> 9090 | O15: 9090
B16: =meter!E14 -> 1 | C16: =meter!F14 -> 1 | D16: Units | E16: =C16-B16 -> 0 | N16: =O16-Q16 -> 9420 | O16: 9420
E17: Amount (Kshs.) | N17: =O17-Q17 -> 11154 | O17: 11154
C18: LAST ACCOUNT | D18: kshs. | E18: =meter!O14 -> 451 | N18: =O18-Q18 -> 10430 | O18: 10430
N19: =O19-Q19 -> 11831 | O19: 11831
C20: MONTH BILL | D20: KSHS. | E20: =meter!I14 -> 0 | N20: =O20-Q20 -> 10590 | O20: 10590
N21: =O21-Q21 -> 22423 | O21: 22423
C22: PUMP/POWER CHARGES | D22: KSHS. | E22: ='1A'!E21 -> 0 | N22: =O22-Q22 -> 9250 | O22: 9250
N23: =O23-Q23 -> 10162 | O23: 10162
C24: MONTH HOUSE RENT | D24: KSHS. | E24: =meter!N14 -> 7000 | N24: =O24-Q24 -> 10270 | O24: 10270
N25: =O25-Q25 -> 11070 | O25: 11070
C26: ='1A'!C25 -> SECURITY | D26: KSHS. | E26: ='1A'!E25 -> 0 | N26: =O26-Q26 -> 11550 | O26: 11550
C27: GARBAGE FEE | D27: KSHS. | N27: =O27-Q27 -> 11393 | O27: 11393
C28: INTEREST ON LATE PAYMENT | D28: KSHS. | E28: =IF(E18*4%*1<0,0,E18*4%*1) -> 18.04 | N28: =O28-Q28 -> 10802 | O28: 10802
N29: =O29-Q29 -> 8930 | O29: 8930
C30: TOTAL PAYABLE | D30: Kshs. | E30: =SUM(E17:E29) -> 7469.04 | N30: =O30-Q30 -> 9570 | O30: 9570
N31: =O31-Q31 -> 11390 | O31: 11390
C32: PAID | E32: =meter!T14 -> 0 | N32: =O32-Q32 -> 10750 | O32: 10750
N33: =O33-Q33 -> 11732 | O33: 11732
C34: AMOUNT DUE | E34: =E30-E32 -> 7469.04 | N34: =O34-Q34 -> 10934 | O34: 10934 | R34: 700
N35: =O35-Q35 -> 10270 | O35: 10270
C36: PAYBILL 4139271 ACC NO UM 5B | N36: =O36-Q36 -> 10598 | O36: 10598
N37: =O37-Q37 -> 8770 | O37: 8770
N38: =O38-Q38 -> 8770 | O38: 8770
O39: =SUM(O3:O38) -> 391268 | Q39: =SUM(Q3:Q38) -> 0

Sheet 6B
B2: OLE SAMEDHA PREMIER HOSTELS | N2: VAR | O2: TAX DUE
B3: ='1A'!B2 -> P.O BOX 9473-00200 NAIROBI | N3: =O3-Q3 -> 10270 | O3: 10270
B4: WATER BILL | H4: BILL NO. | I4: ='1A'!H3+12-1 -> 49 | J4: ='1A'!H3+12-1 -> 49 | N4: =O4-Q4 -> 10304 | O4: 10304
N5: =O5-Q5 -> 10988 | O5: 10988
B6: TENANT NAME | D6: =meter!B15 -> MUNIRA | N6: =O6-Q6 -> 11070 | O6: 11070
N7: =O7-Q7 -> 1197 | O7: 1197
B8: HOUSE NUMBER: | D8: 6B | N8: =O8-Q8 -> 9250 | O8: 9250
N9: =O9-Q9 -> 8770 | O9: 8770
B10: ISSUE DATE | D10: ='1A'!C9 -> 30TH JAN 2026 | N10: =O10-Q10 -> 23190 | O10: 23190
N11: =O11-Q11 -> 10910 | O11: 10910
B12: LAST PAY DATE | D12: ='1A'!C11 -> 5TH FEB 2026 | N12: =O12-Q12 -> 10910 | O12: 10910
N13: =O13-Q13 -> 12190 | O13: 12190
N14: =O14-Q14 -> 11070 | O14: 11070
B15: PREVIOUS READING | D15: CURRENT READING | F15: CONSUMPTION | N15: =O15-Q15 -> 9090 | O15: 9090
B16: =meter!E15 -> 23 | D16: =meter!F15 -> 27 | E16: Units | F16: =D16-B16 -> 4 | N16: =O16-Q16 -> 9420 | O16: 9420
F17: Amount (Kshs.) | N17: =O17-Q17 -> 11154 | O17: 11154
D18: LAST ACCOUNT | E18: kshs. | F18: =meter!O15 -> 0 | N18: =O18-Q18 -> 10430 | O18: 10430
N19: =O19-Q19 -> 11831 | O19: 11831
D20: MONTH BILL | E20: KSHS. | F20: =meter!I15 -> 600 | N20: =O20-Q20 -> 10590 | O20: 10590
N21: =O21-Q21 -> 22423 | O21: 22423
D22: PUMP/POWER CHARGES | E22: KSHS. | F22: ='1A'!E21 -> 0 | N22: =O22-Q22 -> 9250 | O22: 9250
N23: =O23-Q23 -> 10162 | O23: 10162
D24: MONTH HOUSE RENT | E24: KSHS. | F24: =meter!N15 -> 8000 | N24: =O24-Q24 -> 10270 | O24: 10270
N25: =O25-Q25 -> 11070 | O25: 11070
D26: SECURITY | E26: KSHS. | F26: =meter!M15 -> 0 | N26: =O26-Q26 -> 11550 | O26: 11550
D27: GARBAGE FEE | N27: =O27-Q27 -> 11393 | O27: 11393
D28: INTEREST ON LATE PAYMENT | E28: KSHS. | F28: =IF(F18*4%*1<0,0,F18*4%*1) -> 0 | N28: =O28-Q28 -> 10802 | O28: 10802
N29: =O29-Q29 -> 8930 | O29: 8930
C30: TOTAL PAYABLE | D30: TOTAL PAYABLE | E30: Kshs. | F30: =SUM(F17:F29) -> 8600 | N30: =O30-Q30 -> 9570 | O30: 9570
N31: =O31-Q31 -> 11390 | O31: 11390
C32: PAID | D32: PAID | F32: =meter!T15 -> 0 | N32: =O32-Q32 -> 10750 | O32: 10750
N33: =O33-Q33 -> 11732 | O33: 11732
C34: BALANCE C/F | D34: AMOUNT DUE | F34: =F30-F32 -> 8600 | N34: =O34-Q34 -> 10934 | O34: 10934 | R34: 700
B35: NOTE | N35: =O35-Q35 -> 10270 | O35: 10270
D36: PAY BILL 4139271 ACC NO UM 6B | N36: =O36-Q36 -> 10598 | O36: 10598
N37: =O37-Q37 -> 8770 | O37: 8770
N38: =O38-Q38 -> 8770 | O38: 8770
O39: =SUM(O3:O38) -> 391268 | Q39: =SUM(Q3:Q38) -> 0

Sheet 1C
B2: OLE SAMEDHA PREMIER HOSTELS | N2: VAR | O2: TAX DUE
B3: ='1A'!B2 -> P.O BOX 9473-00200 NAIROBI | N3: =O3-Q3 -> 10270 | O3: 10270
B4: WATER BILL | G4: BILL NO. | H4: ='1A'!H3+13-1 -> 50 | N4: =O4-Q4 -> 10304 | O4: 10304
N5: =O5-Q5 -> 10988 | O5: 10988
B6: TENANT NAME | D6: =meter!B16 -> RIDHWAN | N6: =O6-Q6 -> 11070 | O6: 11070
N7: =O7-Q7 -> 1197 | O7: 1197
B8: HOUSE NUMBER: | D8: 1C | N8: =O8-Q8 -> 9250 | O8: 9250
N9: =O9-Q9 -> 8770 | O9: 8770
B10: ISSUE DATE | D10: ='1A'!C9 -> 30TH JAN 2026 | N10: =O10-Q10 -> 23190 | O10: 23190
N11: =O11-Q11 -> 10910 | O11: 10910
B12: LAST PAY DATE | D12: ='1A'!C11 -> 5TH FEB 2026 | N12: =O12-Q12 -> 10910 | O12: 10910
N13: =O13-Q13 -> 12190 | O13: 12190
N14: =O14-Q14 -> 11070 | O14: 11070
B15: PREVIOUS READING | D15: CURRENT READING | F15: CONSUMPTION | N15: =O15-Q15 -> 9090 | O15: 9090
B16: =meter!E16 -> 13 | D16: =meter!F16 -> 13 | E16: Units | F16: =D16-B16 -> 0 | N16: =O16-Q16 -> 9420 | O16: 9420
F17: Amount (Kshs.) | N17: =O17-Q17 -> 11154 | O17: 11154
D18: LAST ACCOUNT B/F | E18: kshs. | F18: =meter!O16 -> 0 | N18: =O18-Q18 -> 10430 | O18: 10430
N19: =O19-Q19 -> 11831 | O19: 11831
D20: MONTH BILL | E20: KSHS. | F20: =meter!I16 -> 0 | N20: =O20-Q20 -> 10590 | O20: 10590
N21: =O21-Q21 -> 22423 | O21: 22423
D22: PUMP/POWER CHARGES | E22: KSHS. | F22: ='1A'!E21 -> 0 | N22: =O22-Q22 -> 9250 | O22: 9250
N23: =O23-Q23 -> 10162 | O23: 10162
D24: MONTH HOUSE RENT | E24: KSHS. | F24: =meter!N16 -> 8000 | N24: =O24-Q24 -> 10270 | O24: 10270
N25: =O25-Q25 -> 11070 | O25: 11070
D26: SECURITY | E26: KSHS. | F26: =meter!M16 -> 0 | N26: =O26-Q26 -> 11550 | O26: 11550
D27: GARBAGE FEE | E27: KSHS. | N27: =O27-Q27 -> 11393 | O27: 11393
D28: INTEREST ON LATE PAYMENT | E28: KSHS. | F28: =IF(F18*4%*1<0,0,F18*4%*1) -> 0 | N28: =O28-Q28 -> 10802 | O28: 10802
N29: =O29-Q29 -> 8930 | O29: 8930
D30: TOTAL PAYABLE | E30: Kshs. | F30: =SUM(F17:F29) -> 8000 | N30: =O30-Q30 -> 9570 | O30: 9570
N31: =O31-Q31 -> 11390 | O31: 11390
D32: PAID | F32: =meter!T16 -> 0 | N32: =O32-Q32 -> 10750 | O32: 10750
N33: =O33-Q33 -> 11732 | O33: 11732
D34: AMOUNT DUE | F34: =F30-F32 -> 8000 | N34: =O34-Q34 -> 10934 | O34: 10934 | R34: 700
N35: =O35-Q35 -> 10270 | O35: 10270
D36: PAY BILL 4139271 ACC NO UM 1C | N36: =O36-Q36 -> 10598 | O36: 10598
N37: =O37-Q37 -> 8770 | O37: 8770
N38: =O38-Q38 -> 8770 | O38: 8770
O39: =SUM(O3:O38) -> 391268 | Q39: =SUM(Q3:Q38) -> 0

Sheet 2C
B2: OLE SAMEDHA APARTMENTS-Kitengela | D2: OLE SAMEDHA PREMIER HOSTELS | N2: VAR | O2: TAX DUE
B3: ='1A'!B2 -> P.O BOX 9473-00200 NAIROBI | N3: =O3-Q3 -> 10270 | O3: 10270
B4: WATER BILL | H4: BILL NO. | I4: ='1A'!H3+14-1 -> 51 | J4: ='1A'!H3+14-1 -> 51 | N4: =O4-Q4 -> 10304 | O4: 10304
N5: =O5-Q5 -> 10988 | O5: 10988
B6: TENANT NAME | D6: =meter!B17 -> 0 | N6: =O6-Q6 -> 11070 | O6: 11070
N7: =O7-Q7 -> 1197 | O7: 1197
B8: HOUSE NUMBER: | D8: 2C | N8: =O8-Q8 -> 9250 | O8: 9250
N9: =O9-Q9 -> 8770 | O9: 8770
B10: ISSUE DATE | D10: ='1A'!C9 -> 30TH JAN 2026 | N10: =O10-Q10 -> 23190 | O10: 23190
N11: =O11-Q11 -> 10910 | O11: 10910
B12: LAST PAY DATE | D12: ='1A'!C11 -> 5TH FEB 2026 | N12: =O12-Q12 -> 10910 | O12: 10910
N13: =O13-Q13 -> 12190 | O13: 12190
N14: =O14-Q14 -> 11070 | O14: 11070
B15: PREVIOUS READING | D15: CURRENT READING | F15: CONSUMPTION | N15: =O15-Q15 -> 9090 | O15: 9090
B16: =meter!E17 -> 45 | D16: =meter!F17 -> 45 | E16: Units | F16: =D16-B16 -> 0 | H16: ESTIMATE | N16: =O16-Q16 -> 9420 | O16: 9420
F17: Amount (Kshs.) | N17: =O17-Q17 -> 11154 | O17: 11154
D18: LAST ACCOUNT B/F | E18: kshs. | F18: =meter!O17 -> 516 | N18: =O18-Q18 -> 10430 | O18: 10430
N19: =O19-Q19 -> 11831 | O19: 11831
D20: MONTH BILL | E20: KSHS. | F20: =meter!I17 -> 0 | N20: =O20-Q20 -> 10590 | O20: 10590
N21: =O21-Q21 -> 22423 | O21: 22423
D22: PUMP/POWER CHARGES | E22: KSHS. | F22: ='1A'!E21 -> 0 | N22: =O22-Q22 -> 9250 | O22: 9250
N23: =O23-Q23 -> 10162 | O23: 10162
D24: MONTH HOUSE RENT | E24: KSHS. | F24: =meter!N17 -> 8000 | N24: =O24-Q24 -> 10270 | O24: 10270
N25: =O25-Q25 -> 11070 | O25: 11070
D26: ='1A'!C25 -> SECURITY | E26: ='1A'!D25 -> Kshs. | F26: ='1A'!E25 -> 0 | N26: =O26-Q26 -> 11550 | O26: 11550
D27: GARBAGE FEE | E27: Kshs. | N27: =O27-Q27 -> 11393 | O27: 11393
D28: ADJUSTMENT (Interest late payment) | E28: KSHS. | F28: =IF(F18*4%*1<0,0,F18*4%*1) -> 20.64 | N28: =O28-Q28 -> 10802 | O28: 10802
N29: =O29-Q29 -> 8930 | O29: 8930
D30: TOTAL PAYABLE | E30: Kshs. | F30: =SUM(F17:F29) -> 8536.64 | N30: =O30-Q30 -> 9570 | O30: 9570
N31: =O31-Q31 -> 11390 | O31: 11390
D32: PAID | F32: =meter!T17 -> 0 | N32: =O32-Q32 -> 10750 | O32: 10750
N33: =O33-Q33 -> 11732 | O33: 11732
D34: AMOUNT DUE | F34: =F30-F32 -> 8536.64 | N34: =O34-Q34 -> 10934 | O34: 10934 | R34: 700
C35: NOTE | N35: =O35-Q35 -> 10270 | O35: 10270
N36: =O36-Q36 -> 10598 | O36: 10598
D37: PAY BILL 4139271 ACC NO UM 2C | N37: =O37-Q37 -> 8770 | O37: 8770
N38: =O38-Q38 -> 8770 | O38: 8770
O39: =SUM(O3:O38) -> 391268 | Q39: =SUM(Q3:Q38) -> 0

Sheet 3C
B2: OLE SAMEDHA PREMIER HOSTELS | N2: VAR | O2: TAX DUE
B3: ='1A'!B2 -> P.O BOX 9473-00200 NAIROBI | N3: =O3-Q3 -> 10270 | O3: 10270
B4: WATER BILL | H4: BILL NO. | I4: ='1A'!H3+15-1 -> 52 | J4: ='1A'!H3+15-1 -> 52 | N4: =O4-Q4 -> 10304 | O4: 10304
N5: =O5-Q5 -> 10988 | O5: 10988
B6: TENANT NAME | D6: =meter!B18 -> AHMED | N6: =O6-Q6 -> 11070 | O6: 11070
N7: =O7-Q7 -> 1197 | O7: 1197
B8: HOUSE NUMBER: | D8: 3C | N8: =O8-Q8 -> 9250 | O8: 9250
N9: =O9-Q9 -> 8770 | O9: 8770
B10: ISSUE DATE | D10: ='1A'!C9 -> 30TH JAN 2026 | N10: =O10-Q10 -> 23190 | O10: 23190
N11: =O11-Q11 -> 10910 | O11: 10910
B12: LAST PAY DATE | D12: ='1A'!C11 -> 5TH FEB 2026 | N12: =O12-Q12 -> 10910 | O12: 10910
N13: =O13-Q13 -> 12190 | O13: 12190
N14: =O14-Q14 -> 11070 | O14: 11070
B15: PREVIOUS READING | D15: CURRENT READING | F15: CONSUMPTION | N15: =O15-Q15 -> 9090 | O15: 9090
B16: =meter!E18 -> 52 | D16: =meter!F18 -> 52 | E16: Units | F16: =D16-B16 -> 0 | N16: =O16-Q16 -> 9420 | O16: 9420
F17: Amount (Kshs) | N17: =O17-Q17 -> 11154 | O17: 11154
D18: LAST ACCOUNT B/F | E18: kshs. | F18: =meter!O18 -> 0 | N18: =O18-Q18 -> 10430 | O18: 10430
N19: =O19-Q19 -> 11831 | O19: 11831
D20: MONTH BILL | E20: KSHS. | F20: =meter!I18 -> 0 | N20: =O20-Q20 -> 10590 | O20: 10590
N21: =O21-Q21 -> 22423 | O21: 22423
D22: PUMP/POWER CHARGES | E22: KSHS. | F22: ='1A'!E21 -> 0 | N22: =O22-Q22 -> 9250 | O22: 9250
N23: =O23-Q23 -> 10162 | O23: 10162
D24: MONTH HOUSE RENT | E24: KSHS. | F24: =meter!N18 -> 10000 | N24: =O24-Q24 -> 10270 | O24: 10270
N25: =O25-Q25 -> 11070 | O25: 11070
D26: ='1A'!C25 -> SECURITY | E26: ='1A'!D25 -> Kshs. | F26: ='1A'!E25 -> 0 | N26: =O26-Q26 -> 11550 | O26: 11550
D27: GARBAGE FEE | E27: Kshs. | N27: =O27-Q27 -> 11393 | O27: 11393
D28: ADJUSTMENT (Interest late payment) | E28: KSHS. | F28: =IF(F18*4%*1<0,0,F18*4%*1) -> 0 | N28: =O28-Q28 -> 10802 | O28: 10802
N29: =O29-Q29 -> 8930 | O29: 8930
C30: TOTAL PAYABLE | D30: AMOUNT PAYABLE | E30: Kshs. | F30: =SUM(F17:F29) -> 10000 | N30: =O30-Q30 -> 9570 | O30: 9570
N31: =O31-Q31 -> 11390 | O31: 11390
C32: PAID | E32: KSHS | F32: =meter!T18 -> 0 | N32: =O32-Q32 -> 10750 | O32: 10750
N33: =O33-Q33 -> 11732 | O33: 11732
C34: BALANCE C/F | D34: AMOUNT DUE | E34: KSHS. | F34: =F30-F32 -> 10000 | N34: =O34-Q34 -> 10934 | O34: 10934 | R34: 700
B35: NOTE | N35: =O35-Q35 -> 10270 | O35: 10270
D36: PAY BILL 4139271 ACC NO UM 3C | N36: =O36-Q36 -> 10598 | O36: 10598
N37: =O37-Q37 -> 8770 | O37: 8770
N38: =O38-Q38 -> 8770 | O38: 8770
O39: =SUM(O3:O38) -> 391268 | Q39: =SUM(Q3:Q38) -> 0

Sheet 4C
B2: OLE SAMEDHA PREMIER HOSTELS | N2: VAR | O2: TAX DUE
B3: ='1A'!B2 -> P.O BOX 9473-00200 NAIROBI | N3: =O3-Q3 -> 10270 | O3: 10270
B4: WATER BILL | H4: BILL NO. | I4: ='1A'!H3+16-1 -> 53 | M4: ='1A'!H3+16-1 -> 53 | N4: =O4-Q4 -> 10304 | O4: 10304
N5: =O5-Q5 -> 10988 | O5: 10988
B6: TENANT NAME | D6: =meter!B19 -> ABASS | N6: =O6-Q6 -> 11070 | O6: 11070
N7: =O7-Q7 -> 1197 | O7: 1197
B8: HOUSE NUMBER: | D8: 4C | N8: =O8-Q8 -> 9250 | O8: 9250
N9: =O9-Q9 -> 8770 | O9: 8770
B10: ISSUE DATE | D10: ='1A'!C9 -> 30TH JAN 2026 | N10: =O10-Q10 -> 23190 | O10: 23190
N11: =O11-Q11 -> 10910 | O11: 10910
B12: LAST PAY DATE | D12: ='1A'!C11 -> 5TH FEB 2026 | N12: =O12-Q12 -> 10910 | O12: 10910
N13: =O13-Q13 -> 12190 | O13: 12190
N14: =O14-Q14 -> 11070 | O14: 11070
B15: PREVIOUS READING | D15: CURRENT READING | F15: CONSUMPTION | N15: =O15-Q15 -> 9090 | O15: 9090
B16: =meter!E19 -> 11 | D16: =meter!F19 -> 12 | E16: Units | F16: =D16-B16 -> 1 | N16: =O16-Q16 -> 9420 | O16: 9420
F17: Amount (Kshs.) | N17: =O17-Q17 -> 11154 | O17: 11154
D18: LAST ACCOUNT B/F | E18: kshs. | F18: =meter!O19 -> 516 | N18: =O18-Q18 -> 10430 | O18: 10430
N19: =O19-Q19 -> 11831 | O19: 11831
D20: MONTH BILL | E20: KSHS. | F20: =meter!I19 -> 150 | N20: =O20-Q20 -> 10590 | O20: 10590
N21: =O21-Q21 -> 22423 | O21: 22423
D22: PUMP/POWER CHARGES | E22: KSHS. | F22: ='1A'!E21 -> 0 | N22: =O22-Q22 -> 9250 | O22: 9250
N23: =O23-Q23 -> 10162 | O23: 10162
D24: MONTH HOUSE RENT | E24: KSHS. | F24: =meter!N19 -> 8000 | N24: =O24-Q24 -> 10270 | O24: 10270
N25: =O25-Q25 -> 11070 | O25: 11070
D26: ='1A'!C25 -> SECURITY | E26: ='1A'!D25 -> Kshs. | F26: ='1A'!E25 -> 0 | N26: =O26-Q26 -> 11550 | O26: 11550
D27: GARBAGE FEE | E27: Kshs. | N27: =O27-Q27 -> 11393 | O27: 11393
D28: ADJUSTMENT-INTEREST LATE PAYMENT | E28: KSHS. | F28: =IF(F18*4%*1<0,0,F18*4%*1) -> 20.64 | N28: =O28-Q28 -> 10802 | O28: 10802
N29: =O29-Q29 -> 8930 | O29: 8930
D30: TOTAL PAYABLE | E30: Kshs. | F30: =SUM(F17:F29) -> 8686.64 | N30: =O30-Q30 -> 9570 | O30: 9570
N31: =O31-Q31 -> 11390 | O31: 11390
D32: PAID | F32: =meter!T19 -> 0 | N32: =O32-Q32 -> 10750 | O32: 10750
N33: =O33-Q33 -> 11732 | O33: 11732
D34: AMOUNT DUE | F34: =F30-F32 -> 8686.64 | N34: =O34-Q34 -> 10934 | O34: 10934 | R34: 700
C35: NOTE | N35: =O35-Q35 -> 10270 | O35: 10270
D36: PAYBILL 4139271 ACC NO UM 4C | N36: =O36-Q36 -> 10598 | O36: 10598
N37: =O37-Q37 -> 8770 | O37: 8770
N38: =O38-Q38 -> 8770 | O38: 8770
O39: =SUM(O3:O38) -> 391268 | Q39: =SUM(Q3:Q38) -> 0

Sheet 5C
B2: OLE SAMEDHA APARTMENTS-Kitengela | D2: OLE SAMEDHA PREMIER HOSTELS | N2: VAR | O2: TAX DUE
B3: ='1A'!B2 -> P.O BOX 9473-00200 NAIROBI | N3: =O3-Q3 -> 10270 | O3: 10270
B4: WATER BILL | H4: BILL NO. | I4: ='1A'!H3+17-1 -> 54 | J4: ='1A'!H3+17-1 -> 54 | N4: =O4-Q4 -> 10304 | O4: 10304
N5: =O5-Q5 -> 10988 | O5: 10988
B6: TENANT NAME | D6: =meter!B20 -> 0 | N6: =O6-Q6 -> 11070 | O6: 11070
N7: =O7-Q7 -> 1197 | O7: 1197
B8: HOUSE NUMBER: | D8: 5C | N8: =O8-Q8 -> 9250 | O8: 9250
D9: 0775203183 | N9: =O9-Q9 -> 8770 | O9: 8770
B10: ISSUE DATE | D10: ='1A'!C9 -> 30TH JAN 2026 | N10: =O10-Q10 -> 23190 | O10: 23190
N11: =O11-Q11 -> 10910 | O11: 10910
B12: LAST PAY DATE | D12: ='1A'!C11 -> 5TH FEB 2026 | N12: =O12-Q12 -> 10910 | O12: 10910
N13: =O13-Q13 -> 12190 | O13: 12190
N14: =O14-Q14 -> 11070 | O14: 11070
B15: PREVIOUS READING | D15: CURRENT READING | F15: CONSUMPTION | N15: =O15-Q15 -> 9090 | O15: 9090
B16: =meter!E20 -> 12 | D16: =meter!F20 -> 12 | E16: Units | F16: =D16-B16 -> 0 | N16: =O16-Q16 -> 9420 | O16: 9420
F17: Amount (Kshs.) | N17: =O17-Q17 -> 11154 | O17: 11154
D18: LAST ACCOUNT B/F | E18: kshs. | F18: =meter!O20 -> 0 | N18: =O18-Q18 -> 10430 | O18: 10430
N19: =O19-Q19 -> 11831 | O19: 11831
D20: MONTH BILL | E20: KSHS. | F20: =meter!I20 -> 0 | N20: =O20-Q20 -> 10590 | O20: 10590
N21: =O21-Q21 -> 22423 | O21: 22423
D22: PUMP/POWER CHARGES | E22: KSHS. | F22: ='1A'!E21 -> 0 | N22: =O22-Q22 -> 9250 | O22: 9250
N23: =O23-Q23 -> 10162 | O23: 10162
D24: MONTH HOUSE RENT | E24: KSHS. | F24: =meter!N20 -> 8000 | N24: =O24-Q24 -> 10270 | O24: 10270
N25: =O25-Q25 -> 11070 | O25: 11070
D26: ='1A'!C25 -> SECURITY | E26: ='1A'!D25 -> Kshs. | F26: ='1A'!E25 -> 0 | N26: =O26-Q26 -> 11550 | O26: 11550
D27: GARBAGE FEE | E27: Kshs. | N27: =O27-Q27 -> 11393 | O27: 11393
D28: INTEREST LATE PAYMENT | E28: KSHS. | F28: =IF(F18*8%*1<0,0,F18*8%*1) -> 0 | N28: =O28-Q28 -> 10802 | O28: 10802
N29: =O29-Q29 -> 8930 | O29: 8930
D30: TOTAL PAYABLE | E30: Kshs. | F30: =SUM(F17:F29) -> 8000 | N30: =O30-Q30 -> 9570 | O30: 9570
N31: =O31-Q31 -> 11390 | O31: 11390
D32: PAID | F32: =meter!T20 -> 0 | N32: =O32-Q32 -> 10750 | O32: 10750
N33: =O33-Q33 -> 11732 | O33: 11732
D34: AMOUNT DUE | F34: =F30-F32 -> 8000 | N34: =O34-Q34 -> 10934 | O34: 10934 | R34: 700
C35: NOTE | N35: =O35-Q35 -> 10270 | O35: 10270
N36: =O36-Q36 -> 10598 | O36: 10598
D37: PAY BILL 4139271 ACC NO UM 5C | N37: =O37-Q37 -> 8770 | O37: 8770
N38: =O38-Q38 -> 8770 | O38: 8770
O39: =SUM(O3:O38) -> 391268 | Q39: =SUM(Q3:Q38) -> 0

Sheet 6C
B2: OLE SAMEDHA PREMIER HOSTELS | N2: VAR | O2: TAX DUE
B3: ='1A'!B2 -> P.O BOX 9473-00200 NAIROBI | N3: =O3-Q3 -> 10270 | O3: 10270
B4: WATER BILL | H4: BILL NO. | I4: ='1A'!H3+18-1 -> 55 | K4: ='1A'!H3+18-1 -> 55 | N4: =O4-Q4 -> 10304 | O4: 10304
N5: =O5-Q5 -> 10988 | O5: 10988
B6: TENANT NAME | D6: =meter!B21 -> KHADIJA | N6: =O6-Q6 -> 11070 | O6: 11070
N7: =O7-Q7 -> 1197 | O7: 1197
B8: HOUSE NUMBER | D8: 6C | N8: =O8-Q8 -> 9250 | O8: 9250
N9: =O9-Q9 -> 8770 | O9: 8770
B10: ISSUE DATE | D10: ='1A'!C9 -> 30TH JAN 2026 | N10: =O10-Q10 -> 23190 | O10: 23190
N11: =O11-Q11 -> 10910 | O11: 10910
B12: LAST PAY DATE | D12: ='1A'!C11 -> 5TH FEB 2026 | N12: =O12-Q12 -> 10910 | O12: 10910
N13: =O13-Q13 -> 12190 | O13: 12190
N14: =O14-Q14 -> 11070 | O14: 11070
B15: PREVIOUS READING | D15: CURRENT READING | F15: CONSUMPTION | N15: =O15-Q15 -> 9090 | O15: 9090
B16: =meter!E21 -> 17 | D16: =meter!F21 -> 20 | E16: Units | F16: =D16-B16 -> 3 | N16: =O16-Q16 -> 9420 | O16: 9420
F17: Amount (Kshs.) | N17: =O17-Q17 -> 11154 | O17: 11154
D18: LAST ACCOUNT B/F | E18: Kshs. | F18: =meter!O21 -> 0 | N18: =O18-Q18 -> 10430 | O18: 10430
N19: =O19-Q19 -> 11831 | O19: 11831
D20: MONTH BILL | E20: KSHS. | F20: =meter!I21 -> 450 | N20: =O20-Q20 -> 10590 | O20: 10590
N21: =O21-Q21 -> 22423 | O21: 22423
D22: PUMP/POWER CHARGES | E22: KSHS. | F22: ='1A'!E21 -> 0 | N22: =O22-Q22 -> 9250 | O22: 9250
N23: =O23-Q23 -> 10162 | O23: 10162
D24: MONTH HOUSE RENT | E24: KSHS. | F24: =meter!N21 -> 10000 | N24: =O24-Q24 -> 10270 | O24: 10270
N25: =O25-Q25 -> 11070 | O25: 11070
D26: ='1A'!C25 -> SECURITY | E26: ='1A'!D25 -> Kshs. | F26: 0 | N26: =O26-Q26 -> 11550 | O26: 11550
D27: GARBAGE FEE | E27: Kshs. | N27: =O27-Q27 -> 11393 | O27: 11393
D28: ADJUSTMENT (Interest late payment) | E28: KSHS. | F28: =IF(F18*4%*1<0,0,F18*4%*1) -> 0 | N28: =O28-Q28 -> 10802 | O28: 10802
N29: =O29-Q29 -> 8930 | O29: 8930
D30: TOTAL PAYABLE | E30: Kshs. | F30: =SUM(F17:F29) -> 10450 | N30: =O30-Q30 -> 9570 | O30: 9570
N31: =O31-Q31 -> 11390 | O31: 11390
D32: PAID | F32: =meter!T21 -> 0 | N32: =O32-Q32 -> 10750 | O32: 10750
N33: =O33-Q33 -> 11732 | O33: 11732
D34: AMOUNT DUE | F34: =F30-F32 -> 10450 | N34: =O34-Q34 -> 10934 | O34: 10934 | R34: 700
C35: NOTE | N35: =O35-Q35 -> 10270 | O35: 10270
D36: PAY BILL 4139271 ACC NO UM 6C | N36: =O36-Q36 -> 10598 | O36: 10598
N37: =O37-Q37 -> 8770 | O37: 8770
N38: =O38-Q38 -> 8770 | O38: 8770
O39: =SUM(O3:O38) -> 391268 | Q39: =SUM(Q3:Q38) -> 0

Sheet 1D
B2: OLE SAMEDHA PREMIER HOSTELS | N2: VAR | O2: TAX DUE
B3: ='1A'!B2 -> P.O BOX 9473-00200 NAIROBI | N3: =O3-Q3 -> 10270 | O3: 10270
B4: WATER BILL | G4: BILL NO. | H4: ='1A'!H3+19-1 -> 56 | I4: ='1A'!H3+19-1 -> 56 | N4: =O4-Q4 -> 10304 | O4: 10304
G5: ='1A'!H3+19-1 -> 56 | N5: =O5-Q5 -> 10988 | O5: 10988
B6: TENANT NAME | D6: =meter!B22 -> AIRHA | N6: =O6-Q6 -> 11070 | O6: 11070
N7: =O7-Q7 -> 1197 | O7: 1197
B8: HOUSE NUMBER: | D8: 1D | N8: =O8-Q8 -> 9250 | O8: 9250
N9: =O9-Q9 -> 8770 | O9: 8770
B10: ISSUE DATE | D10: ='1A'!C9 -> 30TH JAN 2026 | N10: =O10-Q10 -> 23190 | O10: 23190
N11: =O11-Q11 -> 10910 | O11: 10910
B12: LAST PAY DATE | D12: ='1A'!C11 -> 5TH FEB 2026 | N12: =O12-Q12 -> 10910 | O12: 10910
N13: =O13-Q13 -> 12190 | O13: 12190
N14: =O14-Q14 -> 11070 | O14: 11070
B15: PREVIOUS READING | D15: CURRENT READING | F15: CONSUMPTION | N15: =O15-Q15 -> 9090 | O15: 9090
B16: =meter!E22 -> 12 | D16: =meter!F22 -> 15 | E16: Units | F16: =D16-B16+I16 -> 3 | N16: =O16-Q16 -> 9420 | O16: 9420
F17: Amount (Kshs.) | N17: =O17-Q17 -> 11154 | O17: 11154
D18: LAST ACCOUNT B/F | E18: Kshs. | F18: =meter!O22 -> 0 | N18: =O18-Q18 -> 10430 | O18: 10430
N19: =O19-Q19 -> 11831 | O19: 11831
D20: MONTH BILL | E20: KSHS. | F20: =meter!I22 -> 450 | N20: =O20-Q20 -> 10590 | O20: 10590
N21: =O21-Q21 -> 22423 | O21: 22423
D22: PUMP/POWER CHARGES | E22: KSHS. | F22: ='1A'!E21 -> 0 | N22: =O22-Q22 -> 9250 | O22: 9250
N23: =O23-Q23 -> 10162 | O23: 10162
D24: MONTH HOUSE RENT | E24: KSHS. | F24: =meter!N22 -> 8000 | N24: =O24-Q24 -> 10270 | O24: 10270
N25: =O25-Q25 -> 11070 | O25: 11070
D26: ='1A'!C25 -> SECURITY | E26: ='1A'!D25 -> Kshs. | F26: 0 | N26: =O26-Q26 -> 11550 | O26: 11550
D27: GARBAGE FEE | E27: Kshs. | N27: =O27-Q27 -> 11393 | O27: 11393
D28: ADJUSTMENT-Interest on arrears | E28: KSHS. | F28: =IF(F18*8%*1<0,0,F18*8%*1) -> 0 | N28: =O28-Q28 -> 10802 | O28: 10802
N29: =O29-Q29 -> 8930 | O29: 8930
D30: TOTAL PAYABLE | E30: Kshs. | F30: =SUM(F17:F29) -> 8450 | N30: =O30-Q30 -> 9570 | O30: 9570
N31: =O31-Q31 -> 11390 | O31: 11390
D32: PAID | F32: =meter!T22 -> 0 | N32: =O32-Q32 -> 10750 | O32: 10750
N33: =O33-Q33 -> 11732 | O33: 11732
D34: AMOUNT DUE | F34: =F30-F32 -> 8450 | N34: =O34-Q34 -> 10934 | O34: 10934 | R34: 700
C35: NOTE | N35: =O35-Q35 -> 10270 | O35: 10270
D36: PAY BILL 4139271 ACC NO UM 1D | N36: =O36-Q36 -> 10598 | O36: 10598
N37: =O37-Q37 -> 8770 | O37: 8770
N38: =O38-Q38 -> 8770 | O38: 8770
O39: =SUM(O3:O38) -> 391268 | Q39: =SUM(Q3:Q38) -> 0
R58: A

Sheet 2D
B2: OLE SAMEDHA PREMIER HOSTELS | N2: VAR | O2: TAX DUE
B3: ='1A'!B2 -> P.O BOX 9473-00200 NAIROBI | N3: =O3-Q3 -> 10270 | O3: 10270
B4: WATER BILL | H4: BILL NO. | I4: ='1A'!H3+20-1 -> 57 | J4: ='1A'!H3+20-1 -> 57 | N4: =O4-Q4 -> 10304 | O4: 10304
N5: =O5-Q5 -> 10988 | O5: 10988
B6: TENANT NAME | D6: =meter!B23 -> MOHAMMED | N6: =O6-Q6 -> 11070 | O6: 11070
N7: =O7-Q7 -> 1197 | O7: 1197
B8: HOUSE NUMBER: | D8: 2D | N8: =O8-Q8 -> 9250 | O8: 9250
N9: =O9-Q9 -> 8770 | O9: 8770
B10: ISSUE DATE | D10: ='1A'!C9 -> 30TH JAN 2026 | N10: =O10-Q10 -> 23190 | O10: 23190
N11: =O11-Q11 -> 10910 | O11: 10910
B12: LAST PAY DATE | D12: ='1A'!C11 -> 5TH FEB 2026 | N12: =O12-Q12 -> 10910 | O12: 10910
N13: =O13-Q13 -> 12190 | O13: 12190
N14: =O14-Q14 -> 11070 | O14: 11070
B15: PREVIOUS READING | D15: CURRENT READING | F15: CONSUMPTION | N15: =O15-Q15 -> 9090 | O15: 9090
B16: =meter!E23 -> 21 | D16: =meter!F23 -> 28 | E16: Units | F16: =D16-B16 -> 7 | N16: =O16-Q16 -> 9420 | O16: 9420
F17: Amount (Kshs.) | N17: =O17-Q17 -> 11154 | O17: 11154
D18: LAST ACCOUNT B/F | E18: Kshs. | F18: =meter!O23 -> 0 | N18: =O18-Q18 -> 10430 | O18: 10430
N19: =O19-Q19 -> 11831 | O19: 11831
D20: MONTH BILL | E20: KSHS. | F20: =meter!I23 -> 1050 | N20: =O20-Q20 -> 10590 | O20: 10590
N21: =O21-Q21 -> 22423 | O21: 22423
D22: PUMP/POWER CHARGES | E22: KSHS. | F22: ='1A'!E21 -> 0 | N22: =O22-Q22 -> 9250 | O22: 9250
N23: =O23-Q23 -> 10162 | O23: 10162
D24: MONTH HOUSE RENT | E24: KSHS. | F24: =meter!N23 -> 8000 | N24: =O24-Q24 -> 10270 | O24: 10270
N25: =O25-Q25 -> 11070 | O25: 11070
D26: ='1A'!C25 -> SECURITY | E26: ='1A'!D25 -> Kshs. | F26: ='1A'!E25 -> 0 | N26: =O26-Q26 -> 11550 | O26: 11550
D27: GARBAGE FEE | E27: Kshs. | N27: =O27-Q27 -> 11393 | O27: 11393
D28: ADJUSTMENT-interest on arrears | E28: KSHS. | F28: =IF(F18*4%*1<0,0,F18*4%*1) -> 0 | N28: =O28-Q28 -> 10802 | O28: 10802
N29: =O29-Q29 -> 8930 | O29: 8930
D30: TOTAL PAYABLE | E30: Kshs. | F30: =SUM(F17:F29) -> 9050 | N30: =O30-Q30 -> 9570 | O30: 9570
N31: =O31-Q31 -> 11390 | O31: 11390
D32: PAID | F32: =meter!T23 -> 0 | N32: =O32-Q32 -> 10750 | O32: 10750
N33: =O33-Q33 -> 11732 | O33: 11732
D34: AMOUNT DUE | F34: =F30-F32 -> 9050 | N34: =O34-Q34 -> 10934 | O34: 10934 | R34: 700
C35: NOTE | N35: =O35-Q35 -> 10270 | O35: 10270
N36: =O36-Q36 -> 10598 | O36: 10598
D37: PAY BILL 4139271 ACC NO UM 2D | N37: =O37-Q37 -> 8770 | O37: 8770
N38: =O38-Q38 -> 8770 | O38: 8770
O39: =SUM(O3:O38) -> 391268 | Q39: =SUM(Q3:Q38) -> 0

Sheet 3D
B2: OLE SAMEDHA PREMIER HOSTELS | N2: VAR | O2: TAX DUE
B3: ='1A'!B2 -> P.O BOX 9473-00200 NAIROBI | N3: =O3-Q3 -> 10270 | O3: 10270
B4: WATER BILL | H4: BILL NO. | I4: ='1A'!H3+21-1 -> 58 | L4: ='1A'!H3+21-1 -> 58 | N4: =O4-Q4 -> 10304 | O4: 10304
N5: =O5-Q5 -> 10988 | O5: 10988
B6: TENANT NAME | D6: =meter!B24 -> RIYAQ MOHAMMED | N6: =O6-Q6 -> 11070 | O6: 11070
N7: =O7-Q7 -> 1197 | O7: 1197
B8: HOUSE NUMBER | D8: 3D | N8: =O8-Q8 -> 9250 | O8: 9250
D9: 0723662965 | N9: =O9-Q9 -> 8770 | O9: 8770
B10: ISSUE DATE | D10: ='1A'!C9 -> 30TH JAN 2026 | N10: =O10-Q10 -> 23190 | O10: 23190
N11: =O11-Q11 -> 10910 | O11: 10910
B12: LAST PAY DATE | D12: ='1A'!C11 -> 5TH FEB 2026 | N12: =O12-Q12 -> 10910 | O12: 10910
N13: =O13-Q13 -> 12190 | O13: 12190
N14: =O14-Q14 -> 11070 | O14: 11070
B15: PREVIOUS READING | D15: CURRENT READING | F15: CONSUMPTION | N15: =O15-Q15 -> 9090 | O15: 9090
B16: =meter!E24 -> 23 | D16: =meter!F24 -> 25 | E16: Units | F16: =D16-B16 -> 2 | N16: =O16-Q16 -> 9420 | O16: 9420
F17: Amount (Kshs.) | N17: =O17-Q17 -> 11154 | O17: 11154
D18: LAST ACCOUNT B/F | E18: Kshs. | F18: =meter!O24 -> 0 | N18: =O18-Q18 -> 10430 | O18: 10430
N19: =O19-Q19 -> 11831 | O19: 11831
D20: MONTH BILL | E20: KSHS. | F20: =meter!I24 -> 300 | N20: =O20-Q20 -> 10590 | O20: 10590
N21: =O21-Q21 -> 22423 | O21: 22423
D22: PUMP/POWER CHARGES | E22: KSHS. | F22: ='1A'!E21 -> 0 | N22: =O22-Q22 -> 9250 | O22: 9250
N23: =O23-Q23 -> 10162 | O23: 10162
D24: MONTH HOUSE RENT | E24: KSHS. | F24: =meter!N24 -> 8000 | N24: =O24-Q24 -> 10270 | O24: 10270
N25: =O25-Q25 -> 11070 | O25: 11070
D26: ='1A'!C25 -> SECURITY | E26: ='1A'!D25 -> Kshs. | F26: =meter!M24 -> 0 | N26: =O26-Q26 -> 11550 | O26: 11550
D27: GARBAGE FEE | E27: Kshs. | N27: =O27-Q27 -> 11393 | O27: 11393
D28: INTEREST ON ARREARS | E28: KSHS. | F28: =IF(F18*4%*1<0,0,F18*4%*1) -> 0 | N28: =O28-Q28 -> 10802 | O28: 10802
N29: =O29-Q29 -> 8930 | O29: 8930
D30: TOTAL PAYABLE | E30: Kshs. | F30: =SUM(F17:F29) -> 8300 | N30: =O30-Q30 -> 9570 | O30: 9570
N31: =O31-Q31 -> 11390 | O31: 11390
D32: PAID | F32: =meter!T24 -> 0 | N32: =O32-Q32 -> 10750 | O32: 10750
N33: =O33-Q33 -> 11732 | O33: 11732
D34: AMOUNT DUE | F34: =F30-F32 -> 8300 | N34: =O34-Q34 -> 10934 | O34: 10934 | R34: 700
C35: NOTE | N35: =O35-Q35 -> 10270 | O35: 10270
D36: PAY BILL 4139271 ACC NO UM 3D | N36: =O36-Q36 -> 10598 | O36: 10598
N37: =O37-Q37 -> 8770 | O37: 8770
N38: =O38-Q38 -> 8770 | O38: 8770
O39: =SUM(O3:O38) -> 391268 | Q39: =SUM(Q3:Q38) -> 0

Sheet 4D
B2: OLE SAMEDHA APARTMENTS-Kitengela | D2: OLE SAMEDHA PREMIER HOSTELS | N2: VAR | O2: TAX DUE
B3: ='1A'!B2 -> P.O BOX 9473-00200 NAIROBI | N3: =O3-Q3 -> 10270 | O3: 10270
B4: WATER BILL | H4: BILL NO. | I4: ='1A'!H3+22-1 -> 59 | J4: ='1A'!H3+22-1 -> 59 | N4: =O4-Q4 -> 10304 | O4: 10304
N5: =O5-Q5 -> 10988 | O5: 10988
B6: TENANT NAME | D6: =meter!B25 -> RID WAH ABDULLAH | N6: =O6-Q6 -> 11070 | O6: 11070
N7: =O7-Q7 -> 1197 | O7: 1197
B8: HOUSE NUMBER: | D8: 4D | N8: =O8-Q8 -> 9250 | O8: 9250
N9: =O9-Q9 -> 8770 | O9: 8770
B10: ISSUE DATE | D10: ='1A'!C9 -> 30TH JAN 2026 | N10: =O10-Q10 -> 23190 | O10: 23190
N11: =O11-Q11 -> 10910 | O11: 10910
B12: LAST PAY DATE | D12: ='1A'!C11 -> 5TH FEB 2026 | N12: =O12-Q12 -> 10910 | O12: 10910
N13: =O13-Q13 -> 12190 | O13: 12190
N14: =O14-Q14 -> 11070 | O14: 11070
B15: PREVIOUS READING | D15: CURRENT READING | F15: CONSUMPTION | N15: =O15-Q15 -> 9090 | O15: 9090
B16: =meter!E25 -> 14 | D16: =meter!F25 -> 16 | E16: Units | F16: =D16-B16 -> 2 | N16: =O16-Q16 -> 9420 | O16: 9420
F17: Amount (Kshs.) | N17: =O17-Q17 -> 11154 | O17: 11154
D18: LAST ACCOUNT B/F | E18: Kshs. | F18: =meter!O25 -> 774 | N18: =O18-Q18 -> 10430 | O18: 10430
N19: =O19-Q19 -> 11831 | O19: 11831
D20: MONTH BILL | E20: KSHS. | F20: =meter!I25 -> 300 | N20: =O20-Q20 -> 10590 | O20: 10590
N21: =O21-Q21 -> 22423 | O21: 22423
D22: PUMP/POWER CHARGES | E22: KSHS. | F22: ='1A'!E21 -> 0 | N22: =O22-Q22 -> 9250 | O22: 9250
N23: =O23-Q23 -> 10162 | O23: 10162
D24: MONTH HOUSE RENT | E24: KSHS. | F24: =meter!N25 -> 8000 | N24: =O24-Q24 -> 10270 | O24: 10270
N25: =O25-Q25 -> 11070 | O25: 11070
D26: ='1A'!C25 -> SECURITY | E26: ='1A'!D25 -> Kshs. | F26: ='1A'!E25 -> 0 | N26: =O26-Q26 -> 11550 | O26: 11550
D27: GARBAGE FEE | E27: Kshs. | N27: =O27-Q27 -> 11393 | O27: 11393
D28: INTEREST LATE PAYMENT | E28: KSHS. | F28: =IF(F18*4%*1<0,0,F18*4%*1) -> 30.96 | N28: =O28-Q28 -> 10802 | O28: 10802
N29: =O29-Q29 -> 8930 | O29: 8930
D30: TOTAL PAYABLE | E30: Kshs. | F30: =SUM(F17:F29) -> 9104.96 | N30: =O30-Q30 -> 9570 | O30: 9570
N31: =O31-Q31 -> 11390 | O31: 11390
D32: PAID | F32: =meter!T25 -> 0 | N32: =O32-Q32 -> 10750 | O32: 10750
N33: =O33-Q33 -> 11732 | O33: 11732
D34: AMOUNT DUE | F34: =F30-F32 -> 9104.96 | N34: =O34-Q34 -> 10934 | O34: 10934 | R34: 700
C35: NOTE | N35: =O35-Q35 -> 10270 | O35: 10270
D36: PAY BILL 4139271 ACC NO UM 4D | N36: =O36-Q36 -> 10598 | O36: 10598
N37: =O37-Q37 -> 8770 | O37: 8770
N38: =O38-Q38 -> 8770 | O38: 8770
O39: =SUM(O3:O38) -> 391268 | Q39: =SUM(Q3:Q38) -> 0

Sheet 5D
B1: OLE SAMEDHA APARTMENTS-Kitengela | D1: OLE SAMEDHA PREMIER HOSTELS
B2: ='1A'!B2 -> P.O BOX 9473-00200 NAIROBI | N2: VAR | O2: TAX DUE
B3: WATER BILL | N3: =O3-Q3 -> 10270 | O3: 10270
H4: BILL NO. | I4: ='1A'!H3+23-1 -> 60 | K4: ='1A'!H3+23-1 -> 60 | N4: =O4-Q4 -> 10304 | O4: 10304
N5: =O5-Q5 -> 10988 | O5: 10988
B6: TENANT NAME | D6: =meter!B26 -> NASRA | N6: =O6-Q6 -> 11070 | O6: 11070
N7: =O7-Q7 -> 1197 | O7: 1197
B8: HOUSE NUMBER | D8: 5D | N8: =O8-Q8 -> 9250 | O8: 9250
N9: =O9-Q9 -> 8770 | O9: 8770
B10: ISSUE DATE | D10: ='1A'!C9 -> 30TH JAN 2026 | N10: =O10-Q10 -> 23190 | O10: 23190
N11: =O11-Q11 -> 10910 | O11: 10910
B12: LAST PAY DATE | D12: ='1A'!C11 -> 5TH FEB 2026 | N12: =O12-Q12 -> 10910 | O12: 10910
N13: =O13-Q13 -> 12190 | O13: 12190
N14: =O14-Q14 -> 11070 | O14: 11070
B15: PREVIOUS READING | D15: CURRENT READING | F15: CONSUMPTION | N15: =O15-Q15 -> 9090 | O15: 9090
B16: =meter!E26 -> 25 | D16: =meter!F26 -> 28 | E16: Units | F16: =D16-B16 -> 3 | N16: =O16-Q16 -> 9420 | O16: 9420
F17: Amount (Kshs.) | N17: =O17-Q17 -> 11154 | O17: 11154
D18: LAST ACCOUNT B/F | E18: Kshs. | F18: =meter!O26 -> 0 | N18: =O18-Q18 -> 10430 | O18: 10430
N19: =O19-Q19 -> 11831 | O19: 11831
D20: MONTH BILL | E20: KSHS. | F20: =meter!I26 -> 450 | N20: =O20-Q20 -> 10590 | O20: 10590
N21: =O21-Q21 -> 22423 | O21: 22423
D22: PUMP/POWER CHARGES | E22: KSHS. | F22: ='1A'!E21 -> 0 | N22: =O22-Q22 -> 9250 | O22: 9250
N23: =O23-Q23 -> 10162 | O23: 10162
D24: MONTH HOUSE RENT | E24: KSHS. | F24: =meter!N26 -> 8000 | N24: =O24-Q24 -> 10270 | O24: 10270
N25: =O25-Q25 -> 11070 | O25: 11070
D26: ='1A'!C25 -> SECURITY | E26: ='1A'!D25 -> Kshs. | F26: ='1A'!E25 -> 0 | N26: =O26-Q26 -> 11550 | O26: 11550
D27: GARBAGE FEE | E27: Kshs. | N27: =O27-Q27 -> 11393 | O27: 11393
D28: PENALTY LATE PAYMENT | E28: KSHS. | F28: =IF(F18*4%*1<0,0,F18*4%*1) -> 0 | N28: =O28-Q28 -> 10802 | O28: 10802
N29: =O29-Q29 -> 8930 | O29: 8930
D30: TOTAL PAYABLE | E30: Kshs. | F30: =SUM(F17:F29) -> 8450 | N30: =O30-Q30 -> 9570 | O30: 9570
N31: =O31-Q31 -> 11390 | O31: 11390
D32: PAID | F32: =meter!T26 -> 0 | N32: =O32-Q32 -> 10750 | O32: 10750
N33: =O33-Q33 -> 11732 | O33: 11732
D34: AMOUNT DUE | F34: =F30-F32 -> 8450 | N34: =O34-Q34 -> 10934 | O34: 10934 | R34: 700
D35: PAY BILL 4139271 ACC NO UM 5D | N35: =O35-Q35 -> 10270 | O35: 10270
B36: Rent is due on or before 5th of the month. By 7th day, any rent not paid will attract interest at 2% per day. | N36: =O36-Q36 -> 10598 | O36: 10598
B37: Any default in Rent payment by 10th of the following month the house shall be locked without notice and belongings removed for re-letting. | N37: =O37-Q37 -> 8770 | O37: 8770
N38: =O38-Q38 -> 8770 | O38: 8770
B39: Amounts not cleared by last pay date will render to water disconnection. | O39: =SUM(O3:O38) -> 391268 | Q39: =SUM(Q3:Q38) -> 0
B41: A reconnection fee of Kshs. 1,000 will be charged and paid before supply is reconnected.
...

Sheet 6D
B1: OLE SAMEDHA PREMIER HOSTELS
B2: ='1A'!B2 -> P.O BOX 9473-00200 NAIROBI | N2: VAR | O2: TAX DUE
B3: WATER BILL | N3: =O3-Q3 -> 10270 | O3: 10270
H4: BILL NO. | I4: ='1A'!H3+24-1 -> 61 | M4: ='1A'!H3+24-1 -> 61 | N4: =O4-Q4 -> 10304 | O4: 10304
N5: =O5-Q5 -> 10988 | O5: 10988
B6: TENANT NAME | D6: =meter!B27 -> 0 | N6: =O6-Q6 -> 11070 | O6: 11070
N7: =O7-Q7 -> 1197 | O7: 1197
B8: HOUSE NUMBER: | D8: 6D | N8: =O8-Q8 -> 9250 | O8: 9250
N9: =O9-Q9 -> 8770 | O9: 8770
B10: ISSUE DATE | D10: ='1A'!C9 -> 30TH JAN 2026 | N10: =O10-Q10 -> 23190 | O10: 23190
N11: =O11-Q11 -> 10910 | O11: 10910
B12: LAST PAY DATE | D12: ='1A'!C11 -> 5TH FEB 2026 | N12: =O12-Q12 -> 10910 | O12: 10910
N13: =O13-Q13 -> 12190 | O13: 12190
N14: =O14-Q14 -> 11070 | O14: 11070
B15: PREVIOUS READING | D15: CURRENT READING | F15: CONSUMPTION | N15: =O15-Q15 -> 9090 | O15: 9090
B16: =meter!E27 -> 28 | D16: =meter!F27 -> 29 | E16: Units | F16: =D16-B16 -> 1 | N16: =O16-Q16 -> 9420 | O16: 9420
F17: Amount (Kshs.) | N17: =O17-Q17 -> 11154 | O17: 11154
D18: LAST ACCOUNT B/F | E18: Kshs. | F18: =meter!O27 -> 484 | N18: =O18-Q18 -> 10430 | O18: 10430
N19: =O19-Q19 -> 11831 | O19: 11831
D20: MONTH BILL | E20: KSHS. | F20: =meter!I27 -> 150 | N20: =O20-Q20 -> 10590 | O20: 10590
N21: =O21-Q21 -> 22423 | O21: 22423
D22: PUMP/POWER CHARGES | E22: KSHS. | F22: ='1A'!E21 -> 0 | N22: =O22-Q22 -> 9250 | O22: 9250
N23: =O23-Q23 -> 10162 | O23: 10162
D24: MONTH HOUSE RENT | E24: KSHS. | F24: =meter!N27 -> 7500 | N24: =O24-Q24 -> 10270 | O24: 10270
N25: =O25-Q25 -> 11070 | O25: 11070
D26: ='1A'!C25 -> SECURITY | E26: ='1A'!D25 -> Kshs. | F26: ='1A'!E25 -> 0 | N26: =O26-Q26 -> 11550 | O26: 11550
D27: GARBAGE FEE | E27: Kshs. | N27: =O27-Q27 -> 11393 | O27: 11393
D28: INTEREST ON ARREARS | E28: KSHS. | F28: =IF(F18*4%*1<0,0,F18*4%*1) -> 19.36 | N28: =O28-Q28 -> 10802 | O28: 10802
N29: =O29-Q29 -> 8930 | O29: 8930
D30: TOTAL PAYABLE | E30: Kshs. | F30: =SUM(F17:F29) -> 8153.36 | N30: =O30-Q30 -> 9570 | O30: 9570
N31: =O31-Q31 -> 11390 | O31: 11390
D32: PAID | F32: =meter!T27 -> 0 | N32: =O32-Q32 -> 10750 | O32: 10750
N33: =O33-Q33 -> 11732 | O33: 11732
D34: AMOUNT DUE | F34: =F30-F32 -> 8153.36 | N34: =O34-Q34 -> 10934 | O34: 10934 | R34: 700
N35: =O35-Q35 -> 10270 | O35: 10270
D36: PAY BILL 4139271 ACC NO UM 6D | N36: =O36-Q36 -> 10598 | O36: 10598
N37: =O37-Q37 -> 8770 | O37: 8770
N38: =O38-Q38 -> 8770 | O38: 8770
O39: =SUM(O3:O38) -> 391268 | Q39: =SUM(Q3:Q38) -> 0

Sheet 1E
B1: OLE SAMEDHA PREMIER HOSTELS
B2: ='1A'!B2 -> P.O BOX 9473-00200 NAIROBI | N2: VAR | O2: TAX DUE
B3: WATER BILL | N3: =O3-Q3 -> 10270 | O3: 10270
